Workbook

Sheet 鉄骨鉄筋コンクリート造
A1: 鉄骨鉄筋コンクリート造
C3: 2015（基準） | G3: 令和4年2月分 | K3: 令和4年5月分 | O3: 令和4年8月分 | S3: 令和4年11月分 | W3: 令和5年2月分 | AA3: 令和5年5月分 | AE3: 令和5年8月分 | AI3: 令和5年11月分 | AM3: 令和6年2月分 | AQ3: 令和6年5月分 | AU3: 令和6年8月分 | AY3: 令和6年11月分 | BC3: 令和7年2月分 | BG3: 令和7年5月分
C4: 床面積の合計 （㎡） | D4: 工事費予定額（万円） | E4: 面積単価 （万円/㎡） | F4: 面積単価 （万円/坪） | G4: 床面積の合計 （㎡） | H4: 工事費予定額（万円） | I4: 面積単価 （万円/㎡） | J4: 面積単価 （万円/坪） | K4: 床面積の合計 （㎡） | L4: 工事費予定額（万円） | M4: 面積単価 （万円/㎡） | N4: 面積単価 （万円/坪） | O4: 床面積の合計 （㎡） | P4: 工事費予定額（万円） | Q4: 面積単価 （万円/㎡） | R4: 面積単価 （万円/坪） | S4: 床面積の合計 （㎡） | T4: 工事費予定額（万円） | U4: 面積単価 （万円/㎡） | V4: 面積単価 （万円/坪） | W4: 床面積の合計 （㎡） | X4: 工事費予定額（万円） | Y4: 面積単価 （万円/㎡） | Z4: 面積単価 （万円/坪） | AA4: 床面積の合計 （㎡） | AB4: 工事費予定額（万円） | AC4: 面積単価 （万円/㎡） | AD4: 面積単価 （万円/坪） | AE4: 床面積の合計 （㎡） | AF4: 工事費予定額（万円） | AG4: 面積単価 （万円/㎡） | AH4: 面積単価 （万円/坪） | AI4: 床面積の合計 （㎡） | AJ4: 工事費予定額（万円） | AK4: 面積単価 （万円/㎡） | AL4: 面積単価 （万円/坪） | AM4: 床面積の合計 （㎡） | AN4: 工事費予定額（万円） | AO4: 面積単価 （万円/㎡） | AP4: 面積単価 （万円/坪） | AQ4: 床面積の合計 （㎡） | AR4: 工事費予定額（万円） | AS4: 面積単価 （万円/㎡） | AT4: 面積単価 （万円/坪） | AU4: 床面積の合計 （㎡） | AV4: 工事費予定額（万円） | AW4: 面積単価 （万円/㎡） | AX4: 面積単価 （万円/坪） | AY4: 床面積の合計 （㎡） | AZ4: 工事費予定額（万円） | BA4: 面積単価 （万円/㎡） | BB4: 面積単価 （万円/坪） | BC4: 床面積の合計 （㎡） | BD4: 工事費予定額（万円） | BE4: 面積単価 （万円/㎡） | BF4: 面積単価 （万円/坪） | BG4: 床面積の合計 （㎡） | BH4: 工事費予定額（万円） | BI4: 面積単価 （万円/㎡） | BJ4: 面積単価 （万円/坪）
B5: 事務所 | C5: 376276 | D5: 14713671 | E5: =D5/C5 | F5: =E5*3.30578512 | G5: 14473 | H5: 703002 | I5: =H5/G5 | J5: =I5*3.30578512 | K5: 12930 | L5: 468976 | M5: =L5/K5 | N5: =M5*3.30578512 | O5: 2176 | P5: 33947 | Q5: =P5/O5 | R5: =Q5*3.30578512 | S5: 6950 | T5: 278981 | U5: =T5/S5 | V5: =U5*3.30578512 | W5: 15791 | X5: 679000 | Y5: =X5/W5 | Z5: =Y5*3.30578512 | AA5: 13436 | AB5: 844000 | AC5: =AB5/AA5 | AD5: =AC5*3.30578512 | AE5: 29255 | AF5: 1503500 | AG5: =AF5/AE5 | AH5: =AG5*3.30578512 | AI5: 6133 | AJ5: 385200 | AK5: =AJ5/AI5 | AL5: =AK5*3.30578512 | AM5: 0 | AN5: 0 | AO5: =AN5/AM5 | AP5: =AO5*3.30578512 | AQ5: 73716 | AR5: 4000000 | AS5: =AR5/AQ5 | AT5: =AS5*3.30578512 | AU5: 3487 | AV5: 213200 | AW5: =AV5/AU5 | AX5: =AW5*3.30578512 | AY5: 43887 | AZ5: 2383000 | BA5: =AZ5/AY5 | BB5: =BA5*3.30578512 | BC5: 3548 | BD5: 325057.04 | BE5: =BD5/BC5 | BF5: =BE5*3.30578512 | BG5: 1988 | BH5: 96136 | BI5: =BH5/BG5 | BJ5: =BI5*3.30578512
B6: 店舗 | C6: 47766 | D6: 1192080 | E6: =D6/C6 | F6: =E6*3.30578512 | G6: 505 | H6: 30000 | I6: =H6/G6 | J6: =I6*3.30578512 | K6: 178 | L6: 2250 | M6: =L6/K6 | N6: =M6*3.30578512 | O6: 7218 | P6: 122430 | Q6: =P6/O6 | R6: =Q6*3.30578512 | S6: 1194 | T6: 10000 | U6: =T6/S6 | V6: =U6*3.30578512 | W6: 5739 | X6: 177000 | Y6: =X6/W6 | Z6: =Y6*3.30578512 | AA6: 0 | AB6: 0 | AC6: =AB6/AA6 | AD6: =AC6*3.30578512 | AE6: 309 | AF6: 30000 | AG6: =AF6/AE6 | AH6: =AG6*3.30578512 | AI6: 0 | AJ6: 0 | AK6: =AJ6/AI6 | AL6: =AK6*3.30578512 | AM6: 0 | AN6: 0 | AO6: =AN6/AM6 | AP6: =AO6*3.30578512 | AQ6: 285 | AR6: 100 | AS6: =AR6/AQ6 | AT6: =AS6*3.30578512 | AU6: 243 | AV6: 16057 | AW6: =AV6/AU6 | AX6: =AW6*3.30578512 | AY6: 120 | AZ6: 1650 | BA6: =AZ6/AY6 | BB6: =BA6*3.30578512 | BC6: 0 | BD6: 0 | BE6: =BD6/BC6 | BF6: =BE6*3.30578512 | BG6: 173 | BH6: 5000 | BI6: =BH6/BG6 | BJ6: =BI6*3.30578512
B7: 工場及び作業場 | C7: 99563 | D7: 2195253 | E7: =D7/C7 | F7: =E7*3.30578512 | G7: 42149 | H7: 1962412 | I7: =H7/G7 | J7: =I7*3.30578512 | K7: 233702 | L7: 16079466 | M7: =L7/K7 | N7: =M7*3.30578512 | O7: 540 | P7: 10000 | Q7: =P7/O7 | R7: =Q7*3.30578512 | S7: 0 | T7: 0 | U7: =T7/S7 | V7: =U7*3.30578512 | W7: 779 | X7: 15879 | Y7: =X7/W7 | Z7: =Y7*3.30578512 | AA7: 0 | AB7: 0 | AC7: =AB7/AA7 | AD7: =AC7*3.30578512 | AE7: 22641 | AF7: 315800 | AG7: =AF7/AE7 | AH7: =AG7*3.30578512 | AI7: 0 | AJ7: 0 | AK7: =AJ7/AI7 | AL7: =AK7*3.30578512 | AM7: 10032 | AN7: 459980 | AO7: =AN7/AM7 | AP7: =AO7*3.30578512 | AQ7: 0 | AR7: 0 | AS7: =AR7/AQ7 | AT7: =AS7*3.30578512 | AU7: 39086 | AV7: 2340000 | AW7: =AV7/AU7 | AX7: =AW7*3.30578512 | AY7: 181 | AZ7: 6000 | BA7: =AZ7/AY7 | BB7: =BA7*3.30578512 | BC7: 0 | BD7: 0 | BE7: =BD7/BC7 | BF7: =BE7*3.30578512 | BG7: 1096 | BH7: 70000 | BI7: =BH7/BG7 | BJ7: =BI7*3.30578512
B8: 倉庫 | C8: 560842 | D8: 5842073 | E8: =D8/C8 | F8: =E8*3.30578512 | G8: 58534 | H8: 780080 | I8: =H8/G8 | J8: =I8*3.30578512 | K8: 485 | L8: 5600 | M8: =L8/K8 | N8: =M8*3.30578512 | O8: 73357 | P8: 1094000 | Q8: =P8/O8 | R8: =Q8*3.30578512 | S8: 25992 | T8: 350320 | U8: =T8/S8 | V8: =U8*3.30578512 | W8: 438 | X8: 4533 | Y8: =X8/W8 | Z8: =Y8*3.30578512 | AA8: 76510 | AB8: 1550000 | AC8: =AB8/AA8 | AD8: =AC8*3.30578512 | AE8: 72696 | AF8: 1100500 | AG8: =AF8/AE8 | AH8: =AG8*3.30578512 | AI8: 0 | AJ8: 0 | AK8: =AJ8/AI8 | AL8: =AK8*3.30578512 | AM8: 20271 | AN8: 500800 | AO8: =AN8/AM8 | AP8: =AO8*3.30578512 | AQ8: 55 | AR8: 600 | AS8: =AR8/AQ8 | AT8: =AS8*3.30578512 | AU8: 41165 | AV8: 1500630 | AW8: =AV8/AU8 | AX8: =AW8*3.30578512 | AY8: 438 | AZ8: 18000 | BA8: =AZ8/AY8 | BB8: =BA8*3.30578512 | BC8: 188 | BD8: 16950 | BE8: =BD8/BC8 | BF8: =BE8*3.30578512 | BG8: 387 | BH8: 12085 | BI8: =BH8/BG8 | BJ8: =BI8*3.30578512
B9: 学校の校舎 | C9: 266605 | D9: 8404400 | E9: =D9/C9 | F9: =E9*3.30578512 | G9: 31335 | H9: 1411293 | I9: =H9/G9 | J9: =I9*3.30578512 | K9: 7137 | L9: 235000 | M9: =L9/K9 | N9: =M9*3.30578512 | O9: 9146 | P9: 400000 | Q9: =P9/O9 | R9: =Q9*3.30578512 | S9: 13024 | T9: 403300 | U9: =T9/S9 | V9: =U9*3.30578512 | W9: 3518 | X9: 225292 | Y9: =X9/W9 | Z9: =Y9*3.30578512 | AA9: 3068 | AB9: 78000 | AC9: =AB9/AA9 | AD9: =AC9*3.30578512 | AE9: 8672 | AF9: 335000 | AG9: =AF9/AE9 | AH9: =AG9*3.30578512 | AI9: 15400 | AJ9: 859050 | AK9: =AJ9/AI9 | AL9: =AK9*3.30578512 | AM9: 15055 | AN9: 410000 | AO9: =AN9/AM9 | AP9: =AO9*3.30578512 | AQ9: 34043 | AR9: 1561518 | AS9: =AR9/AQ9 | AT9: =AS9*3.30578512 | AU9: 11391 | AV9: 786964 | AW9: =AV9/AU9 | AX9: =AW9*3.30578512 | AY9: 2491 | AZ9: 100000 | BA9: =AZ9/AY9 | BB9: =BA9*3.30578512 | BC9: 0 | BD9: 0 | BE9: =BD9/BC9 | BF9: =BE9*3.30578512 | BG9: 16153 | BH9: 560000 | BI9: =BH9/BG9 | BJ9: =BI9*3.30578512
B10: 病院・診療所 | C10: 314681 | D10: 7514820 | E10: =D10/C10 | F10: =E10*3.30578512 | G10: 7101 | H10: 250000 | I10: =H10/G10 | J10: =I10*3.30578512 | K10: 0 | L10: 0 | M10: =L10/K10 | N10: =M10*3.30578512 | O10: 0 | P10: 0 | Q10: =P10/O10 | R10: =Q10*3.30578512 | S10: 45264 | T10: 1927700 | U10: =T10/S10 | V10: =U10*3.30578512 | W10: 0 | X10: 0 | Y10: =X10/W10 | Z10: =Y10*3.30578512 | AA10: 1698 | AB10: 65000 | AC10: =AB10/AA10 | AD10: =AC10*3.30578512 | AE10: 233 | AF10: 100000 | AG10: =AF10/AE10 | AH10: =AG10*3.30578512 | AI10: 0 | AJ10: 0 | AK10: =AJ10/AI10 | AL10: =AK10*3.30578512 | AM10: 0 | AN10: 0 | AO10: =AN10/AM10 | AP10: =AO10*3.30578512 | AQ10: 0 | AR10: 0 | AS10: =AR10/AQ10 | AT10: =AS10*3.30578512 | AU10: 0 | AV10: 0 | AW10: =AV10/AU10 | AX10: =AW10*3.30578512 | AY10: 0 | AZ10: 0 | BA10: =AZ10/AY10 | BB10: =BA10*3.30578512 | BC10: 0 | BD10: 0 | BE10: =BD10/BC10 | BF10: =BE10*3.30578512 | BG10: 117 | BH10: 10000 | BI10: =BH10/BG10 | BJ10: =BI10*3.30578512
B11: その他 | C11: 507097 | D11: 17314472 | E11: =D11/C11 | F11: =E11*3.30578512 | G11: 50041 | H11: 2062198 | I11: =H11/G11 | J11: =I11*3.30578512 | K11: 8699 | L11: 257572 | M11: =L11/K11 | N11: =M11*3.30578512 | O11: 11687 | P11: 363695 | Q11: =P11/O11 | R11: =Q11*3.30578512 | S11: 29941 | T11: 1871775 | U11: =T11/S11 | V11: =U11*3.30578512 | W11: 9188 | X11: 483125 | Y11: =X11/W11 | Z11: =Y11*3.30578512 | AA11: 34727 | AB11: 1085909 | AC11: =AB11/AA11 | AD11: =AC11*3.30578512 | AE11: 4314 | AF11: 175486 | AG11: =AF11/AE11 | AH11: =AG11*3.30578512 | AI11: 12774 | AJ11: 936374 | AK11: =AJ11/AI11 | AL11: =AK11*3.30578512 | AM11: 1320 | AN11: 58144 | AO11: =AN11/AM11 | AP11: =AO11*3.30578512 | AQ11: 968 | AR11: 13963 | AS11: =AR11/AQ11 | AT11: =AS11*3.30578512 | AU11: 72472 | AV11: 7480770 | AW11: =AV11/AU11 | AX11: =AW11*3.30578512 | AY11: 125722 | AZ11: 12810713 | BA11: =AZ11/AY11 | BB11: =BA11*3.30578512 | BC11: 66242 | BD11: 4926066 | BE11: =BD11/BC11 | BF11: =BE11*3.30578512 | BG11: 11749 | BH11: 267872 | BI11: =BH11/BG11 | BJ11: =BI11*3.30578512

Sheet 鉄筋コンクリート造
A1: 鉄筋コンクリート造
C3: 2015（基準） | G3: 令和4年2月分 | K3: 令和4年5月分 | O3: 令和4年8月分 | S3: 令和4年11月分 | W3: 令和5年2月分 | AA3: 令和5年5月分 | AE3: 令和5年8月分 | AI3: 令和5年11月分 | AM3: 令和6年2月分 | AQ3: 令和6年5月分 | AU3: 令和6年8月分 | AY3: 令和6年11月分 | BC3: 令和7年2月分 | BG3: 令和7年5月分
C4: 床面積の合計 （㎡） | D4: 工事費予定額（万円） | E4: 面積単価 （万円/㎡） | F4: 面積単価 （万円/坪） | G4: 床面積の合計 （㎡） | H4: 工事費予定額（万円） | I4: 面積単価 （万円/㎡） | J4: 面積単価 （万円/坪） | K4: 床面積の合計 （㎡） | L4: 工事費予定額（万円） | M4: 面積単価 （万円/㎡） | N4: 面積単価 （万円/坪） | O4: 床面積の合計 （㎡） | P4: 工事費予定額（万円） | Q4: 面積単価 （万円/㎡） | R4: 面積単価 （万円/坪） | S4: 床面積の合計 （㎡） | T4: 工事費予定額（万円） | U4: 面積単価 （万円/㎡） | V4: 面積単価 （万円/坪） | W4: 床面積の合計 （㎡） | X4: 工事費予定額（万円） | Y4: 面積単価 （万円/㎡） | Z4: 面積単価 （万円/坪） | AA4: 床面積の合計 （㎡） | AB4: 工事費予定額（万円） | AC4: 面積単価 （万円/㎡） | AD4: 面積単価 （万円/坪） | AE4: 床面積の合計 （㎡） | AF4: 工事費予定額（万円） | AG4: 面積単価 （万円/㎡） | AH4: 面積単価 （万円/坪） | AI4: 床面積の合計 （㎡） | AJ4: 工事費予定額（万円） | AK4: 面積単価 （万円/㎡） | AL4: 面積単価 （万円/坪） | AM4: 床面積の合計 （㎡） | AN4: 工事費予定額（万円） | AO4: 面積単価 （万円/㎡） | AP4: 面積単価 （万円/坪） | AQ4: 床面積の合計 （㎡） | AR4: 工事費予定額（万円） | AS4: 面積単価 （万円/㎡） | AT4: 面積単価 （万円/坪） | AU4: 床面積の合計 （㎡） | AV4: 工事費予定額（万円） | AW4: 面積単価 （万円/㎡） | AX4: 面積単価 （万円/坪） | AY4: 床面積の合計 （㎡） | AZ4: 工事費予定額（万円） | BA4: 面積単価 （万円/㎡） | BB4: 面積単価 （万円/坪） | BC4: 床面積の合計 （㎡） | BD4: 工事費予定額（万円） | BE4: 面積単価 （万円/㎡） | BF4: 面積単価 （万円/坪） | BG4: 床面積の合計 （㎡） | BH4: 工事費予定額（万円） | BI4: 面積単価 （万円/㎡） | BJ4: 面積単価 （万円/坪）
B5: 事務所 | C5: 673470 | D5: 21399499 | E5: =D5/C5 | F5: =E5*3.30578512 | G5: 32466 | H5: 1049125 | I5: =H5/G5 | J5: =I5*3.30578512 | K5: 79603 | L5: 3510950 | M5: =L5/K5 | N5: =M5*3.30578512 | O5: 57126 | P5: 2171051 | Q5: =P5/O5 | R5: =Q5*3.30578512 | S5: 45541 | T5: 1919944 | U5: =T5/S5 | V5: =U5*3.30578512 | W5: 55883 | X5: 2392358 | Y5: =X5/W5 | Z5: =Y5*3.30578512 | AA5: 53575 | AB5: 2353715 | AC5: =AB5/AA5 | AD5: =AC5*3.30578512 | AE5: 40073 | AF5: 2134117 | AG5: =AF5/AE5 | AH5: =AG5*3.30578512 | AI5: 39643 | AJ5: 2271769 | AK5: =AJ5/AI5 | AL5: =AK5*3.30578512 | AM5: 20929 | AN5: 1282400 | AO5: =AN5/AM5 | AP5: =AO5*3.30578512 | AQ5: 35108 | AR5: 1791375 | AS5: =AR5/AQ5 | AT5: =AS5*3.30578512 | AU5: 21870 | AV5: 1267345 | AW5: =AV5/AU5 | AX5: =AW5*3.30578512 | AY5: 76901 | AZ5: 5281615 | BA5: =AZ5/AY5 | BB5: =BA5*3.30578512 | BC5: 76113 | BD5: 4479190.8 | BE5: =BD5/BC5 | BF5: =BE5*3.30578512 | BG5: 47106 | BH5: 1677680.4 | BI5: =BH5/BG5 | BJ5: =BI5*3.30578512
B6: 店舗 | C6: 72357 | D6: 1758084 | E6: =D6/C6 | F6: =E6*3.30578512 | G6: 27939 | H6: 779947 | I6: =H6/G6 | J6: =I6*3.30578512 | K6: 23904 | L6: 951091 | M6: =L6/K6 | N6: =M6*3.30578512 | O6: 10431 | P6: 262239 | Q6: =P6/O6 | R6: =Q6*3.30578512 | S6: 1536 | T6: 47894 | U6: =T6/S6 | V6: =U6*3.30578512 | W6: 6306 | X6: 215418 | Y6: =X6/W6 | Z6: =Y6*3.30578512 | AA6: 5822 | AB6: 179220 | AC6: =AB6/AA6 | AD6: =AC6*3.30578512 | AE6: 8806 | AF6: 377134 | AG6: =AF6/AE6 | AH6: =AG6*3.30578512 | AI6: 1430 | AJ6: 71400 | AK6: =AJ6/AI6 | AL6: =AK6*3.30578512 | AM6: 5235 | AN6: 321235 | AO6: =AN6/AM6 | AP6: =AO6*3.30578512 | AQ6: 32529 | AR6: 864522 | AS6: =AR6/AQ6 | AT6: =AS6*3.30578512 | AU6: 1537 | AV6: 157000 | AW6: =AV6/AU6 | AX6: =AW6*3.30578512 | AY6: 4645 | AZ6: 250910 | BA6: =AZ6/AY6 | BB6: =BA6*3.30578512 | BC6: 7686 | BD6: 363662.18 | BE6: =BD6/BC6 | BF6: =BE6*3.30578512 | BG6: 12462 | BH6: 685329.05 | BI6: =BH6/BG6 | BJ6: =BI6*3.30578512
B7: 工場及び作業場 | C7: 229990 | D7: 5185075 | E7: =D7/C7 | F7: =E7*3.30578512 | G7: 10490 | H7: 93064 | I7: =H7/G7 | J7: =I7*3.30578512 | K7: 24994 | L7: 485825 | M7: =L7/K7 | N7: =M7*3.30578512 | O7: 22450 | P7: 1435629 | Q7: =P7/O7 | R7: =Q7*3.30578512 | S7: 8420 | T7: 176370 | U7: =T7/S7 | V7: =U7*3.30578512 | W7: 107226 | X7: 2452202 | Y7: =X7/W7 | Z7: =Y7*3.30578512 | AA7: 14417 | AB7: 952900 | AC7: =AB7/AA7 | AD7: =AC7*3.30578512 | AE7: 1056 | AF7: 63500 | AG7: =AF7/AE7 | AH7: =AG7*3.30578512 | AI7: 380 | AJ7: 57440 | AK7: =AJ7/AI7 | AL7: =AK7*3.30578512 | AM7: 4600 | AN7: 115328 | AO7: =AN7/AM7 | AP7: =AO7*3.30578512 | AQ7: 6481 | AR7: 245050 | AS7: =AR7/AQ7 | AT7: =AS7*3.30578512 | AU7: 75089 | AV7: 2969080 | AW7: =AV7/AU7 | AX7: =AW7*3.30578512 | AY7: 7039 | AZ7: 190150 | BA7: =AZ7/AY7 | BB7: =BA7*3.30578512 | BC7: 11647 | BD7: 985376 | BE7: =BD7/BC7 | BF7: =BE7*3.30578512 | BG7: 6591 | BH7: 594050 | BI7: =BH7/BG7 | BJ7: =BI7*3.30578512
B8: 倉庫 | C8: 1031373 | D8: 13384389 | E8: =D8/C8 | F8: =E8*3.30578512 | G8: 382289 | H8: 4603680 | I8: =H8/G8 | J8: =I8*3.30578512 | K8: 273698 | L8: 2918396 | M8: =L8/K8 | N8: =M8*3.30578512 | O8: 458673 | P8: 6841976 | Q8: =P8/O8 | R8: =Q8*3.30578512 | S8: 1171 | T8: 41750 | U8: =T8/S8 | V8: =U8*3.30578512 | W8: 226910 | X8: 3484438 | Y8: =X8/W8 | Z8: =Y8*3.30578512 | AA8: 208410 | AB8: 2703090 | AC8: =AB8/AA8 | AD8: =AC8*3.30578512 | AE8: 565298 | AF8: 9002018 | AG8: =AF8/AE8 | AH8: =AG8*3.30578512 | AI8: 428385 | AJ8: 7280600 | AK8: =AJ8/AI8 | AL8: =AK8*3.30578512 | AM8: 266570 | AN8: 6278887 | AO8: =AN8/AM8 | AP8: =AO8*3.30578512 | AQ8: 72900 | AR8: 1278061 | AS8: =AR8/AQ8 | AT8: =AS8*3.30578512 | AU8: 67268 | AV8: 1471680 | AW8: =AV8/AU8 | AX8: =AW8*3.30578512 | AY8: 98948 | AZ8: 2231733 | BA8: =AZ8/AY8 | BB8: =BA8*3.30578512 | BC8: 526019 | BD8: 10420454 | BE8: =BD8/BC8 | BF8: =BE8*3.30578512 | BG8: 701489 | BH8: 17963969 | BI8: =BH8/BG8 | BJ8: =BI8*3.30578512
B9: 学校の校舎 | C9: 1835193 | D9: 50330867 | E9: =D9/C9 | F9: =E9*3.30578512 | G9: 51890 | H9: 1774216 | I9: =H9/G9 | J9: =I9*3.30578512 | K9: 116271 | L9: 3203689 | M9: =L9/K9 | N9: =M9*3.30578512 | O9: 173181 | P9: 6427432 | Q9: =P9/O9 | R9: =Q9*3.30578512 | S9: 88166 | T9: 2508835 | U9: =T9/S9 | V9: =U9*3.30578512 | W9: 62683 | X9: 2232198 | Y9: =X9/W9 | Z9: =Y9*3.30578512 | AA9: 85769 | AB9: 3909924 | AC9: =AB9/AA9 | AD9: =AC9*3.30578512 | AE9: 90258 | AF9: 3745219 | AG9: =AF9/AE9 | AH9: =AG9*3.30578512 | AI9: 34086 | AJ9: 1288005 | AK9: =AJ9/AI9 | AL9: =AK9*3.30578512 | AM9: 32190 | AN9: 1072003 | AO9: =AN9/AM9 | AP9: =AO9*3.30578512 | AQ9: 40077 | AR9: 1483873 | AS9: =AR9/AQ9 | AT9: =AS9*3.30578512 | AU9: 78959 | AV9: 3358800 | AW9: =AV9/AU9 | AX9: =AW9*3.30578512 | AY9: 61695 | AZ9: 3184395 | BA9: =AZ9/AY9 | BB9: =BA9*3.30578512 | BC9: 46855 | BD9: 2164665.5 | BE9: =BD9/BC9 | BF9: =BE9*3.30578512 | BG9: 36837 | BH9: 1676479.1 | BI9: =BH9/BG9 | BJ9: =BI9*3.30578512
B10: 病院・診療所 | C10: 1024242 | D10: 29249650 | E10: =D10/C10 | F10: =E10*3.30578512 | G10: 37579 | H10: 1256192 | I10: =H10/G10 | J10: =I10*3.30578512 | K10: 35646 | L10: 942009 | M10: =L10/K10 | N10: =M10*3.30578512 | O10: 30421 | P10: 1316334 | Q10: =P10/O10 | R10: =Q10*3.30578512 | S10: 51002 | T10: 1899726 | U10: =T10/S10 | V10: =U10*3.30578512 | W10: 53670 | X10: 2730012 | Y10: =X10/W10 | Z10: =Y10*3.30578512 | AA10: 131908 | AB10: 5493250 | AC10: =AB10/AA10 | AD10: =AC10*3.30578512 | AE10: 15684 | AF10: 747019 | AG10: =AF10/AE10 | AH10: =AG10*3.30578512 | AI10: 31814 | AJ10: 1390287 | AK10: =AJ10/AI10 | AL10: =AK10*3.30578512 | AM10: 4911 | AN10: 252510 | AO10: =AN10/AM10 | AP10: =AO10*3.30578512 | AQ10: 33521 | AR10: 1394000 | AS10: =AR10/AQ10 | AT10: =AS10*3.30578512 | AU10: 42760 | AV10: 2069660 | AW10: =AV10/AU10 | AX10: =AW10*3.30578512 | AY10: 56004 | AZ10: 1992480 | BA10: =AZ10/AY10 | BB10: =BA10*3.30578512 | BC10: 16968 | BD10: 834225.11 | BE10: =BD10/BC10 | BF10: =BE10*3.30578512 | BG10: 16780 | BH10: 973237.34 | BI10: =BH10/BG10 | BJ10: =BI10*3.30578512
B11: その他 | C11: 2863587 | D11: 79499077 | E11: =D11/C11 | F11: =E11*3.30578512 | G11: 145387 | H11: 8433486 | I11: =H11/G11 | J11: =I11*3.30578512 | K11: 139166 | L11: 4777887 | M11: =L11/K11 | N11: =M11*3.30578512 | O11: 108312 | P11: 4182521 | Q11: =P11/O11 | R11: =Q11*3.30578512 | S11: 196902 | T11: 9093172 | U11: =T11/S11 | V11: =U11*3.30578512 | W11: 124745 | X11: 5453712 | Y11: =X11/W11 | Z11: =Y11*3.30578512 | AA11: 162589 | AB11: 6832117 | AC11: =AB11/AA11 | AD11: =AC11*3.30578512 | AE11: 164354 | AF11: 8016236 | AG11: =AF11/AE11 | AH11: =AG11*3.30578512 | AI11: 155119 | AJ11: 6724494 | AK11: =AJ11/AI11 | AL11: =AK11*3.30578512 | AM11: 157352 | AN11: 8032040 | AO11: =AN11/AM11 | AP11: =AO11*3.30578512 | AQ11: 148141 | AR11: 7330161 | AS11: =AR11/AQ11 | AT11: =AS11*3.30578512 | AU11: 224207 | AV11: 13715335 | AW11: =AV11/AU11 | AX11: =AW11*3.30578512 | AY11: 129124 | AZ11: 6513811 | BA11: =AZ11/AY11 | BB11: =BA11*3.30578512 | BC11: 123812 | BD11: 6408679 | BE11: =BD11/BC11 | BF11: =BE11*3.30578512 | BG11: 149719 | BH11: 6668545.9 | BI11: =BH11/BG11 | BJ11: =BI11*3.30578512

Sheet 鉄骨造
A1: 鉄骨造
C3: 2015（基準） | G3: 令和4年1月分 | K3: 令和4年2月分 | O3: 令和4年3月分 | S3: 令和4年4月分 | W3: 令和4年5月分 | AA3: 令和4年6月分 | AE3: 令和4年7月分 | AI3: 令和4年8月分 | AM3: 令和4年9月分 | AQ3: 令和4年10月分 | AU3: 令和4年11月分 | AY3: 令和4年12月分 | BC3: 令和5年1月分 | BG3: 令和5年2月分 | BK3: 令和5年3月分 | BO3: 令和5年4月分 | BS3: 令和5年5月分 | BW3: 令和5年6月分 | CA3: 令和5年7月分 | CE3: 令和5年8月分 | CI3: 令和5年9月分 | CM3: 令和5年10月分 | CQ3: 令和5年11月分 | CU3: 令和5年12月分 | CY3: 令和6年1月分 | DC3: 令和6年2月分 | DG3: 令和6年3月分 | DK3: 令和6年4月分 | DO3: 令和6年5月分 | DS3: 令和6年6月分 | DW3: 令和6年7月分 | EA3: 令和6年8月分 | EE3: 令和6年9月分 | EI3: 令和6年10月分 | EM3: 令和6年11月分 | EQ3: 令和6年12月分 | EU3: 令和7年1月分 | EY3: 令和7年2月分 | FC3: 令和7年3月分 | FG3: 令和7年4月分 | FK3: 令和7年5月分 | FO3: 令和7年6月分 | FS3: 令和7年7月分 | FW3: 令和7年8月分
C4: 床面積の合計 （㎡） | D4: 工事費予定額（万円） | E4: 面積単価 （万円/㎡） | F4: 面積単価 （万円/坪） | G4: 床面積の合計 （㎡） | H4: 工事費予定額（万円） | I4: 面積単価 （万円/㎡） | J4: 面積単価 （万円/坪） | K4: 床面積の合計 （㎡） | L4: 工事費予定額（万円） | M4: 面積単価 （万円/㎡） | N4: 面積単価 （万円/坪） | O4: 床面積の合計 （㎡） | P4: 工事費予定額（万円） | Q4: 面積単価 （万円/㎡） | R4: 面積単価 （万円/坪） | S4: 床面積の合計 （㎡） | T4: 工事費予定額（万円） | U4: 面積単価 （万円/㎡） | V4: 面積単価 （万円/坪） | W4: 床面積の合計 （㎡） | X4: 工事費予定額（万円） | Y4: 面積単価 （万円/㎡） | Z4: 面積単価 （万円/坪） | AA4: 床面積の合計 （㎡） | AB4: 工事費予定額（万円） | AC4: 面積単価 （万円/㎡） | AD4: 面積単価 （万円/坪） | AE4: 床面積の合計 （㎡） | AF4: 工事費予定額（万円） | AG4: 面積単価 （万円/㎡） | AH4: 面積単価 （万円/坪） | AI4: 床面積の合計 （㎡） | AJ4: 工事費予定額（万円） | AK4: 面積単価 （万円/㎡） | AL4: 面積単価 （万円/坪） | AM4: 床面積の合計 （㎡） | AN4: 工事費予定額（万円） | AO4: 面積単価 （万円/㎡） | AP4: 面積単価 （万円/坪） | AQ4: 床面積の合計 （㎡） | AR4: 工事費予定額（万円） | AS4: 面積単価 （万円/㎡） | AT4: 面積単価 （万円/坪） | AU4: 床面積の合計 （㎡） | AV4: 工事費予定額（万円） | AW4: 面積単価 （万円/㎡） | AX4: 面積単価 （万円/坪） | AY4: 床面積の合計 （㎡） | AZ4: 工事費予定額（万円） | BA4: 面積単価 （万円/㎡） | BB4: 面積単価 （万円/坪） | BC4: 床面積の合計 （㎡） | BD4: 工事費予定額（万円） | BE4: 面積単価 （万円/㎡） | BF4: 面積単価 （万円/坪） | BG4: 床面積の合計 （㎡） | BH4: 工事費予定額（万円） | BI4: 面積単価 （万円/㎡） | BJ4: 面積単価 （万円/坪） | BK4: 床面積の合計 （㎡） | BL4: 工事費予定額（万円） | BM4: 面積単価 （万円/㎡） | BN4: 面積単価 （万円/坪） | BO4: 床面積の合計 （㎡） | BP4: 工事費予定額（万円） | BQ4: 面積単価 （万円/㎡） | BR4: 面積単価 （万円/坪） | BS4: 床面積の合計 （㎡） | BT4: 工事費予定額（万円） | BU4: 面積単価 （万円/㎡） | BV4: 面積単価 （万円/坪） | BW4: 床面積の合計 （㎡） | BX4: 工事費予定額（万円） | BY4: 面積単価 （万円/㎡） | BZ4: 面積単価 （万円/坪） | CA4: 床面積の合計 （㎡） | CB4: 工事費予定額（万円） | CC4: 面積単価 （万円/㎡） | CD4: 面積単価 （万円/坪） | CE4: 床面積の合計 （㎡） | CF4: 工事費予定額（万円） | CG4: 面積単価 （万円/㎡） | CH4: 面積単価 （万円/坪） | CI4: 床面積の合計 （㎡） | CJ4: 工事費予定額（万円） | CK4: 面積単価 （万円/㎡） | CL4: 面積単価 （万円/坪） | CM4: 床面積の合計 （㎡） | CN4: 工事費予定額（万円） | CO4: 面積単価 （万円/㎡） | CP4: 面積単価 （万円/坪） | CQ4: 床面積の合計 （㎡） | CR4: 工事費予定額（万円） | CS4: 面積単価 （万円/㎡） | CT4: 面積単価 （万円/坪） | CU4: 床面積の合計 （㎡） | CV4: 工事費予定額（万円） | CW4: 面積単価 （万円/㎡） | CX4: 面積単価 （万円/坪） | CY4: 床面積の合計 （㎡） | CZ4: 工事費予定額（万円） | DA4: 面積単価 （万円/㎡） | DB4: 面積単価 （万円/坪） | DC4: 床面積の合計 （㎡） | DD4: 工事費予定額（万円） | DE4: 面積単価 （万円/㎡） | DF4: 面積単価 （万円/坪） | DG4: 床面積の合計 （㎡） | DH4: 工事費予定額（万円） | DI4: 面積単価 （万円/㎡） | DJ4: 面積単価 （万円/坪） | DK4: 床面積の合計 （㎡） | DL4: 工事費予定額（万円） | DM4: 面積単価 （万円/㎡） | DN4: 面積単価 （万円/坪） | DO4: 床面積の合計 （㎡） | DP4: 工事費予定額（万円） | DQ4: 面積単価 （万円/㎡） | DR4: 面積単価 （万円/坪） | DS4: 床面積の合計 （㎡） | DT4: 工事費予定額（万円） | DU4: 面積単価 （万円/㎡） | DV4: 面積単価 （万円/坪） | DW4: 床面積の合計 （㎡） | DX4: 工事費予定額（万円） | DY4: 面積単価 （万円/㎡） | DZ4: 面積単価 （万円/坪） | EA4: 床面積の合計 （㎡） | EB4: 工事費予定額（万円） | EC4: 面積単価 （万円/㎡） | ED4: 面積単価 （万円/坪） | EE4: 床面積の合計 （㎡） | EF4: 工事費予定額（万円） | EG4: 面積単価 （万円/㎡） | EH4: 面積単価 （万円/坪） | EI4: 床面積の合計 （㎡） | EJ4: 工事費予定額（万円） | EK4: 面積単価 （万円/㎡） | EL4: 面積単価 （万円/坪） | EM4: 床面積の合計 （㎡） | EN4: 工事費予定額（万円） | EO4: 面積単価 （万円/㎡） | EP4: 面積単価 （万円/坪） | EQ4: 床面積の合計 （㎡） | ER4: 工事費予定額（万円） | ES4: 面積単価 （万円/㎡） | ET4: 面積単価 （万円/坪） | EU4: 床面積の合計 （㎡） | EV4: 工事費予定額（万円） | EW4: 面積単価 （万円/㎡） | EX4: 面積単価 （万円/坪） | EY4: 床面積の合計 （㎡） | EZ4: 工事費予定額（万円） | FA4: 面積単価 （万円/㎡） | FB4: 面積単価 （万円/坪） | FC4: 床面積の合計 （㎡） | FD4: 工事費予定額（万円） | FE4: 面積単価 （万円/㎡） | FF4: 面積単価 （万円/坪） | FG4: 床面積の合計 （㎡） | FH4: 工事費予定額（万円） | FI4: 面積単価 （万円/㎡） | FJ4: 面積単価 （万円/坪） | FK4: 床面積の合計 （㎡） | FL4: 工事費予定額（万円） | FM4: 面積単価 （万円/㎡） | FN4: 面積単価 （万円/坪） | FO4: 床面積の合計 （㎡） | FP4: 工事費予定額（万円） | FQ4: 面積単価 （万円/㎡） | FR4: 面積単価 （万円/坪） | FS4: 床面積の合計 （㎡） | FT4: 工事費予定額（万円） | FU4: 面積単価 （万円/㎡） | FV4: 面積単価 （万円/坪） | FW4: 床面積の合計 （㎡） | FX4: 工事費予定額（万円） | FY4: 面積単価 （万円/㎡） | FZ4: 面積単価 （万円/坪）
B5: 事務所 | C5: 4986837 | D5: 138290050 | E5: =D5/C5 | F5: =E5*3.30578512 | G5: 304427 | H5: 9964888 | I5: =H5/G5 | J5: =I5*3.30578512 | K5: 234568 | L5: 7178890 | M5: =L5/K5 | N5: =M5*3.30578512 | O5: 326568 | P5: 8655630 | Q5: =P5/O5 | R5: =Q5*3.30578512 | S5: 372268 | T5: 11180130 | U5: =T5/S5 | V5: =U5*3.30578512 | W5: 251106 | X5: 9823521 | Y5: =X5/W5 | Z5: =Y5*3.30578512 | AA5: 384784 | AB5: 13228464 | AC5: =AB5/AA5 | AD5: =AC5*3.30578512 | AE5: 438227 | AF5: 19316127 | AG5: =AF5/AE5 | AH5: =AG5*3.30578512 | AI5: 288928 | AJ5: 8129108 | AK5: =AJ5/AI5 | AL5: =AK5*3.30578512 | AM5: 416123 | AN5: 18487312 | AO5: =AN5/AM5 | AP5: =AO5*3.30578512 | AQ5: 335080 | AR5: 11983171 | AS5: =AR5/AQ5 | AT5: =AS5*3.30578512 | AU5: 396639 | AV5: 14275145 | AW5: =AV5/AU5 | AX5: =AW5*3.30578512 | AY5: 243333 | AZ5: 11055431 | BA5: =AZ5/AY5 | BB5: =BA5*3.30578512 | BC5: 265880 | BD5: 9030358 | BE5: =BD5/BC5 | BF5: =BE5*3.30578512 | BG5: 252616 | BH5: 8814267 | BI5: =BH5/BG5 | BJ5: =BI5*3.30578512 | BK5: 262835 | BL5: 9011710 | BM5: =BL5/BK5 | BN5: =BM5*3.30578512 | BO5: 375752 | BP5: 13476755 | BQ5: =BP5/BO5 | BR5: =BQ5*3.30578512 | BS5: 265069 | BT5: 9528771 | BU5: =BT5/BS5 | BV5: =BU5*3.30578512 | BW5: 283220 | BX5: 10474266 | BY5: =BX5/BW5 | BZ5: =BY5*3.30578512 | CA5: 371653 | CB5: 17028276 | CC5: =CB5/CA5 | CD5: =CC5*3.30578512 | CE5: 177442 | CF5: 6836406 | CG5: =CF5/CE5 | CH5: =CG5*3.30578512 | CI5: 264665 | CJ5: 10186205 | CK5: =CJ5/CI5 | CL5: =CK5*3.30578512 | CM5: 301774 | CN5: 11024756 | CO5: =CN5/CM5 | CP5: =CO5*3.30578512 | CQ5: 293557 | CR5: 10566113 | CS5: =CR5/CQ5 | CT5: =CS5*3.30578512 | CU5: 772017 | CV5: 49470449 | CW5: =CV5/CU5 | CX5: =CW5*3.30578512 | CY5: 696891 | CZ5: 28702203 | DA5: =CZ5/CY5 | DB5: =DA5*3.30578512 | DC5: 294618 | DD5: 12178890 | DE5: =DD5/DC5 | DF5: =DE5*3.30578512 | DG5: 609659 | DH5: 25614822 | DI5: =DH5/DG5 | DJ5: =DI5*3.30578512 | DK5: 346102 | DL5: 15827781 | DM5: =DL5/DK5 | DN5: =DM5*3.30578512 | DO5: 350082 | DP5: 8443971 | DQ5: =DP5/DO5 | DR5: =DQ5*3.30578512 | DS5: 265989 | DT5: 12465579 | DU5: =DT5/DS5 | DV5: =DU5*3.30578512 | DW5: 628940 | DX5: 25489877 | DY5: =DX5/DW5 | DZ5: =DY5*3.30578512 | EA5: 166485 | EB5: 7412704 | EC5: =EB5/EA5 | ED5: =EC5*3.30578512 | EE5: 274097 | EF5: 11321662 | EG5: =EF5/EE5 | EH5: =EG5*3.30578512 | EI5: 254290 | EJ5: 10139886 | EK5: =EJ5/EI5 | EL5: =EK5*3.30578512 | EM5: 170842 | EN5: 6032659 | EO5: =EN5/EM5 | EP5: =EO5*3.30578512 | EQ5: 206504 | ER5: 8393466 | ES5: =ER5/EQ5 | ET5: =ES5*3.30578512 | EU5: 266043 | EV5: 12105799 | EW5: =EV5/EU5 | EX5: =EW5*3.30578512 | EY5: 186444 | EZ5: 6580223.6 | FA5: =EZ5/EY5 | FB5: =FA5*3.30578512 | FC5: 539369 | FD5: 38448948 | FE5: =FD5/FC5 | FF5: =FE5*3.30578512 | FG5: 331956 | FH5: 16259901 | FI5: =FH5/FG5 | FJ5: =FI5*3.30578512 | FK5: 266452 | FL5: 13057560 | FM5: =FL5/FK5 | FN5: =FM5*3.30578512 | FQ5: =FP5/FO5 | FR5: =FQ5*3.30578512 | FU5: =FT5/FS5 | FV5: =FU5*3.30578512 | FY5: =FX5/FW5 | FZ5: =FY5*3.30578512
B6: 店舗 | C6: 5648530 | D6: 91415609 | E6: =D6/C6 | F6: =E6*3.30578512 | G6: 235062 | H6: 4409546 | I6: =H6/G6 | J6: =I6*3.30578512 | K6: 340618 | L6: 5562274 | M6: =L6/K6 | N6: =M6*3.30578512 | O6: 285237 | P6: 4767054 | Q6: =P6/O6 | R6: =Q6*3.30578512 | S6: 376830 | T6: 6137473 | U6: =T6/S6 | V6: =U6*3.30578512 | W6: 293027 | X6: 4772590 | Y6: =X6/W6 | Z6: =Y6*3.30578512 | AA6: 364727 | AB6: 6242425 | AC6: =AB6/AA6 | AD6: =AC6*3.30578512 | AE6: 409659 | AF6: 6185950 | AG6: =AF6/AE6 | AH6: =AG6*3.30578512 | AI6: 259968 | AJ6: 4368510 | AK6: =AJ6/AI6 | AL6: =AK6*3.30578512 | AM6: 283028 | AN6: 4752291 | AO6: =AN6/AM6 | AP6: =AO6*3.30578512 | AQ6: 297073 | AR6: 5803999 | AS6: =AR6/AQ6 | AT6: =AS6*3.30578512 | AU6: 297961 | AV6: 6201695 | AW6: =AV6/AU6 | AX6: =AW6*3.30578512 | AY6: 336799 | AZ6: 7061378 | BA6: =AZ6/AY6 | BB6: =BA6*3.30578512 | BC6: 349495 | BD6: 6533442 | BE6: =BD6/BC6 | BF6: =BE6*3.30578512 | BG6: 299766 | BH6: 9026374 | BI6: =BH6/BG6 | BJ6: =BI6*3.30578512 | BK6: 265050 | BL6: 4385844 | BM6: =BL6/BK6 | BN6: =BM6*3.30578512 | BO6: 301640 | BP6: 5766701 | BQ6: =BP6/BO6 | BR6: =BQ6*3.30578512 | BS6: 273555 | BT6: 5429301 | BU6: =BT6/BS6 | BV6: =BU6*3.30578512 | BW6: 242463 | BX6: 5250744 | BY6: =BX6/BW6 | BZ6: =BY6*3.30578512 | CA6: 260084 | CB6: 4704308 | CC6: =CB6/CA6 | CD6: =CC6*3.30578512 | CE6: 293055 | CF6: 5122568 | CG6: =CF6/CE6 | CH6: =CG6*3.30578512 | CI6: 319914 | CJ6: 5949907 | CK6: =CJ6/CI6 | CL6: =CK6*3.30578512 | CM6: 373898 | CN6: 6937033 | CO6: =CN6/CM6 | CP6: =CO6*3.30578512 | CQ6: 259485 | CR6: 5528798 | CS6: =CR6/CQ6 | CT6: =CS6*3.30578512 | CU6: 271390 | CV6: 5482636 | CW6: =CV6/CU6 | CX6: =CW6*3.30578512 | CY6: 251489 | CZ6: 5666683 | DA6: =CZ6/CY6 | DB6: =DA6*3.30578512 | DC6: 183913 | DD6: 3718826 | DE6: =DD6/DC6 | DF6: =DE6*3.30578512 | DG6: 251143 | DH6: 5111682 | DI6: =DH6/DG6 | DJ6: =DI6*3.30578512 | DK6: 508490 | DL6: 14852741 | DM6: =DL6/DK6 | DN6: =DM6*3.30578512 | DO6: 254162 | DP6: 5601602 | DQ6: =DP6/DO6 | DR6: =DQ6*3.30578512 | DS6: 258448 | DT6: 5469074 | DU6: =DT6/DS6 | DV6: =DU6*3.30578512 | DW6: 305800 | DX6: 5297357 | DY6: =DX6/DW6 | DZ6: =DY6*3.30578512 | EA6: 331828 | EB6: 7277925 | EC6: =EB6/EA6 | ED6: =EC6*3.30578512 | EE6: 251692 | EF6: 5649538 | EG6: =EF6/EE6 | EH6: =EG6*3.30578512 | EI6: 210277 | EJ6: 5070897 | EK6: =EJ6/EI6 | EL6: =EK6*3.30578512 | EM6: 232139 | EN6: 5033326 | EO6: =EN6/EM6 | EP6: =EO6*3.30578512 | EQ6: 288301 | ER6: 5920779 | ES6: =ER6/EQ6 | ET6: =ES6*3.30578512 | EU6: 268000 | EV6: 7319344.1 | EW6: =EV6/EU6 | EX6: =EW6*3.30578512 | EY6: 182826 | EZ6: 4543917.8 | FA6: =EZ6/EY6 | FB6: =FA6*3.30578512 | FC6: 315483 | FD6: 10934838 | FE6: =FD6/FC6 | FF6: =FE6*3.30578512 | FG6: 360430 | FH6: 12264372 | FI6: =FH6/FG6 | FJ6: =FI6*3.30578512 | FK6: 351659 | FL6: 7324507.7 | FM6: =FL6/FK6 | FN6: =FM6*3.30578512 | FQ6: =FP6/FO6 | FR6: =FQ6*3.30578512 | FU6: =FT6/FS6 | FV6: =FU6*3.30578512 | FY6: =FX6/FW6 | FZ6: =FY6*3.30578512
B7: 工場及び作業場 | C7: 8378701 | D7: 151709668 | E7: =D7/C7 | F7: =E7*3.30578512 | G7: 461179 | H7: 11699628 | I7: =H7/G7 | J7: =I7*3.30578512 | K7: 576152 | L7: 14477709 | M7: =L7/K7 | N7: =M7*3.30578512 | O7: 634383 | P7: 13578836 | Q7: =P7/O7 | R7: =Q7*3.30578512 | S7: 929291 | T7: 25142992 | U7: =T7/S7 | V7: =U7*3.30578512 | W7: 624765 | X7: 12090194 | Y7: =X7/W7 | Z7: =Y7*3.30578512 | AA7: 896466 | AB7: 21601128 | AC7: =AB7/AA7 | AD7: =AC7*3.30578512 | AE7: 674375 | AF7: 12666144 | AG7: =AF7/AE7 | AH7: =AG7*3.30578512 | AI7: 693613 | AJ7: 18737249 | AK7: =AJ7/AI7 | AL7: =AK7*3.30578512 | AM7: 543075 | AN7: 15759087 | AO7: =AN7/AM7 | AP7: =AO7*3.30578512 | AQ7: 705775 | AR7: 19656272 | AS7: =AR7/AQ7 | AT7: =AS7*3.30578512 | AU7: 575926 | AV7: 14206123 | AW7: =AV7/AU7 | AX7: =AW7*3.30578512 | AY7: 663086 | AZ7: 18570676 | BA7: =AZ7/AY7 | BB7: =BA7*3.30578512 | BC7: 518150 | BD7: 13016740 | BE7: =BD7/BC7 | BF7: =BE7*3.30578512 | BG7: 538992 | BH7: 13018503 | BI7: =BH7/BG7 | BJ7: =BI7*3.30578512 | BK7: 531918 | BL7: 15139970 | BM7: =BL7/BK7 | BN7: =BM7*3.30578512 | BO7: 869886 | BP7: 25825737 | BQ7: =BP7/BO7 | BR7: =BQ7*3.30578512 | BS7: 435893 | BT7: 11764341 | BU7: =BT7/BS7 | BV7: =BU7*3.30578512 | BW7: 527697 | BX7: 18187780 | BY7: =BX7/BW7 | BZ7: =BY7*3.30578512 | CA7: 509297 | CB7: 15393273 | CC7: =CB7/CA7 | CD7: =CC7*3.30578512 | CE7: 361341 | CF7: 9577597 | CG7: =CF7/CE7 | CH7: =CG7*3.30578512 | CI7: 769521 | CJ7: 36413143 | CK7: =CJ7/CI7 | CL7: =CK7*3.30578512 | CM7: 522592 | CN7: 20713834 | CO7: =CN7/CM7 | CP7: =CO7*3.30578512 | CQ7: 629812 | CR7: 24095807 | CS7: =CR7/CQ7 | CT7: =CS7*3.30578512 | CU7: 530454 | CV7: 15670166 | CW7: =CV7/CU7 | CX7: =CW7*3.30578512 | CY7: 704081 | CZ7: 25256331 | DA7: =CZ7/CY7 | DB7: =DA7*3.30578512 | DC7: 521230 | DD7: 15818107 | DE7: =DD7/DC7 | DF7: =DE7*3.30578512 | DG7: 539736 | DH7: 20160905 | DI7: =DH7/DG7 | DJ7: =DI7*3.30578512 | DK7: 765476 | DL7: 27470352 | DM7: =DL7/DK7 | DN7: =DM7*3.30578512 | DO7: 461489 | DP7: 15973688 | DQ7: =DP7/DO7 | DR7: =DQ7*3.30578512 | DS7: 541315 | DT7: 16496767 | DU7: =DT7/DS7 | DV7: =DU7*3.30578512 | DW7: 515771 | DX7: 15552540 | DY7: =DX7/DW7 | DZ7: =DY7*3.30578512 | EA7: 664134 | EB7: 28924634 | EC7: =EB7/EA7 | ED7: =EC7*3.30578512 | EE7: 588359 | EF7: 19307098 | EG7: =EF7/EE7 | EH7: =EG7*3.30578512 | EI7: 584507 | EJ7: 24734102 | EK7: =EJ7/EI7 | EL7: =EK7*3.30578512 | EM7: 458530 | EN7: 13199930 | EO7: =EN7/EM7 | EP7: =EO7*3.30578512 | EQ7: 498123 | ER7: 16397926 | ES7: =ER7/EQ7 | ET7: =ES7*3.30578512 | EU7: 361898 | EV7: 14097829 | EW7: =EV7/EU7 | EX7: =EW7*3.30578512 | EY7: 448540 | EZ7: 20530172 | FA7: =EZ7/EY7 | FB7: =FA7*3.30578512 | FC7: 407575 | FD7: 14030443 | FE7: =FD7/FC7 | FF7: =FE7*3.30578512 | FG7: 619321 | FH7: 21840277 | FI7: =FH7/FG7 | FJ7: =FI7*3.30578512 | FK7: 595452 | FL7: 26572301 | FM7: =FL7/FK7 | FN7: =FM7*3.30578512 | FQ7: =FP7/FO7 | FR7: =FQ7*3.30578512 | FU7: =FT7/FS7 | FV7: =FU7*3.30578512 | FY7: =FX7/FW7 | FZ7: =FY7*3.30578512
B8: 倉庫 | C8: 6068912 | D8: 71338916 | E8: =D8/C8 | F8: =E8*3.30578512 | G8: 835125 | H8: 10518520 | I8: =H8/G8 | J8: =I8*3.30578512 | K8: 775039 | L8: 10489793 | M8: =L8/K8 | N8: =M8*3.30578512 | O8: 912194 | P8: 11744726 | Q8: =P8/O8 | R8: =Q8*3.30578512 | S8: 881069 | T8: 11962789 | U8: =T8/S8 | V8: =U8*3.30578512 | W8: 852317 | X8: 11001456 | Y8: =X8/W8 | Z8: =Y8*3.30578512 | AA8: 963165 | AB8: 13762764 | AC8: =AB8/AA8 | AD8: =AC8*3.30578512 | AE8: 931010 | AF8: 14396013 | AG8: =AF8/AE8 | AH8: =AG8*3.30578512 | AI8: 660707 | AJ8: 9569279 | AK8: =AJ8/AI8 | AL8: =AK8*3.30578512 | AM8: 572632 | AN8: 8144155 | AO8: =AN8/AM8 | AP8: =AO8*3.30578512 | AQ8: 462154 | AR8: 7709515 | AS8: =AR8/AQ8 | AT8: =AS8*3.30578512 | AU8: 600119 | AV8: 8565731 | AW8: =AV8/AU8 | AX8: =AW8*3.30578512 | AY8: 672464 | AZ8: 9951811 | BA8: =AZ8/AY8 | BB8: =BA8*3.30578512 | BC8: 674938 | BD8: 10530530 | BE8: =BD8/BC8 | BF8: =BE8*3.30578512 | BG8: 900471 | BH8: 12993465 | BI8: =BH8/BG8 | BJ8: =BI8*3.30578512 | BK8: 346787 | BL8: 5546101 | BM8: =BL8/BK8 | BN8: =BM8*3.30578512 | BO8: 1025089 | BP8: 14773342 | BQ8: =BP8/BO8 | BR8: =BQ8*3.30578512 | BS8: 564527 | BT8: 8541089 | BU8: =BT8/BS8 | BV8: =BU8*3.30578512 | BW8: 498046 | BX8: 8652166 | BY8: =BX8/BW8 | BZ8: =BY8*3.30578512 | CA8: 489596 | CB8: 7565679 | CC8: =CB8/CA8 | CD8: =CC8*3.30578512 | CE8: 674749 | CF8: 11295329 | CG8: =CF8/CE8 | CH8: =CG8*3.30578512 | CI8: 566910 | CJ8: 10583923 | CK8: =CJ8/CI8 | CL8: =CK8*3.30578512 | CM8: 813132 | CN8: 17541418 | CO8: =CN8/CM8 | CP8: =CO8*3.30578512 | CQ8: 431285 | CR8: 7939075 | CS8: =CR8/CQ8 | CT8: =CS8*3.30578512 | CU8: 547167 | CV8: 8335203 | CW8: =CV8/CU8 | CX8: =CW8*3.30578512 | CY8: 471248 | CZ8: 7460266 | DA8: =CZ8/CY8 | DB8: =DA8*3.30578512 | DC8: 769671 | DD8: 12584915 | DE8: =DD8/DC8 | DF8: =DE8*3.30578512 | DG8: 535000 | DH8: 9907385 | DI8: =DH8/DG8 | DJ8: =DI8*3.30578512 | DK8: 633476 | DL8: 11687494 | DM8: =DL8/DK8 | DN8: =DM8*3.30578512 | DO8: 534316 | DP8: 8145786 | DQ8: =DP8/DO8 | DR8: =DQ8*3.30578512 | DS8: 824075 | DT8: 13859993 | DU8: =DT8/DS8 | DV8: =DU8*3.30578512 | DW8: 533993 | DX8: 9059516 | DY8: =DX8/DW8 | DZ8: =DY8*3.30578512 | EA8: 422016 | EB8: 10597770 | EC8: =EB8/EA8 | ED8: =EC8*3.30578512 | EE8: 918818 | EF8: 16429638 | EG8: =EF8/EE8 | EH8: =EG8*3.30578512 | EI8: 672820 | EJ8: 10715865 | EK8: =EJ8/EI8 | EL8: =EK8*3.30578512 | EM8: 859998 | EN8: 17432970 | EO8: =EN8/EM8 | EP8: =EO8*3.30578512 | EQ8: 685091 | ER8: 12932026 | ES8: =ER8/EQ8 | ET8: =ES8*3.30578512 | EU8: 637391 | EV8: 14475455 | EW8: =EV8/EU8 | EX8: =EW8*3.30578512 | EY8: 846196 | EZ8: 17147341 | FA8: =EZ8/EY8 | FB8: =FA8*3.30578512 | FC8: 450890 | FD8: 8036493.1 | FE8: =FD8/FC8 | FF8: =FE8*3.30578512 | FG8: 462406 | FH8: 9510154.6 | FI8: =FH8/FG8 | FJ8: =FI8*3.30578512 | FK8: 655850 | FL8: 14292666 | FM8: =FL8/FK8 | FN8: =FM8*3.30578512 | FQ8: =FP8/FO8 | FR8: =FQ8*3.30578512 | FU8: =FT8/FS8 | FV8: =FU8*3.30578512 | FY8: =FX8/FW8 | FZ8: =FY8*3.30578512
B9: 学校の校舎 | C9: 1386294 | D9: 32660664 | E9: =D9/C9 | F9: =E9*3.30578512 | G9: 41707 | H9: 1257098 | I9: =H9/G9 | J9: =I9*3.30578512 | K9: 46099 | L9: 817146 | M9: =L9/K9 | N9: =M9*3.30578512 | O9: 28892 | P9: 615910 | Q9: =P9/O9 | R9: =Q9*3.30578512 | S9: 55420 | T9: 1672270 | U9: =T9/S9 | V9: =U9*3.30578512 | W9: 101064 | X9: 3428795 | Y9: =X9/W9 | Z9: =Y9*3.30578512 | AA9: 159002 | AB9: 4075445 | AC9: =AB9/AA9 | AD9: =AC9*3.30578512 | AE9: 104728 | AF9: 2873377 | AG9: =AF9/AE9 | AH9: =AG9*3.30578512 | AI9: 144121 | AJ9: 5453098 | AK9: =AJ9/AI9 | AL9: =AK9*3.30578512 | AM9: 72391 | AN9: 1663524 | AO9: =AN9/AM9 | AP9: =AO9*3.30578512 | AQ9: 109123 | AR9: 2766055 | AS9: =AR9/AQ9 | AT9: =AS9*3.30578512 | AU9: 202225 | AV9: 6923977 | AW9: =AV9/AU9 | AX9: =AW9*3.30578512 | AY9: 43313 | AZ9: 1096098 | BA9: =AZ9/AY9 | BB9: =BA9*3.30578512 | BC9: 39246 | BD9: 944029 | BE9: =BD9/BC9 | BF9: =BE9*3.30578512 | BG9: 59265 | BH9: 1946253 | BI9: =BH9/BG9 | BJ9: =BI9*3.30578512 | BK9: 63893 | BL9: 1200093 | BM9: =BL9/BK9 | BN9: =BM9*3.30578512 | BO9: 113460 | BP9: 2994431 | BQ9: =BP9/BO9 | BR9: =BQ9*3.30578512 | BS9: 59127 | BT9: 1557736 | BU9: =BT9/BS9 | BV9: =BU9*3.30578512 | BW9: 74781 | BX9: 2690113 | BY9: =BX9/BW9 | BZ9: =BY9*3.30578512 | CA9: 95736 | CB9: 5035463 | CC9: =CB9/CA9 | CD9: =CC9*3.30578512 | CE9: 42496 | CF9: 1340424 | CG9: =CF9/CE9 | CH9: =CG9*3.30578512 | CI9: 66248 | CJ9: 1746260 | CK9: =CJ9/CI9 | CL9: =CK9*3.30578512 | CM9: 93038 | CN9: 2863704 | CO9: =CN9/CM9 | CP9: =CO9*3.30578512 | CQ9: 84806 | CR9: 3555254 | CS9: =CR9/CQ9 | CT9: =CS9*3.30578512 | CU9: 27220 | CV9: 791133 | CW9: =CV9/CU9 | CX9: =CW9*3.30578512 | CY9: 67724 | CZ9: 2787558 | DA9: =CZ9/CY9 | DB9: =DA9*3.30578512 | DC9: 79088 | DD9: 2635389 | DE9: =DD9/DC9 | DF9: =DE9*3.30578512 | DG9: 59923 | DH9: 1746024 | DI9: =DH9/DG9 | DJ9: =DI9*3.30578512 | DK9: 96462 | DL9: 3082989 | DM9: =DL9/DK9 | DN9: =DM9*3.30578512 | DO9: 41794 | DP9: 1429051 | DQ9: =DP9/DO9 | DR9: =DQ9*3.30578512 | DS9: 60645 | DT9: 1714198 | DU9: =DT9/DS9 | DV9: =DU9*3.30578512 | DW9: 76047 | DX9: 3006457 | DY9: =DX9/DW9 | DZ9: =DY9*3.30578512 | EA9: 38811 | EB9: 1172992 | EC9: =EB9/EA9 | ED9: =EC9*3.30578512 | EE9: 97907 | EF9: 3537671 | EG9: =EF9/EE9 | EH9: =EG9*3.30578512 | EI9: 127139 | EJ9: 6918704 | EK9: =EJ9/EI9 | EL9: =EK9*3.30578512 | EM9: 64270 | EN9: 1724033 | EO9: =EN9/EM9 | EP9: =EO9*3.30578512 | EQ9: 97785 | ER9: 2305605 | ES9: =ER9/EQ9 | ET9: =ES9*3.30578512 | EU9: 54215 | EV9: 2414176.8 | EW9: =EV9/EU9 | EX9: =EW9*3.30578512 | EY9: 59521 | EZ9: 2046943.4 | FA9: =EZ9/EY9 | FB9: =FA9*3.30578512 | FC9: 90752 | FD9: 3601431.8 | FE9: =FD9/FC9 | FF9: =FE9*3.30578512 | FG9: 85456 | FH9: 2622310.3 | FI9: =FH9/FG9 | FJ9: =FI9*3.30578512 | FK9: 58555 | FL9: 1998331.5 | FM9: =FL9/FK9 | FN9: =FM9*3.30578512 | FQ9: =FP9/FO9 | FR9: =FQ9*3.30578512 | FU9: =FT9/FS9 | FV9: =FU9*3.30578512 | FY9: =FX9/FW9 | FZ9: =FY9*3.30578512
B10: 病院・診療所 | C10: 1106860 | D10: 32198273 | E10: =D10/C10 | F10: =E10*3.30578512 | G10: 57385 | H10: 1755028 | I10: =H10/G10 | J10: =I10*3.30578512 | K10: 43562 | L10: 1402723 | M10: =L10/K10 | N10: =M10*3.30578512 | O10: 82304 | P10: 2924934 | Q10: =P10/O10 | R10: =Q10*3.30578512 | S10: 96019 | T10: 3707881 | U10: =T10/S10 | V10: =U10*3.30578512 | W10: 43189 | X10: 1435762 | Y10: =X10/W10 | Z10: =Y10*3.30578512 | AA10: 28557 | AB10: 1059931 | AC10: =AB10/AA10 | AD10: =AC10*3.30578512 | AE10: 56783 | AF10: 2046138 | AG10: =AF10/AE10 | AH10: =AG10*3.30578512 | AI10: 72247 | AJ10: 3036285 | AK10: =AJ10/AI10 | AL10: =AK10*3.30578512 | AM10: 50968 | AN10: 1703512 | AO10: =AN10/AM10 | AP10: =AO10*3.30578512 | AQ10: 132415 | AR10: 4726199 | AS10: =AR10/AQ10 | AT10: =AS10*3.30578512 | AU10: 58545 | AV10: 2537034 | AW10: =AV10/AU10 | AX10: =AW10*3.30578512 | AY10: 58359 | AZ10: 1995069 | BA10: =AZ10/AY10 | BB10: =BA10*3.30578512 | BC10: 72190 | BD10: 2761493 | BE10: =BD10/BC10 | BF10: =BE10*3.30578512 | BG10: 163710 | BH10: 7492181 | BI10: =BH10/BG10 | BJ10: =BI10*3.30578512 | BK10: 29840 | BL10: 1086113 | BM10: =BL10/BK10 | BN10: =BM10*3.30578512 | BO10: 35438 | BP10: 1486760 | BQ10: =BP10/BO10 | BR10: =BQ10*3.30578512 | BS10: 77116 | BT10: 3958952 | BU10: =BT10/BS10 | BV10: =BU10*3.30578512 | BW10: 46232 | BX10: 1816366 | BY10: =BX10/BW10 | BZ10: =BY10*3.30578512 | CA10: 28963 | CB10: 1084974 | CC10: =CB10/CA10 | CD10: =CC10*3.30578512 | CE10: 60497 | CF10: 3091654 | CG10: =CF10/CE10 | CH10: =CG10*3.30578512 | CI10: 26281 | CJ10: 1308569 | CK10: =CJ10/CI10 | CL10: =CK10*3.30578512 | CM10: 45229 | CN10: 2018809 | CO10: =CN10/CM10 | CP10: =CO10*3.30578512 | CQ10: 31937 | CR10: 1354894 | CS10: =CR10/CQ10 | CT10: =CS10*3.30578512 | CU10: 21575 | CV10: 771966 | CW10: =CV10/CU10 | CX10: =CW10*3.30578512 | CY10: 18213 | CZ10: 718820 | DA10: =CZ10/CY10 | DB10: =DA10*3.30578512 | DC10: 61783 | DD10: 2591161 | DE10: =DD10/DC10 | DF10: =DE10*3.30578512 | DG10: 75208 | DH10: 3674094 | DI10: =DH10/DG10 | DJ10: =DI10*3.30578512 | DK10: 39809 | DL10: 1533622 | DM10: =DL10/DK10 | DN10: =DM10*3.30578512 | DO10: 56450 | DP10: 3493040 | DQ10: =DP10/DO10 | DR10: =DQ10*3.30578512 | DS10: 30018 | DT10: 1239589 | DU10: =DT10/DS10 | DV10: =DU10*3.30578512 | DW10: 21802 | DX10: 739533 | DY10: =DX10/DW10 | DZ10: =DY10*3.30578512 | EA10: 17463 | EB10: 662700 | EC10: =EB10/EA10 | ED10: =EC10*3.30578512 | EE10: 50757 | EF10: 2939783 | EG10: =EF10/EE10 | EH10: =EG10*3.30578512 | EI10: 15878 | EJ10: 569335 | EK10: =EJ10/EI10 | EL10: =EK10*3.30578512 | EM10: 85131 | EN10: 5736312 | EO10: =EN10/EM10 | EP10: =EO10*3.30578512 | EQ10: 18176 | ER10: 663243 | ES10: =ER10/EQ10 | ET10: =ES10*3.30578512 | EU10: 17345 | EV10: 624753.38 | EW10: =EV10/EU10 | EX10: =EW10*3.30578512 | EY10: 59787 | EZ10: 3657944 | FA10: =EZ10/EY10 | FB10: =FA10*3.30578512 | FC10: 81632 | FD10: 5121355.7 | FE10: =FD10/FC10 | FF10: =FE10*3.30578512 | FG10: 89374 | FH10: 4527145.6 | FI10: =FH10/FG10 | FJ10: =FI10*3.30578512 | FK10: 39756 | FL10: 2022945.2 | FM10: =FL10/FK10 | FN10: =FM10*3.30578512 | FQ10: =FP10/FO10 | FR10: =FQ10*3.30578512 | FU10: =FT10/FS10 | FV10: =FU10*3.30578512 | FY10: =FX10/FW10 | FZ10: =FY10*3.30578512
B11: その他 | C11: 8608567 | D11: 167466039 | E11: =D11/C11 | F11: =E11*3.30578512 | G11: 468787 | H11: 11628801 | I11: =H11/G11 | J11: =I11*3.30578512 | K11: 554269 | L11: 13303890 | M11: =L11/K11 | N11: =M11*3.30578512 | O11: 475415 | P11: 11484248 | Q11: =P11/O11 | R11: =Q11*3.30578512 | S11: 543839 | T11: 13801597 | U11: =T11/S11 | V11: =U11*3.30578512 | W11: 444209 | X11: 14214159 | Y11: =X11/W11 | Z11: =Y11*3.30578512 | AA11: 525185 | AB11: 12856987 | AC11: =AB11/AA11 | AD11: =AC11*3.30578512 | AE11: 784656 | AF11: 23232064 | AG11: =AF11/AE11 | AH11: =AG11*3.30578512 | AI11: 516754 | AJ11: 14356047 | AK11: =AJ11/AI11 | AL11: =AK11*3.30578512 | AM11: 483962 | AN11: 13861034 | AO11: =AN11/AM11 | AP11: =AO11*3.30578512 | AQ11: 517179 | AR11: 13067907 | AS11: =AR11/AQ11 | AT11: =AS11*3.30578512 | AU11: 493168 | AV11: 12400631 | AW11: =AV11/AU11 | AX11: =AW11*3.30578512 | AY11: 452254 | AZ11: 10896023 | BA11: =AZ11/AY11 | BB11: =BA11*3.30578512 | BC11: 426713 | BD11: 12037838 | BE11: =BD11/BC11 | BF11: =BE11*3.30578512 | BG11: 426628 | BH11: 10028344 | BI11: =BH11/BG11 | BJ11: =BI11*3.30578512 | BK11: 429740 | BL11: 10476952 | BM11: =BL11/BK11 | BN11: =BM11*3.30578512 | BO11: 477653 | BP11: 14518674 | BQ11: =BP11/BO11 | BR11: =BQ11*3.30578512 | BS11: 436991 | BT11: 13656448 | BU11: =BT11/BS11 | BV11: =BU11*3.30578512 | BW11: 441980 | BX11: 13211462 | BY11: =BX11/BW11 | BZ11: =BY11*3.30578512 | CA11: 587762 | CB11: 18266439 | CC11: =CB11/CA11 | CD11: =CC11*3.30578512 | CE11: 507410 | CF11: 15077442 | CG11: =CF11/CE11 | CH11: =CG11*3.30578512 | CI11: 431504 | CJ11: 13681572 | CK11: =CJ11/CI11 | CL11: =CK11*3.30578512 | CM11: 569025 | CN11: 16385060 | CO11: =CN11/CM11 | CP11: =CO11*3.30578512 | CQ11: 384777 | CR11: 12314279 | CS11: =CR11/CQ11 | CT11: =CS11*3.30578512 | CU11: 396343 | CV11: 13183424 | CW11: =CV11/CU11 | CX11: =CW11*3.30578512 | CY11: 382059 | CZ11: 13252033 | DA11: =CZ11/CY11 | DB11: =DA11*3.30578512 | DC11: 423007 | DD11: 22456401 | DE11: =DD11/DC11 | DF11: =DE11*3.30578512 | DG11: 467942 | DH11: 19166153 | DI11: =DH11/DG11 | DJ11: =DI11*3.30578512 | DK11: 690848 | DL11: 28299445 | DM11: =DL11/DK11 | DN11: =DM11*3.30578512 | DO11: 369532 | DP11: 12152064 | DQ11: =DP11/DO11 | DR11: =DQ11*3.30578512 | DS11: 413077 | DT11: 14026501 | DU11: =DT11/DS11 | DV11: =DU11*3.30578512 | DW11: 369620 | DX11: 11544272 | DY11: =DX11/DW11 | DZ11: =DY11*3.30578512 | EA11: 427197 | EB11: 21559705 | EC11: =EB11/EA11 | ED11: =EC11*3.30578512 | EE11: 473210 | EF11: 17192389 | EG11: =EF11/EE11 | EH11: =EG11*3.30578512 | EI11: 432596 | EJ11: 15735547 | EK11: =EJ11/EI11 | EL11: =EK11*3.30578512 | EM11: 344658 | EN11: 10792773 | EO11: =EN11/EM11 | EP11: =EO11*3.30578512 | EQ11: 335412 | ER11: 12330928 | ES11: =ER11/EQ11 | ET11: =ES11*3.30578512 | EU11: 353303 | EV11: 10780340 | EW11: =EV11/EU11 | EX11: =EW11*3.30578512 | EY11: 270559 | EZ11: 12760862 | FA11: =EZ11/EY11 | FB11: =FA11*3.30578512 | FC11: 469145 | FD11: 25382588 | FE11: =FD11/FC11 | FF11: =FE11*3.30578512 | FG11: 1234635 | FH11: 88701906 | FI11: =FH11/FG11 | FJ11: =FI11*3.30578512 | FK11: 358272 | FL11: 22722116 | FM11: =FL11/FK11 | FN11: =FM11*3.30578512 | FQ11: =FP11/FO11 | FR11: =FQ11*3.30578512 | FU11: =FT11/FS11 | FV11: =FU11*3.30578512 | FY11: =FX11/FW11 | FZ11: =FY11*3.30578512
B15: 着工多用途建築物
C16: 2015（基準） | G16: 令和4年1月分 | K16: 令和4年2月分 | O16: 令和4年3月分 | S16: 令和4年4月分 | W16: 令和4年5月分 | AA16: 令和4年6月分 | AE16: 令和4年7月分 | AI16: 令和4年8月分 | AM16: 令和4年9月分 | AQ16: 令和4年10月分 | AU16: 令和4年11月分 | AY16: 令和4年12月分 | BC16: 令和5年1月分 | BG16: 令和5年2月分 | BK16: 令和5年3月分 | BO16: 令和5年4月分 | BS16: 令和5年5月分 | BW16: 令和5年6月分 | CA16: 令和5年7月分 | CE16: 令和5年8月分 | CI16: 令和5年9月分 | CM16: 令和5年10月分 | CQ16: 令和5年11月分 | CU16: 令和5年12月分 | CY16: 令和6年1月分 | DC16: 令和6年2月分 | DG16: 令和6年3月分 | DK16: 令和6年4月分 | DO16: 令和6年5月分 | DS16: 令和6年6月分 | DW16: 令和6年7月分 | EA16: 令和6年8月分 | EE16: 令和6年9月分 | EI16: 令和6年10月分 | EM16: 令和6年11月分 | EQ16: 令和6年12月分 | EU16: 令和7年1月分 | EY16: 令和7年2月分 | FC16: 令和7年3月分 | FG16: 令和7年4月分 | FK16: 令和7年5月分 | FO16: 令和7年6月分 | FS16: 令和7年7月分 | FW16: 令和7年8月分 | GA16: 令和7年9月分 | GE16: 令和7年10月分 | GI16: 令和7年11月分
C17: 床面積の合計 （㎡） | D17: 工事費予定額（万円） | E17: 面積単価 （万円/㎡） | F17: 面積単価 （万円/坪） | G17: 床面積の合計 （㎡） | H17: 工事費予定額（万円） | I17: 面積単価 （万円/㎡） | J17: 面積単価 （万円/坪） | K17: 床面積の合計 （㎡） | L17: 工事費予定額（万円） | M17: 面積単価 （万円/㎡） | N17: 面積単価 （万円/坪） | O17: 床面積の合計 （㎡） | P17: 工事費予定額（万円） | Q17: 面積単価 （万円/㎡） | R17: 面積単価 （万円/坪） | S17: 床面積の合計 （㎡） | T17: 工事費予定額（万円） | U17: 面積単価 （万円/㎡） | V17: 面積単価 （万円/坪） | W17: 床面積の合計 （㎡） | X17: 工事費予定額（万円） | Y17: 面積単価 （万円/㎡） | Z17: 面積単価 （万円/坪） | AA17: 床面積の合計 （㎡） | AB17: 工事費予定額（万円） | AC17: 面積単価 （万円/㎡） | AD17: 面積単価 （万円/坪） | AE17: 床面積の合計 （㎡） | AF17: 工事費予定額（万円） | AG17: 面積単価 （万円/㎡） | AH17: 面積単価 （万円/坪） | AI17: 床面積の合計 （㎡） | AJ17: 工事費予定額（万円） | AK17: 面積単価 （万円/㎡） | AL17: 面積単価 （万円/坪） | AM17: 床面積の合計 （㎡） | AN17: 工事費予定額（万円） | AO17: 面積単価 （万円/㎡） | AP17: 面積単価 （万円/坪） | AQ17: 床面積の合計 （㎡） | AR17: 工事費予定額（万円） | AS17: 面積単価 （万円/㎡） | AT17: 面積単価 （万円/坪） | AU17: 床面積の合計 （㎡） | AV17: 工事費予定額（万円） | AW17: 面積単価 （万円/㎡） | AX17: 面積単価 （万円/坪） | AY17: 床面積の合計 （㎡） | AZ17: 工事費予定額（万円） | BA17: 面積単価 （万円/㎡） | BB17: 面積単価 （万円/坪） | BC17: 床面積の合計 （㎡） | BD17: 工事費予定額（万円） | BE17: 面積単価 （万円/㎡） | BF17: 面積単価 （万円/坪） | BG17: 床面積の合計 （㎡） | BH17: 工事費予定額（万円） | BI17: 面積単価 （万円/㎡） | BJ17: 面積単価 （万円/坪） | BK17: 床面積の合計 （㎡） | BL17: 工事費予定額（万円） | BM17: 面積単価 （万円/㎡） | BN17: 面積単価 （万円/坪） | BO17: 床面積の合計 （㎡） | BP17: 工事費予定額（万円） | BQ17: 面積単価 （万円/㎡） | BR17: 面積単価 （万円/坪） | BS17: 床面積の合計 （㎡） | BT17: 工事費予定額（万円） | BU17: 面積単価 （万円/㎡） | BV17: 面積単価 （万円/坪） | BW17: 床面積の合計 （㎡） | BX17: 工事費予定額（万円） | BY17: 面積単価 （万円/㎡） | BZ17: 面積単価 （万円/坪） | CA17: 床面積の合計 （㎡） | CB17: 工事費予定額（万円） | CC17: 面積単価 （万円/㎡） | CD17: 面積単価 （万円/坪） | CE17: 床面積の合計 （㎡） | CF17: 工事費予定額（万円） | CG17: 面積単価 （万円/㎡） | CH17: 面積単価 （万円/坪） | CI17: 床面積の合計 （㎡） | CJ17: 工事費予定額（万円） | CK17: 面積単価 （万円/㎡） | CL17: 面積単価 （万円/坪） | CM17: 床面積の合計 （㎡） | CN17: 工事費予定額（万円） | CO17: 面積単価 （万円/㎡） | CP17: 面積単価 （万円/坪） | CQ17: 床面積の合計 （㎡） | CR17: 工事費予定額（万円） | CS17: 面積単価 （万円/㎡） | CT17: 面積単価 （万円/坪） | CU17: 床面積の合計 （㎡） | CV17: 工事費予定額（万円） | CW17: 面積単価 （万円/㎡） | CX17: 面積単価 （万円/坪） | CY17: 床面積の合計 （㎡） | CZ17: 工事費予定額（万円） | DA17: 面積単価 （万円/㎡） | DB17: 面積単価 （万円/坪） | DC17: 床面積の合計 （㎡） | DD17: 工事費予定額（万円） | DE17: 面積単価 （万円/㎡） | DF17: 面積単価 （万円/坪） | DG17: 床面積の合計 （㎡） | DH17: 工事費予定額（万円） | DI17: 面積単価 （万円/㎡） | DJ17: 面積単価 （万円/坪） | DK17: 床面積の合計 （㎡） | DL17: 工事費予定額（万円） | DM17: 面積単価 （万円/㎡） | DN17: 面積単価 （万円/坪） | DO17: 床面積の合計 （㎡） | DP17: 工事費予定額（万円） | DQ17: 面積単価 （万円/㎡） | DR17: 面積単価 （万円/坪） | DS17: 床面積の合計 （㎡） | DT17: 工事費予定額（万円） | DU17: 面積単価 （万円/㎡） | DV17: 面積単価 （万円/坪） | DW17: 床面積の合計 （㎡） | DX17: 工事費予定額（万円） | DY17: 面積単価 （万円/㎡） | DZ17: 面積単価 （万円/坪） | EA17: 床面積の合計 （㎡） | EB17: 工事費予定額（万円） | EC17: 面積単価 （万円/㎡） | ED17: 面積単価 （万円/坪） | EE17: 床面積の合計 （㎡） | EF17: 工事費予定額（万円） | EG17: 面積単価 （万円/㎡） | EH17: 面積単価 （万円/坪） | EI17: 床面積の合計 （㎡） | EJ17: 工事費予定額（万円） | EK17: 面積単価 （万円/㎡） | EL17: 面積単価 （万円/坪） | EM17: 床面積の合計 （㎡） | EN17: 工事費予定額（万円） | EO17: 面積単価 （万円/㎡） | EP17: 面積単価 （万円/坪） | EQ17: 床面積の合計 （㎡） | ER17: 工事費予定額（万円） | ES17: 面積単価 （万円/㎡） | ET17: 面積単価 （万円/坪） | EU17: 床面積の合計 （㎡） | EV17: 工事費予定額（万円） | EW17: 面積単価 （万円/㎡） | EX17: 面積単価 （万円/坪） | EY17: 床面積の合計 （㎡） | EZ17: 工事費予定額（万円） | FA17: 面積単価 （万円/㎡） | FB17: 面積単価 （万円/坪） | FC17: 床面積の合計 （㎡） | FD17: 工事費予定額（万円） | FE17: 面積単価 （万円/㎡） | FF17: 面積単価 （万円/坪） | FG17: 床面積の合計 （㎡） | FH17: 工事費予定額（万円） | FI17: 面積単価 （万円/㎡） | FJ17: 面積単価 （万円/坪） | FK17: 床面積の合計 （㎡） | FL17: 工事費予定額（万円） | FM17: 面積単価 （万円/㎡） | FN17: 面積単価 （万円/坪） | FO17: 床面積の合計 （㎡） | FP17: 工事費予定額（万円） | FQ17: 面積単価 （万円/㎡） | FR17: 面積単価 （万円/坪） | FS17: 床面積の合計 （㎡） | FT17: 工事費予定額（万円） | FU17: 面積単価 （万円/㎡） | FV17: 面積単価 （万円/坪） | FW17: 床面積の合計 （㎡） | FX17: 工事費予定額（万円） | FY17: 面積単価 （万円/㎡） | FZ17: 面積単価 （万円/坪） | GA17: 床面積の合計 （㎡） | GB17: 工事費予定額（万円） | GC17: 面積単価 （万円/㎡） | GD17: 面積単価 （万円/坪） | GE17: 床面積の合計 （㎡） | GF17: 工事費予定額（万円） | GG17: 面積単価 （万円/㎡） | GH17: 面積単価 （万円/坪） | GI17: 床面積の合計 （㎡） | GJ17: 工事費予定額（万円） | GK17: 面積単価 （万円/㎡） | GL17: 面積単価 （万円/坪）
B18: 全体 | C18: 1103222 | D18: 19509216 | E18: =D18/C18 | F18: =E18*3.30578512 | G18: 159225 | H18: 5993976 | I18: =H18/G18 | J18: =I18*3.30578512 | K18: 75673 | L18: 1420880 | M18: =L18/K18 | N18: =M18*3.30578512 | O18: 41719 | P18: 1258500 | Q18: =P18/O18 | R18: =Q18*3.30578512 | S18: 36580 | T18: 711484 | U18: =T18/S18 | V18: =U18*3.30578512 | W18: 107748 | X18: 2528819 | Y18: =X18/W18 | Z18: =Y18*3.30578512 | AA18: 102739 | AB18: 3257069 | AC18: =AB18/AA18 | AD18: =AC18*3.30578512 | AE18: 466219 | AF18: 22831606 | AG18: =AF18/AE18 | AH18: =AG18*3.30578512 | AI18: 60919 | AJ18: 1858333 | AK18: =AJ18/AI18 | AL18: =AK18*3.30578512 | AM18: 122998 | AN18: 2556975 | AO18: =AN18/AM18 | AP18: =AO18*3.30578512 | AQ18: 51633 | AR18: 1309923 | AS18: =AR18/AQ18 | AT18: =AS18*3.30578512 | AU18: 143935 | AV18: 5404134 | AW18: =AV18/AU18 | AX18: =AW18*3.30578512 | AY18: 39881 | AZ18: 1205900 | BA18: =AZ18/AY18 | BB18: =BA18*3.30578512 | BC18: 143379 | BD18: 3659626 | BE18: =BD18/BC18 | BF18: =BE18*3.30578512 | BG18: 98141 | BH18: 6161740 | BI18: =BH18/BG18 | BJ18: =BI18*3.30578512 | BK18: 63717 | BL18: 1194731 | BM18: =BL18/BK18 | BN18: =BM18*3.30578512 | BO18: 109508 | BP18: 3975640 | BQ18: =BP18/BO18 | BR18: =BQ18*3.30578512 | BS18: 22215 | BT18: 576600 | BU18: =BT18/BS18 | BV18: =BU18*3.30578512 | BW18: 120167 | BX18: 5057849 | BY18: =BX18/BW18 | BZ18: =BY18*3.30578512 | CA18: 100204 | CB18: 4395390 | CC18: =CB18/CA18 | CD18: =CC18*3.30578512 | CE18: 44090 | CF18: 1815671 | CG18: =CF18/CE18 | CH18: =CG18*3.30578512 | CI18: 40642 | CJ18: 1627548 | CK18: =CJ18/CI18 | CL18: =CK18*3.30578512 | CM18: 156857 | CN18: 5989746 | CO18: =CN18/CM18 | CP18: =CO18*3.30578512 | CQ18: 129724 | CR18: 4570680 | CS18: =CR18/CQ18 | CT18: =CS18*3.30578512 | CU18: 69386 | CV18: 3711854 | CW18: =CV18/CU18 | CX18: =CW18*3.30578512 | CY18: 453605 | CZ18: 17408583 | DA18: =CZ18/CY18 | DB18: =DA18*3.30578512 | DC18: 70556 | DD18: 3013703 | DE18: =DD18/DC18 | DF18: =DE18*3.30578512 | DG18: 332838 | DH18: 15401400 | DI18: =DH18/DG18 | DJ18: =DI18*3.30578512 | DK18: 236995 | DL18: 14028450 | DM18: =DL18/DK18 | DN18: =DM18*3.30578512 | DO18: 108920 | DP18: 2562775 | DQ18: =DP18/DO18 | DR18: =DQ18*3.30578512 | DS18: 55373 | DT18: 2008887 | DU18: =DT18/DS18 | DV18: =DU18*3.30578512 | DW18: 523788 | DX18: 19125330 | DY18: =DX18/DW18 | DZ18: =DY18*3.30578512 | EA18: 126018 | EB18: 10329075 | EC18: =EB18/EA18 | ED18: =EC18*3.30578512 | EE18: 56886 | EF18: 2276608 | EG18: =EF18/EE18 | EH18: =EG18*3.30578512 | EI18: 89961 | EJ18: 3861400 | EK18: =EJ18/EI18 | EL18: =EK18*3.30578512 | EM18: 262130 | EN18: 5048134 | EO18: =EN18/EM18 | EP18: =EO18*3.30578512 | EQ18: 91150 | ER18: 2552985 | ES18: =ER18/EQ18 | ET18: =ES18*3.30578512 | EU18: 126520 | EV18: 4244079 | EW18: =EV18/EU18 | EX18: =EW18*3.30578512 | EY18: 116427 | EZ18: 7631509 | FA18: =EZ18/EY18 | FB18: =FA18*3.30578512 | FC18: 512631 | FD18: 33631871 | FE18: =FD18/FC18 | FF18: =FE18*3.30578512 | FG18: 981465 | FH18: 74897323 | FI18: =FH18/FG18 | FJ18: =FI18*3.30578512 | FK18: 421367 | FL18: 19018430 | FM18: =FL18/FK18 | FN18: =FM18*3.30578512 | FO18: 324000 | FP18: 13701446 | FQ18: =FP18/FO18 | FR18: =FQ18*3.30578512 | FS18: 265842 | FT18: 9772874 | FU18: =FT18/FS18 | FV18: =FU18*3.30578512 | FW18: 258130 | FX18: 14909790 | FY18: =FX18/FW18 | FZ18: =FY18*3.30578512 | GA18: 734078 | GB18: 38824049 | GC18: =GB18/GA18 | GD18: =GC18*3.30578512 | GE18: 274612 | GF18: 10789496 | GG18: =GF18/GE18 | GH18: =GG18*3.30578512 | GI18: 197908 | GJ18: 8660604 | GK18: =GJ18/GI18 | GL18: =GK18*3.30578512
B19: 事務所 | C19: 498519 | D19: 9638971 | E19: =D19/C19 | F19: =E19*3.30578512 | G19: 80650 | H19: 3313000 | I19: =H19/G19 | J19: =I19*3.30578512 | K19: 4639 | L19: 122000 | M19: =L19/K19 | N19: =M19*3.30578512 | O19: 15483 | P19: 580450 | Q19: =P19/O19 | R19: =Q19*3.30578512 | S19: 1714 | T19: 35400 | U19: =T19/S19 | V19: =U19*3.30578512 | W19: 24514 | X19: 969760 | Y19: =X19/W19 | Z19: =Y19*3.30578512 | AA19: 44780 | AB19: 1883437 | AC19: =AB19/AA19 | AD19: =AC19*3.30578512 | AE19: 234789 | AF19: 13363500 | AG19: =AF19/AE19 | AH19: =AG19*3.30578512 | AI19: 2280 | AJ19: 75000 | AK19: =AJ19/AI19 | AL19: =AK19*3.30578512 | AM19: 5892 | AN19: 327700 | AO19: =AN19/AM19 | AP19: =AO19*3.30578512 | AQ19: 797 | AR19: 20184 | AS19: =AR19/AQ19 | AT19: =AS19*3.30578512 | AU19: 29687 | AV19: 1023892 | AW19: =AV19/AU19 | AX19: =AW19*3.30578512 | AY19: 915 | AZ19: 24200 | BA19: =AZ19/AY19 | BB19: =BA19*3.30578512 | BC19: 46977 | BD19: 1820500 | BE19: =BD19/BC19 | BF19: =BE19*3.30578512 | BG19: 22073 | BH19: 1270000 | BI19: =BH19/BG19 | BJ19: =BI19*3.30578512 | BK19: 9274 | BL19: 397100 | BM19: =BL19/BK19 | BN19: =BM19*3.30578512 | BO19: 63729 | BP19: 2824400 | BQ19: =BP19/BO19 | BR19: =BQ19*3.30578512 | BS19: 3286 | BT19: 111200 | BU19: =BT19/BS19 | BV19: =BU19*3.30578512 | BW19: 91302 | BX19: 4254000 | BY19: =BX19/BW19 | BZ19: =BY19*3.30578512 | CA19: 60478 | CB19: 3539990 | CC19: =CB19/CA19 | CD19: =CC19*3.30578512 | CE19: 4796 | CF19: 191500 | CG19: =CF19/CE19 | CH19: =CG19*3.30578512 | CI19: 21176 | CJ19: 1108400 | CK19: =CJ19/CI19 | CL19: =CK19*3.30578512 | CM19: 121848 | CN19: 5081595 | CO19: =CN19/CM19 | CP19: =CO19*3.30578512 | CQ19: 96242 | CR19: 3775665 | CS19: =CR19/CQ19 | CT19: =CS19*3.30578512 | CU19: 4155 | CV19: 149000 | CW19: =CV19/CU19 | CX19: =CW19*3.30578512 | CY19: 412702 | CZ19: 15230143 | DA19: =CZ19/CY19 | DB19: =DA19*3.30578512 | DC19: 31070 | DD19: 706393 | DE19: =DD19/DC19 | DF19: =DE19*3.30578512 | DG19: 305819 | DH19: 14492500 | DI19: =DH19/DG19 | DJ19: =DI19*3.30578512 | DK19: 736 | DL19: 25800 | DM19: =DL19/DK19 | DN19: =DM19*3.30578512 | DO19: 78458 | DP19: 1191275 | DQ19: =DP19/DO19 | DR19: =DQ19*3.30578512 | DS19: 15607 | DT19: 778000 | DU19: =DT19/DS19 | DV19: =DU19*3.30578512 | DW19: 398799 | DX19: 16427800 | DY19: =DX19/DW19 | DZ19: =DY19*3.30578512 | EA19: 2434 | EB19: 170000 | EC19: =EB19/EA19 | ED19: =EC19*3.30578512 | EE19: 11024 | EF19: 689900 | EG19: =EF19/EE19 | EH19: =EG19*3.30578512 | EI19: 32876 | EJ19: 1239800 | EK19: =EJ19/EI19 | EL19: =EK19*3.30578512 | EM19: 1569 | EN19: 88500 | EO19: =EN19/EM19 | EP19: =EO19*3.30578512 | EQ19: 12984 | ER19: 793800 | ES19: =ER19/EQ19 | ET19: =ES19*3.30578512 | EU19: 23484 | EV19: 926228.84 | EW19: =EV19/EU19 | EX19: =EW19*3.30578512 | EY19: 10211 | EZ19: 538339.59 | FA19: =EZ19/EY19 | FB19: =FA19*3.30578512 | FC19: 263207 | FD19: 18687952 | FE19: =FD19/FC19 | FF19: =FE19*3.30578512 | FG19: 120803 | FH19: 7146627.3 | FI19: =FH19/FG19 | FJ19: =FI19*3.30578512 | FK19: 83882 | FL19: 4607638.8 | FM19: =FL19/FK19 | FN19: =FM19*3.30578512 | FO19: 59418 | FP19: 2871328.8 | FQ19: =FP19/FO19 | FR19: =FQ19*3.30578512 | FS19: 66468 | FT19: 3447883.4 | FU19: =FT19/FS19 | FV19: =FU19*3.30578512 | FW19: 57755 | FX19: 5069906.8 | FY19: =FX19/FW19 | FZ19: =FY19*3.30578512 | GA19: 208895 | GB19: 16048052 | GC19: =GB19/GA19 | GD19: =GC19*3.30578512 | GE19: 68750 | GF19: 3714905.3 | GG19: =GF19/GE19 | GH19: =GG19*3.30578512 | GI19: 27803 | GJ19: 1217216 | GK19: =GJ19/GI19 | GL19: =GK19*3.30578512
B20: 店舗 | C20: 227898 | D20: 2802810 | E20: =D20/C20 | F20: =E20*3.30578512 | G20: 1427 | H20: 48000 | I20: =H20/G20 | J20: =I20*3.30578512 | K20: 5729 | L20: 129000 | M20: =L20/K20 | N20: =M20*3.30578512 | O20: 2607 | P20: 87800 | Q20: =P20/O20 | R20: =Q20*3.30578512 | S20: 10534 | T20: 270000 | U20: =T20/S20 | V20: =U20*3.30578512 | W20: 2176 | X20: 67000 | Y20: =X20/W20 | Z20: =Y20*3.30578512 | AA20: 14619 | AB20: 383000 | AC20: =AB20/AA20 | AD20: =AC20*3.30578512 | AE20: 9175 | AF20: 266000 | AG20: =AF20/AE20 | AH20: =AG20*3.30578512 | AI20: 23849 | AJ20: 269649 | AK20: =AJ20/AI20 | AL20: =AK20*3.30578512 | AM20: 15 | AN20: 600 | AO20: =AN20/AM20 | AP20: =AO20*3.30578512 | AQ20: 37199 | AR20: 852022 | AS20: =AR20/AQ20 | AT20: =AS20*3.30578512 | AU20: 15052 | AV20: 600480 | AW20: =AV20/AU20 | AX20: =AW20*3.30578512 | AY20: 3100 | AZ20: 123000 | BA20: =AZ20/AY20 | BB20: =BA20*3.30578512 | BC20: 17347 | BD20: 351914 | BE20: =BD20/BC20 | BF20: =BE20*3.30578512 | BG20: 50847 | BH20: 4401500 | BI20: =BH20/BG20 | BJ20: =BI20*3.30578512 | BK20: 21492 | BL20: 135500 | BM20: =BL20/BK20 | BN20: =BM20*3.30578512 | BO20: 3456 | BP20: 76500 | BQ20: =BP20/BO20 | BR20: =BQ20*3.30578512 | BS20: 3554 | BT20: 142200 | BU20: =BT20/BS20 | BV20: =BU20*3.30578512 | BW20: 9031 | BX20: 267647 | BY20: =BX20/BW20 | BZ20: =BY20*3.30578512 | CA20: 3516 | CB20: 103000 | CC20: =CB20/CA20 | CD20: =CC20*3.30578512 | CE20: 6243 | CF20: 164000 | CG20: =CF20/CE20 | CH20: =CG20*3.30578512 | CI20: 2193 | CJ20: 63500 | CK20: =CJ20/CI20 | CL20: =CK20*3.30578512 | CM20: 1686 | CN20: 15000 | CO20: =CN20/CM20 | CP20: =CO20*3.30578512 | CQ20: 3229 | CR20: 106500 | CS20: =CR20/CQ20 | CT20: =CS20*3.30578512 | CU20: 5603 | CV20: 336700 | CW20: =CV20/CU20 | CX20: =CW20*3.30578512 | CY20: 1251 | CZ20: 80000 | DA20: =CZ20/CY20 | DB20: =DA20*3.30578512 | DC20: 2524 | DD20: 84900 | DE20: =DD20/DC20 | DF20: =DE20*3.30578512 | DG20: 0 | DH20: 0 | DI20: =DH20/DG20 | DJ20: =DI20*3.30578512 | DK20: 109631 | DL20: 5518000 | DM20: =DL20/DK20 | DN20: =DM20*3.30578512 | DO20: 9397 | DP20: 378000 | DQ20: =DP20/DO20 | DR20: =DQ20*3.30578512 | DS20: 299 | DT20: 12000 | DU20: =DT20/DS20 | DV20: =DU20*3.30578512 | DW20: 3365 | DX20: 178500 | DY20: =DX20/DW20 | DZ20: =DY20*3.30578512 | EA20: 25997 | EB20: 684500 | EC20: =EB20/EA20 | ED20: =EC20*3.30578512 | EE20: 24936 | EF20: 803601 | EG20: =EF20/EE20 | EH20: =EG20*3.30578512 | EI20: 6754 | EJ20: 476000 | EK20: =EJ20/EI20 | EL20: =EK20*3.30578512 | EM20: 1806 | EN20: 7270 | EO20: =EN20/EM20 | EP20: =EO20*3.30578512 | EQ20: 3344 | ER20: 151275 | ES20: =ER20/EQ20 | ET20: =ES20*3.30578512 | EU20: 31865 | EV20: 748199.44 | EW20: =EV20/EU20 | EX20: =EW20*3.30578512 | EY20: 7857 | EZ20: 301931.63 | FA20: =EZ20/EY20 | FB20: =FA20*3.30578512 | FC20: 85817 | FD20: 5595189.6 | FE20: =FD20/FC20 | FF20: =FE20*3.30578512 | FG20: 87123 | FH20: 5990048.3 | FI20: =FH20/FG20 | FJ20: =FI20*3.30578512 | FK20: 44228 | FL20: 1533767.9 | FM20: =FL20/FK20 | FN20: =FM20*3.30578512 | FO20: 46931 | FP20: 1738413.5 | FQ20: =FP20/FO20 | FR20: =FQ20*3.30578512 | FS20: 24433 | FT20: 1049753.3 | FU20: =FT20/FS20 | FV20: =FU20*3.30578512 | FW20: 20293 | FX20: 796481.47 | FY20: =FX20/FW20 | FZ20: =FY20*3.30578512 | GA20: 41087 | GB20: 2476355.7 | GC20: =GB20/GA20 | GD20: =GC20*3.30578512 | GE20: 113478 | GF20: 3633237.9 | GG20: =GF20/GE20 | GH20: =GG20*3.30578512 | GI20: 81814 | GJ20: 4079044 | GK20: =GJ20/GI20 | GL20: =GK20*3.30578512
