Workbook

Sheet 鉄骨鉄筋コンクリート造
A1: 鉄骨鉄筋コンクリート造
C3: 2015（基準） | G3: 令和4年2月分 | K3: 令和4年5月分 | O3: 令和4年8月分 | S3: 令和4年11月分 | W3: 令和5年2月分 | AA3: 令和5年5月分 | AE3: 令和5年8月分 | AI3: 令和5年11月分 | AM3: 令和6年2月分 | AQ3: 令和6年5月分 | AU3: 令和6年8月分 | AY3: 令和6年11月分 | BC3: 令和7年2月分 | BG3: 令和7年5月分
C4: 床面積の合計 （㎡） | D4: 工事費予定額（万円） | E4: 面積単価 （万円/㎡） | F4: 面積単価 （万円/坪） | G4: 床面積の合計 （㎡） | H4: 工事費予定額（万円） | I4: 面積単価 （万円/㎡） | J4: 面積単価 （万円/坪） | K4: 床面積の合計 （㎡） | L4: 工事費予定額（万円） | M4: 面積単価 （万円/㎡） | N4: 面積単価 （万円/坪） | O4: 床面積の合計 （㎡） | P4: 工事費予定額（万円） | Q4: 面積単価 （万円/㎡） | R4: 面積単価 （万円/坪） | S4: 床面積の合計 （㎡） | T4: 工事費予定額（万円） | U4: 面積単価 （万円/㎡） | V4: 面積単価 （万円/坪） | W4: 床面積の合計 （㎡） | X4: 工事費予定額（万円） | Y4: 面積単価 （万円/㎡） | Z4: 面積単価 （万円/坪） | AA4: 床面積の合計 （㎡） | AB4: 工事費予定額（万円） | AC4: 面積単価 （万円/㎡） | AD4: 面積単価 （万円/坪） | AE4: 床面積の合計 （㎡） | AF4: 工事費予定額（万円） | AG4: 面積単価 （万円/㎡） | AH4: 面積単価 （万円/坪） | AI4: 床面積の合計 （㎡） | AJ4: 工事費予定額（万円） | AK4: 面積単価 （万円/㎡） | AL4: 面積単価 （万円/坪） | AM4: 床面積の合計 （㎡） | AN4: 工事費予定額（万円） | AO4: 面積単価 （万円/㎡） | AP4: 面積単価 （万円/坪） | AQ4: 床面積の合計 （㎡） | AR4: 工事費予定額（万円） | AS4: 面積単価 （万円/㎡） | AT4: 面積単価 （万円/坪） | AU4: 床面積の合計 （㎡） | AV4: 工事費予定額（万円） | AW4: 面積単価 （万円/㎡） | AX4: 面積単価 （万円/坪） | AY4: 床面積の合計 （㎡） | AZ4: 工事費予定額（万円） | BA4: 面積単価 （万円/㎡） | BB4: 面積単価 （万円/坪） | BC4: 床面積の合計 （㎡） | BD4: 工事費予定額（万円） | BE4: 面積単価 （万円/㎡） | BF4: 面積単価 （万円/坪） | BG4: 床面積の合計 （㎡） | BH4: 工事費予定額（万円） | BI4: 面積単価 （万円/㎡） | BJ4: 面積単価 （万円/坪）
B5: 事務所 | C5: 376276 | D5: 14713671 | E5: =D5/C5 -> 39.1034 | F5: =E5*3.30578512 -> 129.26744 | G5: 14473 | H5: 703002 | I5: =H5/G5 -> 48.573343 | J5: =I5*3.30578512 -> 160.57304 | K5: 12930 | L5: 468976 | M5: =L5/K5 -> 36.270379 | N5: =M5*3.30578512 -> 119.90208 | O5: 2176 | P5: 33947 | Q5: =P5/O5 -> 15.600643 | R5: =Q5*3.30578512 -> 51.572375 | S5: 6950 | T5: 278981 | U5: =T5/S5 -> 40.141151 | V5: =U5*3.30578512 -> 132.69802 | W5: 15791 | X5: 679000 | Y5: =X5/W5 -> 42.999177 | Z5: =Y5*3.30578512 -> 142.14604 | AA5: 13436 | AB5: 844000 | AC5: =AB5/AA5 -> 62.816314 | AD5: =AC5*3.30578512 -> 207.65724 | AE5: 29255 | AF5: 1503500 | AG5: =AF5/AE5 -> 51.392924 | AH5: =AG5*3.30578512 -> 169.89396 | AI5: 6133 | AJ5: 385200 | AK5: =AJ5/AI5 -> 62.807761 | AL5: =AK5*3.30578512 -> 207.62896 | AM5: 0 | AN5: 0 | AO5: =AN5/AM5 -> #DIV/0! | AP5: =AO5*3.30578512 -> #DIV/0! | AQ5: 73716 | AR5: 4000000 | AS5: =AR5/AQ5 -> 54.262304 | AT5: =AS5*3.30578512 -> 179.37952 | AU5: 3487 | AV5: 213200 | AW5: =AV5/AU5 -> 61.141382 | AX5: =AW5*3.30578512 -> 202.12027 | AY5: 43887 | AZ5: 2383000 | BA5: =AZ5/AY5 -> 54.298539 | BB5: =BA5*3.30578512 -> 179.4993 | BC5: 3548 | BD5: 325057.04 | BE5: =BD5/BC5 -> 91.616978 | BF5: =BE5*3.30578512 -> 302.86604 | BG5: 1988 | BH5: 96136 | BI5: =BH5/BG5 -> 48.358149 | BJ5: =BI5*3.30578512 -> 159.86165
B6: 店舗 | C6: 47766 | D6: 1192080 | E6: =D6/C6 -> 24.956664 | F6: =E6*3.30578512 -> 82.501368 | G6: 505 | H6: 30000 | I6: =H6/G6 -> 59.405941 | J6: =I6*3.30578512 -> 196.38327 | K6: 178 | L6: 2250 | M6: =L6/K6 -> 12.640449 | N6: =M6*3.30578512 -> 41.78661 | O6: 7218 | P6: 122430 | Q6: =P6/O6 -> 16.961762 | R6: =Q6*3.30578512 -> 56.071941 | S6: 1194 | T6: 10000 | U6: =T6/S6 -> 8.3752094 | V6: =U6*3.30578512 -> 27.686643 | W6: 5739 | X6: 177000 | Y6: =X6/W6 -> 30.84161 | Z6: =Y6*3.30578512 -> 101.95574 | AA6: 0 | AB6: 0 | AC6: =AB6/AA6 -> #DIV/0! | AD6: =AC6*3.30578512 -> #DIV/0! | AE6: 309 | AF6: 30000 | AG6: =AF6/AE6 -> 97.087379 | AH6: =AG6*3.30578512 -> 320.95001 | AI6: 0 | AJ6: 0 | AK6: =AJ6/AI6 -> #DIV/0! | AL6: =AK6*3.30578512 -> #DIV/0! | AM6: 0 | AN6: 0 | AO6: =AN6/AM6 -> #DIV/0! | AP6: =AO6*3.30578512 -> #DIV/0! | AQ6: 285 | AR6: 100 | AS6: =AR6/AQ6 -> 0.35087719 | AT6: =AS6*3.30578512 -> 1.1599246 | AU6: 243 | AV6: 16057 | AW6: =AV6/AU6 -> 66.078189 | AX6: =AW6*3.30578512 -> 218.44029 | AY6: 120 | AZ6: 1650 | BA6: =AZ6/AY6 -> 13.75 | BB6: =BA6*3.30578512 -> 45.454545 | BC6: 0 | BD6: 0 | BE6: =BD6/BC6 -> #DIV/0! | BF6: =BE6*3.30578512 -> #DIV/0! | BG6: 173 | BH6: 5000 | BI6: =BH6/BG6 -> 28.901734 | BJ6: =BI6*3.30578512 -> 95.542923
B7: 工場及び作業場 | C7: 99563 | D7: 2195253 | E7: =D7/C7 -> 22.048884 | F7: =E7*3.30578512 -> 72.888871 | G7: 42149 | H7: 1962412 | I7: =H7/G7 -> 46.558922 | J7: =I7*3.30578512 -> 153.91379 | K7: 233702 | L7: 16079466 | M7: =L7/K7 -> 68.803288 | N7: =M7*3.30578512 -> 227.44889 | O7: 540 | P7: 10000 | Q7: =P7/O7 -> 18.518519 | R7: =Q7*3.30578512 -> 61.218243 | S7: 0 | T7: 0 | U7: =T7/S7 -> #DIV/0! | V7: =U7*3.30578512 -> #DIV/0! | W7: 779 | X7: 15879 | Y7: =X7/W7 -> 20.383825 | Z7: =Y7*3.30578512 -> 67.384547 | AA7: 0 | AB7: 0 | AC7: =AB7/AA7 -> #DIV/0! | AD7: =AC7*3.30578512 -> #DIV/0! | AE7: 22641 | AF7: 315800 | AG7: =AF7/AE7 -> 13.948147 | AH7: =AG7*3.30578512 -> 46.109577 | AI7: 0 | AJ7: 0 | AK7: =AJ7/AI7 -> #DIV/0! | AL7: =AK7*3.30578512 -> #DIV/0! | AM7: 10032 | AN7: 459980 | AO7: =AN7/AM7 -> 45.851276 | AP7: =AO7*3.30578512 -> 151.57447 | AQ7: 0 | AR7: 0 | AS7: =AR7/AQ7 -> #DIV/0! | AT7: =AS7*3.30578512 -> #DIV/0! | AU7: 39086 | AV7: 2340000 | AW7: =AV7/AU7 -> 59.867983 | AX7: =AW7*3.30578512 -> 197.91069 | AY7: 181 | AZ7: 6000 | BA7: =AZ7/AY7 -> 33.149171 | BB7: =BA7*3.30578512 -> 109.58404 | BC7: 0 | BD7: 0 | BE7: =BD7/BC7 -> #DIV/0! | BF7: =BE7*3.30578512 -> #DIV/0! | BG7: 1096 | BH7: 70000 | BI7: =BH7/BG7 -> 63.868613 | BJ7: =BI7*3.30578512 -> 211.13591
B8: 倉庫 | C8: 560842 | D8: 5842073 | E8: =D8/C8 -> 10.416611 | F8: =E8*3.30578512 -> 34.435078 | G8: 58534 | H8: 780080 | I8: =H8/G8 -> 13.326955 | J8: =I8*3.30578512 -> 44.05605 | K8: 485 | L8: 5600 | M8: =L8/K8 -> 11.546392 | N8: =M8*3.30578512 -> 38.16989 | O8: 73357 | P8: 1094000 | Q8: =P8/O8 -> 14.913369 | R8: =Q8*3.30578512 -> 49.300393 | S8: 25992 | T8: 350320 | U8: =T8/S8 -> 13.477993 | V8: =U8*3.30578512 -> 44.555349 | W8: 438 | X8: 4533 | Y8: =X8/W8 -> 10.349315 | Z8: =Y8*3.30578512 -> 34.212612 | AA8: 76510 | AB8: 1550000 | AC8: =AB8/AA8 -> 20.25879 | AD8: =AC8*3.30578512 -> 66.971206 | AE8: 72696 | AF8: 1100500 | AG8: =AF8/AE8 -> 15.138385 | AH8: =AG8*3.30578512 -> 50.044246 | AI8: 0 | AJ8: 0 | AK8: =AJ8/AI8 -> #DIV/0! | AL8: =AK8*3.30578512 -> #DIV/0! | AM8: 20271 | AN8: 500800 | AO8: =AN8/AM8 -> 24.705244 | AP8: =AO8*3.30578512 -> 81.670228 | AQ8: 55 | AR8: 600 | AS8: =AR8/AQ8 -> 10.909091 | AT8: =AS8*3.30578512 -> 36.06311 | AU8: 41165 | AV8: 1500630 | AW8: =AV8/AU8 -> 36.454026 | AX8: =AW8*3.30578512 -> 120.50918 | AY8: 438 | AZ8: 18000 | BA8: =AZ8/AY8 -> 41.09589 | BB8: =BA8*3.30578512 -> 135.85418 | BC8: 188 | BD8: 16950 | BE8: =BD8/BC8 -> 90.159574 | BF8: =BE8*3.30578512 -> 298.04818 | BG8: 387 | BH8: 12085 | BI8: =BH8/BG8 -> 31.22739 | BJ8: =BI8*3.30578512 -> 103.23104
B9: 学校の校舎 | C9: 266605 | D9: 8404400 | E9: =D9/C9 -> 31.52379 | F9: =E9*3.30578512 -> 104.21088 | G9: 31335 | H9: 1411293 | I9: =H9/G9 -> 45.03887 | J9: =I9*3.30578512 -> 148.88883 | K9: 7137 | L9: 235000 | M9: =L9/K9 -> 32.927 | N9: =M9*3.30578512 -> 108.84959 | O9: 9146 | P9: 400000 | Q9: =P9/O9 -> 43.734966 | R9: =Q9*3.30578512 -> 144.5784 | S9: 13024 | T9: 403300 | U9: =T9/S9 -> 30.965909 | V9: =U9*3.30578512 -> 102.36664 | W9: 3518 | X9: 225292 | Y9: =X9/W9 -> 64.039795 | Z9: =Y9*3.30578512 -> 211.7018 | AA9: 3068 | AB9: 78000 | AC9: =AB9/AA9 -> 25.423729 | AD9: =AC9*3.30578512 -> 84.045384 | AE9: 8672 | AF9: 335000 | AG9: =AF9/AE9 -> 38.630074 | AH9: =AG9*3.30578512 -> 127.70272 | AI9: 15400 | AJ9: 859050 | AK9: =AJ9/AI9 -> 55.782468 | AL9: =AK9*3.30578512 -> 184.40485 | AM9: 15055 | AN9: 410000 | AO9: =AN9/AM9 -> 27.233477 | AP9: =AO9*3.30578512 -> 90.028024 | AQ9: 34043 | AR9: 1561518 | AS9: =AR9/AQ9 -> 45.868989 | AT9: =AS9*3.30578512 -> 151.63302 | AU9: 11391 | AV9: 786964 | AW9: =AV9/AU9 -> 69.086472 | AX9: =AW9*3.30578512 -> 228.38503 | AY9: 2491 | AZ9: 100000 | BA9: =AZ9/AY9 -> 40.14452 | BB9: =BA9*3.30578512 -> 132.70916 | BC9: 0 | BD9: 0 | BE9: =BD9/BC9 -> #DIV/0! | BF9: =BE9*3.30578512 -> #DIV/0! | BG9: 16153 | BH9: 560000 | BI9: =BH9/BG9 -> 34.668483 | BJ9: =BI9*3.30578512 -> 114.60655
B10: 病院・診療所 | C10: 314681 | D10: 7514820 | E10: =D10/C10 -> 23.880755 | F10: =E10*3.30578512 -> 78.944646 | G10: 7101 | H10: 250000 | I10: =H10/G10 -> 35.206309 | J10: =I10*3.30578512 -> 116.38449 | K10: 0 | L10: 0 | M10: =L10/K10 -> #DIV/0! | N10: =M10*3.30578512 -> #DIV/0! | O10: 0 | P10: 0 | Q10: =P10/O10 -> #DIV/0! | R10: =Q10*3.30578512 -> #DIV/0! | S10: 45264 | T10: 1927700 | U10: =T10/S10 -> 42.587929 | V10: =U10*3.30578512 -> 140.78654 | W10: 0 | X10: 0 | Y10: =X10/W10 -> #DIV/0! | Z10: =Y10*3.30578512 -> #DIV/0! | AA10: 1698 | AB10: 65000 | AC10: =AB10/AA10 -> 38.28033 | AD10: =AC10*3.30578512 -> 126.54654 | AE10: 233 | AF10: 100000 | AG10: =AF10/AE10 -> 429.18455 | AH10: =AG10*3.30578512 -> 1418.7919 | AI10: 0 | AJ10: 0 | AK10: =AJ10/AI10 -> #DIV/0! | AL10: =AK10*3.30578512 -> #DIV/0! | AM10: 0 | AN10: 0 | AO10: =AN10/AM10 -> #DIV/0! | AP10: =AO10*3.30578512 -> #DIV/0! | AQ10: 0 | AR10: 0 | AS10: =AR10/AQ10 -> #DIV/0! | AT10: =AS10*3.30578512 -> #DIV/0! | AU10: 0 | AV10: 0 | AW10: =AV10/AU10 -> #DIV/0! | AX10: =AW10*3.30578512 -> #DIV/0! | AY10: 0 | AZ10: 0 | BA10: =AZ10/AY10 -> #DIV/0! | BB10: =BA10*3.30578512 -> #DIV/0! | BC10: 0 | BD10: 0 | BE10: =BD10/BC10 -> #DIV/0! | BF10: =BE10*3.30578512 -> #DIV/0! | BG10: 117 | BH10: 10000 | BI10: =BH10/BG10 -> 85.470085 | BJ10: =BI10*3.30578512 -> 282.54574
B11: その他 | C11: 507097 | D11: 17314472 | E11: =D11/C11 -> 34.1443 | F11: =E11*3.30578512 -> 112.87372 | G11: 50041 | H11: 2062198 | I11: =H11/G11 -> 41.210168 | J11: =I11*3.30578512 -> 136.23196 | K11: 8699 | L11: 257572 | M11: =L11/K11 -> 29.60938 | N11: =M11*3.30578512 -> 97.882249 | O11: 11687 | P11: 363695 | Q11: =P11/O11 -> 31.11962 | R11: =Q11*3.30578512 -> 102.87478 | S11: 29941 | T11: 1871775 | U11: =T11/S11 -> 62.515447 | V11: =U11*3.30578512 -> 206.66263 | W11: 9188 | X11: 483125 | Y11: =X11/W11 -> 52.582172 | Z11: =Y11*3.30578512 -> 173.82536 | AA11: 34727 | AB11: 1085909 | AC11: =AB11/AA11 -> 31.269876 | AD11: =AC11*3.30578512 -> 103.37149 | AE11: 4314 | AF11: 175486 | AG11: =AF11/AE11 -> 40.678257 | AH11: =AG11*3.30578512 -> 134.47358 | AI11: 12774 | AJ11: 936374 | AK11: =AJ11/AI11 -> 73.303116 | AL11: =AK11*3.30578512 -> 242.32435 | AM11: 1320 | AN11: 58144 | AO11: =AN11/AM11 -> 44.048485 | AP11: =AO11*3.30578512 -> 145.61483 | AQ11: 968 | AR11: 13963 | AS11: =AR11/AQ11 -> 14.424587 | AT11: =AS11*3.30578512 -> 47.684584 | AU11: 72472 | AV11: 7480770 | AW11: =AV11/AU11 -> 103.2229 | AX11: =AW11*3.30578512 -> 341.23273 | AY11: 125722 | AZ11: 12810713 | BA11: =AZ11/AY11 -> 101.89715 | BB11: =BA11*3.30578512 -> 336.85007 | BC11: 66242 | BD11: 4926066 | BE11: =BD11/BC11 -> 74.364693 | BF11: =BE11*3.30578512 -> 245.83369 | BG11: 11749 | BH11: 267872 | BI11: =BH11/BG11 -> 22.799557 | BJ11: =BI11*3.30578512 -> 75.370438

Sheet 鉄筋コンクリート造
A1: 鉄筋コンクリート造
C3: 2015（基準） | G3: 令和4年2月分 | K3: 令和4年5月分 | O3: 令和4年8月分 | S3: 令和4年11月分 | W3: 令和5年2月分 | AA3: 令和5年5月分 | AE3: 令和5年8月分 | AI3: 令和5年11月分 | AM3: 令和6年2月分 | AQ3: 令和6年5月分 | AU3: 令和6年8月分 | AY3: 令和6年11月分 | BC3: 令和7年2月分 | BG3: 令和7年5月分
C4: 床面積の合計 （㎡） | D4: 工事費予定額（万円） | E4: 面積単価 （万円/㎡） | F4: 面積単価 （万円/坪） | G4: 床面積の合計 （㎡） | H4: 工事費予定額（万円） | I4: 面積単価 （万円/㎡） | J4: 面積単価 （万円/坪） | K4: 床面積の合計 （㎡） | L4: 工事費予定額（万円） | M4: 面積単価 （万円/㎡） | N4: 面積単価 （万円/坪） | O4: 床面積の合計 （㎡） | P4: 工事費予定額（万円） | Q4: 面積単価 （万円/㎡） | R4: 面積単価 （万円/坪） | S4: 床面積の合計 （㎡） | T4: 工事費予定額（万円） | U4: 面積単価 （万円/㎡） | V4: 面積単価 （万円/坪） | W4: 床面積の合計 （㎡） | X4: 工事費予定額（万円） | Y4: 面積単価 （万円/㎡） | Z4: 面積単価 （万円/坪） | AA4: 床面積の合計 （㎡） | AB4: 工事費予定額（万円） | AC4: 面積単価 （万円/㎡） | AD4: 面積単価 （万円/坪） | AE4: 床面積の合計 （㎡） | AF4: 工事費予定額（万円） | AG4: 面積単価 （万円/㎡） | AH4: 面積単価 （万円/坪） | AI4: 床面積の合計 （㎡） | AJ4: 工事費予定額（万円） | AK4: 面積単価 （万円/㎡） | AL4: 面積単価 （万円/坪） | AM4: 床面積の合計 （㎡） | AN4: 工事費予定額（万円） | AO4: 面積単価 （万円/㎡） | AP4: 面積単価 （万円/坪） | AQ4: 床面積の合計 （㎡） | AR4: 工事費予定額（万円） | AS4: 面積単価 （万円/㎡） | AT4: 面積単価 （万円/坪） | AU4: 床面積の合計 （㎡） | AV4: 工事費予定額（万円） | AW4: 面積単価 （万円/㎡） | AX4: 面積単価 （万円/坪） | AY4: 床面積の合計 （㎡） | AZ4: 工事費予定額（万円） | BA4: 面積単価 （万円/㎡） | BB4: 面積単価 （万円/坪） | BC4: 床面積の合計 （㎡） | BD4: 工事費予定額（万円） | BE4: 面積単価 （万円/㎡） | BF4: 面積単価 （万円/坪） | BG4: 床面積の合計 （㎡） | BH4: 工事費予定額（万円） | BI4: 面積単価 （万円/㎡） | BJ4: 面積単価 （万円/坪）
B5: 事務所 | C5: 673470 | D5: 21399499 | E5: =D5/C5 -> 31.774985 | F5: =E5*3.30578512 -> 105.04127 | G5: 32466 | H5: 1049125 | I5: =H5/G5 -> 32.314575 | J5: =I5*3.30578512 -> 106.82504 | K5: 79603 | L5: 3510950 | M5: =L5/K5 -> 44.10575 | N5: =M5*3.30578512 -> 145.80413 | O5: 57126 | P5: 2171051 | Q5: =P5/O5 -> 38.004604 | R5: =Q5*3.30578512 -> 125.63505 | S5: 45541 | T5: 1919944 | U5: =T5/S5 -> 42.158582 | V5: =U5*3.30578512 -> 139.36721 | W5: 55883 | X5: 2392358 | Y5: =X5/W5 -> 42.810121 | Z5: =Y5*3.30578512 -> 141.52106 | AA5: 53575 | AB5: 2353715 | AC5: =AB5/AA5 -> 43.933084 | AD5: =AC5*3.30578512 -> 145.23334 | AE5: 40073 | AF5: 2134117 | AG5: =AF5/AE5 -> 53.255733 | AH5: =AG5*3.30578512 -> 176.05201 | AI5: 39643 | AJ5: 2271769 | AK5: =AJ5/AI5 -> 57.305678 | AL5: =AK5*3.30578512 -> 189.44026 | AM5: 20929 | AN5: 1282400 | AO5: =AN5/AM5 -> 61.273831 | AP5: =AO5*3.30578512 -> 202.55812 | AQ5: 35108 | AR5: 1791375 | AS5: =AR5/AQ5 -> 51.024695 | AT5: =AS5*3.30578512 -> 168.67668 | AU5: 21870 | AV5: 1267345 | AW5: =AV5/AU5 -> 57.949017 | AX5: =AW5*3.30578512 -> 191.567 | AY5: 76901 | AZ5: 5281615 | BA5: =AZ5/AY5 -> 68.680706 | BB5: =BA5*3.30578512 -> 227.04366 | BC5: 76113 | BD5: 4479190.8 | BE5: =BD5/BC5 -> 58.849221 | BF5: =BE5*3.30578512 -> 194.54288 | BG5: 47106 | BH5: 1677680.4 | BI5: =BH5/BG5 -> 35.615004 | BJ5: =BI5*3.30578512 -> 117.73555
B6: 店舗 | C6: 72357 | D6: 1758084 | E6: =D6/C6 -> 24.297359 | F6: =E6*3.30578512 -> 80.321848 | G6: 27939 | H6: 779947 | I6: =H6/G6 -> 27.916067 | J6: =I6*3.30578512 -> 92.284519 | K6: 23904 | L6: 951091 | M6: =L6/K6 -> 39.787943 | N6: =M6*3.30578512 -> 131.53039 | O6: 10431 | P6: 262239 | Q6: =P6/O6 -> 25.140351 | R6: =Q6*3.30578512 -> 83.108598 | S6: 1536 | T6: 47894 | U6: =T6/S6 -> 31.18099 | V6: =U6*3.30578512 -> 103.07765 | W6: 6306 | X6: 215418 | Y6: =X6/W6 -> 34.160799 | Z6: =Y6*3.30578512 -> 112.92826 | AA6: 5822 | AB6: 179220 | AC6: =AB6/AA6 -> 30.783236 | AD6: =AC6*3.30578512 -> 101.76276 | AE6: 8806 | AF6: 377134 | AG6: =AF6/AE6 -> 42.826936 | AH6: =AG6*3.30578512 -> 141.57665 | AI6: 1430 | AJ6: 71400 | AK6: =AJ6/AI6 -> 49.93007 | AL6: =AK6*3.30578512 -> 165.05808 | AM6: 5235 | AN6: 321235 | AO6: =AN6/AM6 -> 61.362942 | AP6: =AO6*3.30578512 -> 202.8527 | AQ6: 32529 | AR6: 864522 | AS6: =AR6/AQ6 -> 26.576962 | AT6: =AS6*3.30578512 -> 87.857726 | AU6: 1537 | AV6: 157000 | AW6: =AV6/AU6 -> 102.14704 | AX6: =AW6*3.30578512 -> 337.67616 | AY6: 4645 | AZ6: 250910 | BA6: =AZ6/AY6 -> 54.017223 | BB6: =BA6*3.30578512 -> 178.56933 | BC6: 7686 | BD6: 363662.18 | BE6: =BD6/BC6 -> 47.314881 | BF6: =BE6*3.30578512 -> 156.41283 | BG6: 12462 | BH6: 685329.05 | BI6: =BH6/BG6 -> 54.993504 | BJ6: =BI6*3.30578512 -> 181.79671
B7: 工場及び作業場 | C7: 229990 | D7: 5185075 | E7: =D7/C7 -> 22.544785 | F7: =E7*3.30578512 -> 74.528213 | G7: 10490 | H7: 93064 | I7: =H7/G7 -> 8.8716873 | J7: =I7*3.30578512 -> 29.327892 | K7: 24994 | L7: 485825 | M7: =L7/K7 -> 19.437665 | N7: =M7*3.30578512 -> 64.256744 | O7: 22450 | P7: 1435629 | Q7: =P7/O7 -> 63.94784 | R7: =Q7*3.30578512 -> 211.39782 | S7: 8420 | T7: 176370 | U7: =T7/S7 -> 20.946556 | V7: =U7*3.30578512 -> 69.244813 | W7: 107226 | X7: 2452202 | Y7: =X7/W7 -> 22.869472 | Z7: =Y7*3.30578512 -> 75.60156 | AA7: 14417 | AB7: 952900 | AC7: =AB7/AA7 -> 66.095582 | AD7: =AC7*3.30578512 -> 218.49779 | AE7: 1056 | AF7: 63500 | AG7: =AF7/AE7 -> 60.132576 | AH7: =AG7*3.30578512 -> 198.78537 | AI7: 380 | AJ7: 57440 | AK7: =AJ7/AI7 -> 151.15789 | AL7: =AK7*3.30578512 -> 499.69552 | AM7: 4600 | AN7: 115328 | AO7: =AN7/AM7 -> 25.071304 | AP7: =AO7*3.30578512 -> 82.880345 | AQ7: 6481 | AR7: 245050 | AS7: =AR7/AQ7 -> 37.810523 | AT7: =AS7*3.30578512 -> 124.99346 | AU7: 75089 | AV7: 2969080 | AW7: =AV7/AU7 -> 39.540812 | AX7: =AW7*3.30578512 -> 130.71343 | AY7: 7039 | AZ7: 190150 | BA7: =AZ7/AY7 -> 27.01378 | BB7: =BA7*3.30578512 -> 89.301753 | BC7: 11647 | BD7: 985376 | BE7: =BD7/BC7 -> 84.603417 | BF7: =BE7*3.30578512 -> 279.68072 | BG7: 6591 | BH7: 594050 | BI7: =BH7/BG7 -> 90.130481 | BJ7: =BI7*3.30578512 -> 297.952
B8: 倉庫 | C8: 1031373 | D8: 13384389 | E8: =D8/C8 -> 12.977254 | F8: =E8*3.30578512 -> 42.900012 | G8: 382289 | H8: 4603680 | I8: =H8/G8 -> 12.042408 | J8: =I8*3.30578512 -> 39.809612 | K8: 273698 | L8: 2918396 | M8: =L8/K8 -> 10.662833 | N8: =M8*3.30578512 -> 35.249034 | O8: 458673 | P8: 6841976 | Q8: =P8/O8 -> 14.916893 | R8: =Q8*3.30578512 -> 49.312042 | S8: 1171 | T8: 41750 | U8: =T8/S8 -> 35.653288 | V8: =U8*3.30578512 -> 117.86211 | W8: 226910 | X8: 3484438 | Y8: =X8/W8 -> 15.356035 | Z8: =Y8*3.30578512 -> 50.763753 | AA8: 208410 | AB8: 2703090 | AC8: =AB8/AA8 -> 12.970059 | AD8: =AC8*3.30578512 -> 42.876228 | AE8: 565298 | AF8: 9002018 | AG8: =AF8/AE8 -> 15.924376 | AH8: =AG8*3.30578512 -> 52.642566 | AI8: 428385 | AJ8: 7280600 | AK8: =AJ8/AI8 -> 16.99546 | AL8: =AK8*3.30578512 -> 56.183338 | AM8: 266570 | AN8: 6278887 | AO8: =AN8/AM8 -> 23.554365 | AP8: =AO8*3.30578512 -> 77.865668 | AQ8: 72900 | AR8: 1278061 | AS8: =AR8/AQ8 -> 17.531701 | AT8: =AS8*3.30578512 -> 57.956036 | AU8: 67268 | AV8: 1471680 | AW8: =AV8/AU8 -> 21.877862 | AX8: =AW8*3.30578512 -> 72.32351 | AY8: 98948 | AZ8: 2231733 | BA8: =AZ8/AY8 -> 22.554604 | BB8: =BA8*3.30578512 -> 74.560676 | BC8: 526019 | BD8: 10420454 | BE8: =BD8/BC8 -> 19.810034 | BF8: =BE8*3.30578512 -> 65.487716 | BG8: 701489 | BH8: 17963969 | BI8: =BH8/BG8 -> 25.608341 | BJ8: =BI8*3.30578512 -> 84.655672
B9: 学校の校舎 | C9: 1835193 | D9: 50330867 | E9: =D9/C9 -> 27.425381 | F9: =E9*3.30578512 -> 90.662416 | G9: 51890 | H9: 1774216 | I9: =H9/G9 -> 34.191867 | J9: =I9*3.30578512 -> 113.03097 | K9: 116271 | L9: 3203689 | M9: =L9/K9 -> 27.553638 | N9: =M9*3.30578512 -> 91.086405 | O9: 173181 | P9: 6427432 | Q9: =P9/O9 -> 37.113956 | R9: =Q9*3.30578512 -> 122.69076 | S9: 88166 | T9: 2508835 | U9: =T9/S9 -> 28.455811 | V9: =U9*3.30578512 -> 94.068795 | W9: 62683 | X9: 2232198 | Y9: =X9/W9 -> 35.610899 | Z9: =Y9*3.30578512 -> 117.72198 | AA9: 85769 | AB9: 3909924 | AC9: =AB9/AA9 -> 45.586681 | AD9: =AC9*3.30578512 -> 150.69977 | AE9: 90258 | AF9: 3745219 | AG9: =AF9/AE9 -> 41.494593 | AH9: =AG9*3.30578512 -> 137.17221 | AI9: 34086 | AJ9: 1288005 | AK9: =AJ9/AI9 -> 37.786921 | AL9: =AK9*3.30578512 -> 124.91544 | AM9: 32190 | AN9: 1072003 | AO9: =AN9/AM9 -> 33.302361 | AP9: =AO9*3.30578512 -> 110.09045 | AQ9: 40077 | AR9: 1483873 | AS9: =AR9/AQ9 -> 37.025551 | AT9: =AS9*3.30578512 -> 122.39851 | AU9: 78959 | AV9: 3358800 | AW9: =AV9/AU9 -> 42.538533 | AX9: =AW9*3.30578512 -> 140.62325 | AY9: 61695 | AZ9: 3184395 | BA9: =AZ9/AY9 -> 51.615123 | BB9: =BA9*3.30578512 -> 170.6285 | BC9: 46855 | BD9: 2164665.5 | BE9: =BD9/BC9 -> 46.199242 | BF9: =BE9*3.30578512 -> 152.72477 | BG9: 36837 | BH9: 1676479.1 | BI9: =BH9/BG9 -> 45.510738 | BJ9: =BI9*3.30578512 -> 150.44872
B10: 病院・診療所 | C10: 1024242 | D10: 29249650 | E10: =D10/C10 -> 28.557362 | F10: =E10*3.30578512 -> 94.404504 | G10: 37579 | H10: 1256192 | I10: =H10/G10 -> 33.428032 | J10: =I10*3.30578512 -> 110.50589 | K10: 35646 | L10: 942009 | M10: =L10/K10 -> 26.42678 | N10: =M10*3.30578512 -> 87.361256 | O10: 30421 | P10: 1316334 | Q10: =P10/O10 -> 43.27057 | R10: =Q10*3.30578512 -> 143.04321 | S10: 51002 | T10: 1899726 | U10: =T10/S10 -> 37.248069 | V10: =U10*3.30578512 -> 123.13411 | W10: 53670 | X10: 2730012 | Y10: =X10/W10 -> 50.866629 | Z10: =Y10*3.30578512 -> 168.15415 | AA10: 131908 | AB10: 5493250 | AC10: =AB10/AA10 -> 41.644555 | AD10: =AC10*3.30578512 -> 137.66795 | AE10: 15684 | AF10: 747019 | AG10: =AF10/AE10 -> 47.629368 | AH10: =AG10*3.30578512 -> 157.45245 | AI10: 31814 | AJ10: 1390287 | AK10: =AJ10/AI10 -> 43.700478 | AL10: =AK10*3.30578512 -> 144.46439 | AM10: 4911 | AN10: 252510 | AO10: =AN10/AM10 -> 51.417227 | AP10: =AO10*3.30578512 -> 169.9743 | AQ10: 33521 | AR10: 1394000 | AS10: =AR10/AQ10 -> 41.585872 | AT10: =AS10*3.30578512 -> 137.47396 | AU10: 42760 | AV10: 2069660 | AW10: =AV10/AU10 -> 48.401777 | AX10: =AW10*3.30578512 -> 160.00588 | AY10: 56004 | AZ10: 1992480 | BA10: =AZ10/AY10 -> 35.577459 | BB10: =BA10*3.30578512 -> 117.61143 | BC10: 16968 | BD10: 834225.11 | BE10: =BD10/BC10 -> 49.164611 | BF10: =BE10*3.30578512 -> 162.52764 | BG10: 16780 | BH10: 973237.34 | BI10: =BH10/BG10 -> 57.999842 | BJ10: =BI10*3.30578512 -> 191.73501
B11: その他 | C11: 2863587 | D11: 79499077 | E11: =D11/C11 -> 27.762061 | F11: =E11*3.30578512 -> 91.775408 | G11: 145387 | H11: 8433486 | I11: =H11/G11 -> 58.007153 | J11: =I11*3.30578512 -> 191.75918 | K11: 139166 | L11: 4777887 | M11: =L11/K11 -> 34.332287 | N11: =M11*3.30578512 -> 113.49516 | O11: 108312 | P11: 4182521 | Q11: =P11/O11 -> 38.61549 | R11: =Q11*3.30578512 -> 127.65451 | S11: 196902 | T11: 9093172 | U11: =T11/S11 -> 46.181207 | V11: =U11*3.30578512 -> 152.66515 | W11: 124745 | X11: 5453712 | Y11: =X11/W11 -> 43.718883 | Z11: =Y11*3.30578512 -> 144.52523 | AA11: 162589 | AB11: 6832117 | AC11: =AB11/AA11 -> 42.020782 | AD11: =AC11*3.30578512 -> 138.91168 | AE11: 164354 | AF11: 8016236 | AG11: =AF11/AE11 -> 48.774207 | AH11: =AG11*3.30578512 -> 161.23705 | AI11: 155119 | AJ11: 6724494 | AK11: =AJ11/AI11 -> 43.35055 | AL11: =AK11*3.30578512 -> 143.3076 | AM11: 157352 | AN11: 8032040 | AO11: =AN11/AM11 -> 51.045046 | AP11: =AO11*3.30578512 -> 168.74395 | AQ11: 148141 | AR11: 7330161 | AS11: =AR11/AQ11 -> 49.480974 | AT11: =AS11*3.30578512 -> 163.57347 | AU11: 224207 | AV11: 13715335 | AW11: =AV11/AU11 -> 61.172644 | AX11: =AW11*3.30578512 -> 202.22362 | AY11: 129124 | AZ11: 6513811 | BA11: =AZ11/AY11 -> 50.446168 | BB11: =BA11*3.30578512 -> 166.76419 | BC11: 123812 | BD11: 6408679 | BE11: =BD11/BC11 -> 51.761372 | BF11: =BE11*3.30578512 -> 171.11197 | BG11: 149719 | BH11: 6668545.9 | BI11: =BH11/BG11 -> 44.540411 | BJ11: =BI11*3.30578512 -> 147.24103

Sheet 鉄骨造
A1: 鉄骨造
C3: 2015（基準） | G3: 令和4年1月分 | K3: 令和4年2月分 | O3: 令和4年3月分 | S3: 令和4年4月分 | W3: 令和4年5月分 | AA3: 令和4年6月分 | AE3: 令和4年7月分 | AI3: 令和4年8月分 | AM3: 令和4年9月分 | AQ3: 令和4年10月分 | AU3: 令和4年11月分 | AY3: 令和4年12月分 | BC3: 令和5年1月分 | BG3: 令和5年2月分 | BK3: 令和5年3月分 | BO3: 令和5年4月分 | BS3: 令和5年5月分 | BW3: 令和5年6月分 | CA3: 令和5年7月分 | CE3: 令和5年8月分 | CI3: 令和5年9月分 | CM3: 令和5年10月分 | CQ3: 令和5年11月分 | CU3: 令和5年12月分 | CY3: 令和6年1月分 | DC3: 令和6年2月分 | DG3: 令和6年3月分 | DK3: 令和6年4月分 | DO3: 令和6年5月分 | DS3: 令和6年6月分 | DW3: 令和6年7月分 | EA3: 令和6年8月分 | EE3: 令和6年9月分 | EI3: 令和6年10月分 | EM3: 令和6年11月分 | EQ3: 令和6年12月分 | EU3: 令和7年1月分 | EY3: 令和7年2月分 | FC3: 令和7年3月分 | FG3: 令和7年4月分 | FK3: 令和7年5月分 | FO3: 令和7年6月分 | FS3: 令和7年7月分 | FW3: 令和7年8月分
C4: 床面積の合計 （㎡） | D4: 工事費予定額（万円） | E4: 面積単価 （万円/㎡） | F4: 面積単価 （万円/坪） | G4: 床面積の合計 （㎡） | H4: 工事費予定額（万円） | I4: 面積単価 （万円/㎡） | J4: 面積単価 （万円/坪） | K4: 床面積の合計 （㎡） | L4: 工事費予定額（万円） | M4: 面積単価 （万円/㎡） | N4: 面積単価 （万円/坪） | O4: 床面積の合計 （㎡） | P4: 工事費予定額（万円） | Q4: 面積単価 （万円/㎡） | R4: 面積単価 （万円/坪） | S4: 床面積の合計 （㎡） | T4: 工事費予定額（万円） | U4: 面積単価 （万円/㎡） | V4: 面積単価 （万円/坪） | W4: 床面積の合計 （㎡） | X4: 工事費予定額（万円） | Y4: 面積単価 （万円/㎡） | Z4: 面積単価 （万円/坪） | AA4: 床面積の合計 （㎡） | AB4: 工事費予定額（万円） | AC4: 面積単価 （万円/㎡） | AD4: 面積単価 （万円/坪） | AE4: 床面積の合計 （㎡） | AF4: 工事費予定額（万円） | AG4: 面積単価 （万円/㎡） | AH4: 面積単価 （万円/坪） | AI4: 床面積の合計 （㎡） | AJ4: 工事費予定額（万円） | AK4: 面積単価 （万円/㎡） | AL4: 面積単価 （万円/坪） | AM4: 床面積の合計 （㎡） | AN4: 工事費予定額（万円） | AO4: 面積単価 （万円/㎡） | AP4: 面積単価 （万円/坪） | AQ4: 床面積の合計 （㎡） | AR4: 工事費予定額（万円） | AS4: 面積単価 （万円/㎡） | AT4: 面積単価 （万円/坪） | AU4: 床面積の合計 （㎡） | AV4: 工事費予定額（万円） | AW4: 面積単価 （万円/㎡） | AX4: 面積単価 （万円/坪） | AY4: 床面積の合計 （㎡） | AZ4: 工事費予定額（万円） | BA4: 面積単価 （万円/㎡） | BB4: 面積単価 （万円/坪） | BC4: 床面積の合計 （㎡） | BD4: 工事費予定額（万円） | BE4: 面積単価 （万円/㎡） | BF4: 面積単価 （万円/坪） | BG4: 床面積の合計 （㎡） | BH4: 工事費予定額（万円） | BI4: 面積単価 （万円/㎡） | BJ4: 面積単価 （万円/坪） | BK4: 床面積の合計 （㎡） | BL4: 工事費予定額（万円） | BM4: 面積単価 （万円/㎡） | BN4: 面積単価 （万円/坪） | BO4: 床面積の合計 （㎡） | BP4: 工事費予定額（万円） | BQ4: 面積単価 （万円/㎡） | BR4: 面積単価 （万円/坪） | BS4: 床面積の合計 （㎡） | BT4: 工事費予定額（万円） | BU4: 面積単価 （万円/㎡） | BV4: 面積単価 （万円/坪） | BW4: 床面積の合計 （㎡） | BX4: 工事費予定額（万円） | BY4: 面積単価 （万円/㎡） | BZ4: 面積単価 （万円/坪） | CA4: 床面積の合計 （㎡） | CB4: 工事費予定額（万円） | CC4: 面積単価 （万円/㎡） | CD4: 面積単価 （万円/坪） | CE4: 床面積の合計 （㎡） | CF4: 工事費予定額（万円） | CG4: 面積単価 （万円/㎡） | CH4: 面積単価 （万円/坪） | CI4: 床面積の合計 （㎡） | CJ4: 工事費予定額（万円） | CK4: 面積単価 （万円/㎡） | CL4: 面積単価 （万円/坪） | CM4: 床面積の合計 （㎡） | CN4: 工事費予定額（万円） | CO4: 面積単価 （万円/㎡） | CP4: 面積単価 （万円/坪） | CQ4: 床面積の合計 （㎡） | CR4: 工事費予定額（万円） | CS4: 面積単価 （万円/㎡） | CT4: 面積単価 （万円/坪） | CU4: 床面積の合計 （㎡） | CV4: 工事費予定額（万円） | CW4: 面積単価 （万円/㎡） | CX4: 面積単価 （万円/坪） | CY4: 床面積の合計 （㎡） | CZ4: 工事費予定額（万円） | DA4: 面積単価 （万円/㎡） | DB4: 面積単価 （万円/坪） | DC4: 床面積の合計 （㎡） | DD4: 工事費予定額（万円） | DE4: 面積単価 （万円/㎡） | DF4: 面積単価 （万円/坪） | DG4: 床面積の合計 （㎡） | DH4: 工事費予定額（万円） | DI4: 面積単価 （万円/㎡） | DJ4: 面積単価 （万円/坪） | DK4: 床面積の合計 （㎡） | DL4: 工事費予定額（万円） | DM4: 面積単価 （万円/㎡） | DN4: 面積単価 （万円/坪） | DO4: 床面積の合計 （㎡） | DP4: 工事費予定額（万円） | DQ4: 面積単価 （万円/㎡） | DR4: 面積単価 （万円/坪） | DS4: 床面積の合計 （㎡） | DT4: 工事費予定額（万円） | DU4: 面積単価 （万円/㎡） | DV4: 面積単価 （万円/坪） | DW4: 床面積の合計 （㎡） | DX4: 工事費予定額（万円） | DY4: 面積単価 （万円/㎡） | DZ4: 面積単価 （万円/坪） | EA4: 床面積の合計 （㎡） | EB4: 工事費予定額（万円） | EC4: 面積単価 （万円/㎡） | ED4: 面積単価 （万円/坪） | EE4: 床面積の合計 （㎡） | EF4: 工事費予定額（万円） | EG4: 面積単価 （万円/㎡） | EH4: 面積単価 （万円/坪） | EI4: 床面積の合計 （㎡） | EJ4: 工事費予定額（万円） | EK4: 面積単価 （万円/㎡） | EL4: 面積単価 （万円/坪） | EM4: 床面積の合計 （㎡） | EN4: 工事費予定額（万円） | EO4: 面積単価 （万円/㎡） | EP4: 面積単価 （万円/坪） | EQ4: 床面積の合計 （㎡） | ER4: 工事費予定額（万円） | ES4: 面積単価 （万円/㎡） | ET4: 面積単価 （万円/坪） | EU4: 床面積の合計 （㎡） | EV4: 工事費予定額（万円） | EW4: 面積単価 （万円/㎡） | EX4: 面積単価 （万円/坪） | EY4: 床面積の合計 （㎡） | EZ4: 工事費予定額（万円） | FA4: 面積単価 （万円/㎡） | FB4: 面積単価 （万円/坪） | FC4: 床面積の合計 （㎡） | FD4: 工事費予定額（万円） | FE4: 面積単価 （万円/㎡） | FF4: 面積単価 （万円/坪） | FG4: 床面積の合計 （㎡） | FH4: 工事費予定額（万円） | FI4: 面積単価 （万円/㎡） | FJ4: 面積単価 （万円/坪） | FK4: 床面積の合計 （㎡） | FL4: 工事費予定額（万円） | FM4: 面積単価 （万円/㎡） | FN4: 面積単価 （万円/坪） | FO4: 床面積の合計 （㎡） | FP4: 工事費予定額（万円） | FQ4: 面積単価 （万円/㎡） | FR4: 面積単価 （万円/坪） | FS4: 床面積の合計 （㎡） | FT4: 工事費予定額（万円） | FU4: 面積単価 （万円/㎡） | FV4: 面積単価 （万円/坪） | FW4: 床面積の合計 （㎡） | FX4: 工事費予定額（万円） | FY4: 面積単価 （万円/㎡） | FZ4: 面積単価 （万円/坪）
B5: 事務所 | C5: 4986837 | D5: 138290050 | E5: =D5/C5 -> 27.731015 | F5: =E5*3.30578512 -> 91.672776 | G5: 304427 | H5: 9964888 | I5: =H5/G5 -> 32.73326 | J5: =I5*3.30578512 -> 108.20912 | K5: 234568 | L5: 7178890 | M5: =L5/K5 -> 30.604729 | N5: =M5*3.30578512 -> 101.17266 | O5: 326568 | P5: 8655630 | Q5: =P5/O5 -> 26.504832 | R5: =Q5*3.30578512 -> 87.619279 | S5: 372268 | T5: 11180130 | U5: =T5/S5 -> 30.032477 | V5: =U5*3.30578512 -> 99.280914 | W5: 251106 | X5: 9823521 | Y5: =X5/W5 -> 39.121013 | Z5: =Y5*3.30578512 -> 129.32566 | AA5: 384784 | AB5: 13228464 | AC5: =AB5/AA5 -> 34.378935 | AD5: =AC5*3.30578512 -> 113.64937 | AE5: 438227 | AF5: 19316127 | AG5: =AF5/AE5 -> 44.077903 | AH5: =AG5*3.30578512 -> 145.71207 | AI5: 288928 | AJ5: 8129108 | AK5: =AJ5/AI5 -> 28.135411 | AL5: =AK5*3.30578512 -> 93.009623 | AM5: 416123 | AN5: 18487312 | AO5: =AN5/AM5 -> 44.427518 | AP5: =AO5*3.30578512 -> 146.86783 | AQ5: 335080 | AR5: 11983171 | AS5: =AR5/AQ5 -> 35.762119 | AT5: =AS5*3.30578512 -> 118.22188 | AU5: 396639 | AV5: 14275145 | AW5: =AV5/AU5 -> 35.990271 | AX5: =AW5*3.30578512 -> 118.9761 | AY5: 243333 | AZ5: 11055431 | BA5: =AZ5/AY5 -> 45.43334 | BB5: =BA5*3.30578512 -> 150.19286 | BC5: 265880 | BD5: 9030358 | BE5: =BD5/BC5 -> 33.964036 | BF5: =BE5*3.30578512 -> 112.27781 | BG5: 252616 | BH5: 8814267 | BI5: =BH5/BG5 -> 34.891959 | BJ5: =BI5*3.30578512 -> 115.34532 | BK5: 262835 | BL5: 9011710 | BM5: =BL5/BK5 -> 34.286568 | BN5: =BM5*3.30578512 -> 113.34403 | BO5: 375752 | BP5: 13476755 | BQ5: =BP5/BO5 -> 35.86609 | BR5: =BQ5*3.30578512 -> 118.56559 | BS5: 265069 | BT5: 9528771 | BU5: =BT5/BS5 -> 35.948266 | BV5: =BU5*3.30578512 -> 118.83724 | BW5: 283220 | BX5: 10474266 | BY5: =BX5/BW5 -> 36.982791 | BZ5: =BY5*3.30578512 -> 122.25716 | CA5: 371653 | CB5: 17028276 | CC5: =CB5/CA5 -> 45.817674 | CD5: =CC5*3.30578512 -> 151.46338 | CE5: 177442 | CF5: 6836406 | CG5: =CF5/CE5 -> 38.527553 | CH5: =CG5*3.30578512 -> 127.36381 | CI5: 264665 | CJ5: 10186205 | CK5: =CJ5/CI5 -> 38.487163 | CL5: =CK5*3.30578512 -> 127.23029 | CM5: 301774 | CN5: 11024756 | CO5: =CN5/CM5 -> 36.533154 | CP5: =CO5*3.30578512 -> 120.77076 | CQ5: 293557 | CR5: 10566113 | CS5: =CR5/CQ5 -> 35.993395 | CT5: =CS5*3.30578512 -> 118.98643 | CU5: 772017 | CV5: 49470449 | CW5: =CV5/CU5 -> 64.079481 | CX5: =CW5*3.30578512 -> 211.833 | CY5: 696891 | CZ5: 28702203 | DA5: =CZ5/CY5 -> 41.186072 | DB5: =DA5*3.30578512 -> 136.1523 | DC5: 294618 | DD5: 12178890 | DE5: =DD5/DC5 -> 41.337902 | DF5: =DE5*3.30578512 -> 136.65422 | DG5: 609659 | DH5: 25614822 | DI5: =DH5/DG5 -> 42.014999 | DJ5: =DI5*3.30578512 -> 138.89256 | DK5: 346102 | DL5: 15827781 | DM5: =DL5/DK5 -> 45.73155 | DN5: =DM5*3.30578512 -> 151.17868 | DO5: 350082 | DP5: 8443971 | DQ5: =DP5/DO5 -> 24.11998 | DR5: =DQ5*3.30578512 -> 79.735473 | DS5: 265989 | DT5: 12465579 | DU5: =DT5/DS5 -> 46.865017 | DV5: =DU5*3.30578512 -> 154.92568 | DW5: 628940 | DX5: 25489877 | DY5: =DX5/DW5 -> 40.528313 | DZ5: =DY5*3.30578512 -> 133.97789 | EA5: 166485 | EB5: 7412704 | EC5: =EB5/EA5 -> 44.524756 | ED5: =EC5*3.30578512 -> 147.18928 | EE5: 274097 | EF5: 11321662 | EG5: =EF5/EE5 -> 41.305312 | EH5: =EG5*3.30578512 -> 136.54648 | EI5: 254290 | EJ5: 10139886 | EK5: =EJ5/EI5 -> 39.875284 | EL5: =EK5*3.30578512 -> 131.81912 | EM5: 170842 | EN5: 6032659 | EO5: =EN5/EM5 -> 35.311334 | EP5: =EO5*3.30578512 -> 116.73168 | EQ5: 206504 | ER5: 8393466 | ES5: =ER5/EQ5 -> 40.645537 | ET5: =ES5*3.30578512 -> 134.36541 | EU5: 266043 | EV5: 12105799 | EW5: =EV5/EU5 -> 45.503167 | EX5: =EW5*3.30578512 -> 150.42369 | EY5: 186444 | EZ5: 6580223.6 | FA5: =EZ5/EY5 -> 35.293298 | FB5: =FA5*3.30578512 -> 116.67206 | FC5: 539369 | FD5: 38448948 | FE5: =FD5/FC5 -> 71.285054 | FF5: =FE5*3.30578512 -> 235.65307 | FG5: 331956 | FH5: 16259901 | FI5: =FH5/FG5 -> 48.982097 | FJ5: =FI5*3.30578512 -> 161.92429 | FK5: 266452 | FL5: 13057560 | FM5: =FL5/FK5 -> 49.0053 | FN5: =FM5*3.30578512 -> 162.00099 | FQ5: =FP5/FO5 -> #DIV/0! | FR5: =FQ5*3.30578512 -> #DIV/0! | FU5: =FT5/FS5 -> #DIV/0! | FV5: =FU5*3.30578512 -> #DIV/0! | FY5: =FX5/FW5 -> #DIV/0! | FZ5: =FY5*3.30578512 -> #DIV/0!
B6: 店舗 | C6: 5648530 | D6: 91415609 | E6: =D6/C6 -> 16.183965 | F6: =E6*3.30578512 -> 53.500709 | G6: 235062 | H6: 4409546 | I6: =H6/G6 -> 18.759076 | J6: =I6*3.30578512 -> 62.013475 | K6: 340618 | L6: 5562274 | M6: =L6/K6 -> 16.329947 | N6: =M6*3.30578512 -> 53.983297 | O6: 285237 | P6: 4767054 | Q6: =P6/O6 -> 16.712607 | R6: =Q6*3.30578512 -> 55.248289 | S6: 376830 | T6: 6137473 | U6: =T6/S6 -> 16.287114 | V6: =U6*3.30578512 -> 53.841698 | W6: 293027 | X6: 4772590 | Y6: =X6/W6 -> 16.287202 | Z6: =Y6*3.30578512 -> 53.841991 | AA6: 364727 | AB6: 6242425 | AC6: =AB6/AA6 -> 17.115336 | AD6: =AC6*3.30578512 -> 56.579622 | AE6: 409659 | AF6: 6185950 | AG6: =AF6/AE6 -> 15.100242 | AH6: =AG6*3.30578512 -> 49.918155 | AI6: 259968 | AJ6: 4368510 | AK6: =AJ6/AI6 -> 16.80403 | AL6: =AK6*3.30578512 -> 55.550511 | AM6: 283028 | AN6: 4752291 | AO6: =AN6/AM6 -> 16.790886 | AP6: =AO6*3.30578512 -> 55.507062 | AQ6: 297073 | AR6: 5803999 | AS6: =AR6/AQ6 -> 19.537282 | AT6: =AS6*3.30578512 -> 64.586056 | AU6: 297961 | AV6: 6201695 | AW6: =AV6/AU6 -> 20.813781 | AX6: =AW6*3.30578512 -> 68.805888 | AY6: 336799 | AZ6: 7061378 | BA6: =AZ6/AY6 -> 20.966149 | BB6: =BA6*3.30578512 -> 69.309583 | BC6: 349495 | BD6: 6533442 | BE6: =BD6/BC6 -> 18.69395 | BF6: =BE6*3.30578512 -> 61.798181 | BG6: 299766 | BH6: 9026374 | BI6: =BH6/BG6 -> 30.1114 | BJ6: =BI6*3.30578512 -> 99.541819 | BK6: 265050 | BL6: 4385844 | BM6: =BL6/BK6 -> 16.547233 | BN6: =BM6*3.30578512 -> 54.701595 | BO6: 301640 | BP6: 5766701 | BQ6: =BP6/BO6 -> 19.117826 | BR6: =BQ6*3.30578512 -> 63.199424 | BS6: 273555 | BT6: 5429301 | BU6: =BT6/BS6 -> 19.847201 | BV6: =BU6*3.30578512 -> 65.610581 | BW6: 242463 | BX6: 5250744 | BY6: =BX6/BW6 -> 21.655857 | BZ6: =BY6*3.30578512 -> 71.589609 | CA6: 260084 | CB6: 4704308 | CC6: =CB6/CA6 -> 18.087649 | CD6: =CC6*3.30578512 -> 59.79388 | CE6: 293055 | CF6: 5122568 | CG6: =CF6/CE6 -> 17.479886 | CH6: =CG6*3.30578512 -> 57.784747 | CI6: 319914 | CJ6: 5949907 | CK6: =CJ6/CI6 -> 18.598458 | CL6: =CK6*3.30578512 -> 61.482505 | CM6: 373898 | CN6: 6937033 | CO6: =CN6/CM6 -> 18.553277 | CP6: =CO6*3.30578512 -> 61.333146 | CQ6: 259485 | CR6: 5528798 | CS6: =CR6/CQ6 -> 21.306812 | CT6: =CS6*3.30578512 -> 70.435741 | CU6: 271390 | CV6: 5482636 | CW6: =CV6/CU6 -> 20.202056 | CX6: =CW6*3.30578512 -> 66.783656 | CY6: 251489 | CZ6: 5666683 | DA6: =CZ6/CY6 -> 22.532528 | DB6: =DA6*3.30578512 -> 74.487697 | DC6: 183913 | DD6: 3718826 | DE6: =DD6/DC6 -> 20.220572 | DF6: =DE6*3.30578512 -> 66.844865 | DG6: 251143 | DH6: 5111682 | DI6: =DH6/DG6 -> 20.353671 | DJ6: =DI6*3.30578512 -> 67.284863 | DK6: 508490 | DL6: 14852741 | DM6: =DL6/DK6 -> 29.209505 | DN6: =DM6*3.30578512 -> 96.560346 | DO6: 254162 | DP6: 5601602 | DQ6: =DP6/DO6 -> 22.039494 | DR6: =DQ6*3.30578512 -> 72.857833 | DS6: 258448 | DT6: 5469074 | DU6: =DT6/DS6 -> 21.161216 | DV6: =DU6*3.30578512 -> 69.954434 | DW6: 305800 | DX6: 5297357 | DY6: =DX6/DW6 -> 17.322946 | DZ6: =DY6*3.30578512 -> 57.265938 | EA6: 331828 | EB6: 7277925 | EC6: =EB6/EA6 -> 21.932824 | ED6: =EC6*3.30578512 -> 72.505202 | EE6: 251692 | EF6: 5649538 | EG6: =EF6/EE6 -> 22.446236 | EH6: =EG6*3.30578512 -> 74.202433 | EI6: 210277 | EJ6: 5070897 | EK6: =EJ6/EI6 -> 24.115319 | EL6: =EK6*3.30578512 -> 79.720064 | EM6: 232139 | EN6: 5033326 | EO6: =EN6/EM6 -> 21.68238 | EP6: =EO6*3.30578512 -> 71.677289 | EQ6: 288301 | ER6: 5920779 | ES6: =ER6/EQ6 -> 20.536797 | ET6: =ES6*3.30578512 -> 67.890237 | EU6: 268000 | EV6: 7319344.1 | EW6: =EV6/EU6 -> 27.310986 | EX6: =EW6*3.30578512 -> 90.28425 | EY6: 182826 | EZ6: 4543917.8 | FA6: =EZ6/EY6 -> 24.853783 | FB6: =FA6*3.30578512 -> 82.161267 | FC6: 315483 | FD6: 10934838 | FE6: =FD6/FC6 -> 34.660624 | FF6: =FE6*3.30578512 -> 114.58058 | FG6: 360430 | FH6: 12264372 | FI6: =FH6/FG6 -> 34.027058 | FJ6: =FI6*3.30578512 -> 112.48614 | FK6: 351659 | FL6: 7324507.7 | FM6: =FL6/FK6 -> 20.828438 | FN6: =FM6*3.30578512 -> 68.854341 | FQ6: =FP6/FO6 -> #DIV/0! | FR6: =FQ6*3.30578512 -> #DIV/0! | FU6: =FT6/FS6 -> #DIV/0! | FV6: =FU6*3.30578512 -> #DIV/0! | FY6: =FX6/FW6 -> #DIV/0! | FZ6: =FY6*3.30578512 -> #DIV/0!
B7: 工場及び作業場 | C7: 8378701 | D7: 151709668 | E7: =D7/C7 -> 18.106586 | F7: =E7*3.30578512 -> 59.856482 | G7: 461179 | H7: 11699628 | I7: =H7/G7 -> 25.368952 | J7: =I7*3.30578512 -> 83.864305 | K7: 576152 | L7: 14477709 | M7: =L7/K7 -> 25.12828 | N7: =M7*3.30578512 -> 83.068695 | O7: 634383 | P7: 13578836 | Q7: =P7/O7 -> 21.404792 | R7: =Q7*3.30578512 -> 70.759642 | S7: 929291 | T7: 25142992 | U7: =T7/S7 -> 27.056102 | V7: =U7*3.30578512 -> 89.441659 | W7: 624765 | X7: 12090194 | Y7: =X7/W7 -> 19.351587 | Z7: =Y7*3.30578512 -> 63.972187 | AA7: 896466 | AB7: 21601128 | AC7: =AB7/AA7 -> 24.09587 | AD7: =AC7*3.30578512 -> 79.655768 | AE7: 674375 | AF7: 12666144 | AG7: =AF7/AE7 -> 18.782049 | AH7: =AG7*3.30578512 -> 62.089417 | AI7: 693613 | AJ7: 18737249 | AK7: =AJ7/AI7 -> 27.013982 | AL7: =AK7*3.30578512 -> 89.302419 | AM7: 543075 | AN7: 15759087 | AO7: =AN7/AM7 -> 29.018252 | AP7: =AO7*3.30578512 -> 95.928104 | AQ7: 705775 | AR7: 19656272 | AS7: =AR7/AQ7 -> 27.850621 | AT7: =AS7*3.30578512 -> 92.068168 | AU7: 575926 | AV7: 14206123 | AW7: =AV7/AU7 -> 24.666577 | AX7: =AW7*3.30578512 -> 81.542403 | AY7: 663086 | AZ7: 18570676 | BA7: =AZ7/AY7 -> 28.006437 | BB7: =BA7*3.30578512 -> 92.583261 | BC7: 518150 | BD7: 13016740 | BE7: =BD7/BC7 -> 25.121567 | BF7: =BE7*3.30578512 -> 83.046503 | BG7: 538992 | BH7: 13018503 | BI7: =BH7/BG7 -> 24.153425 | BJ7: =BI7*3.30578512 -> 79.846034 | BK7: 531918 | BL7: 15139970 | BM7: =BL7/BK7 -> 28.462977 | BN7: =BM7*3.30578512 -> 94.092487 | BO7: 869886 | BP7: 25825737 | BQ7: =BP7/BO7 -> 29.688645 | BR7: =BQ7*3.30578512 -> 98.144282 | BS7: 435893 | BT7: 11764341 | BU7: =BT7/BS7 -> 26.989057 | BV7: =BU7*3.30578512 -> 89.220023 | BW7: 527697 | BX7: 18187780 | BY7: =BX7/BW7 -> 34.466332 | BZ7: =BY7*3.30578512 -> 113.93829 | CA7: 509297 | CB7: 15393273 | CC7: =CB7/CA7 -> 30.224551 | CD7: =CC7*3.30578512 -> 99.91587 | CE7: 361341 | CF7: 9577597 | CG7: =CF7/CE7 -> 26.505702 | CH7: =CG7*3.30578512 -> 87.622156 | CI7: 769521 | CJ7: 36413143 | CK7: =CJ7/CI7 -> 47.319232 | CL7: =CK7*3.30578512 -> 156.42721 | CM7: 522592 | CN7: 20713834 | CO7: =CN7/CM7 -> 39.636722 | CP7: =CO7*3.30578512 -> 131.03049 | CQ7: 629812 | CR7: 24095807 | CS7: =CR7/CQ7 -> 38.25873 | CT7: =CS7*3.30578512 -> 126.47514 | CU7: 530454 | CV7: 15670166 | CW7: =CV7/CU7 -> 29.541046 | CX7: =CW7*3.30578512 -> 97.65635 | CY7: 704081 | CZ7: 25256331 | DA7: =CZ7/CY7 -> 35.871343 | DB7: =DA7*3.30578512 -> 118.58295 | DC7: 521230 | DD7: 15818107 | DE7: =DD7/DC7 -> 30.347653 | DF7: =DE7*3.30578512 -> 100.32282 | DG7: 539736 | DH7: 20160905 | DI7: =DH7/DG7 -> 37.353271 | DJ7: =DI7*3.30578512 -> 123.48189 | DK7: 765476 | DL7: 27470352 | DM7: =DL7/DK7 -> 35.886627 | DN7: =DM7*3.30578512 -> 118.63348 | DO7: 461489 | DP7: 15973688 | DQ7: =DP7/DO7 -> 34.613367 | DR7: =DQ7*3.30578512 -> 114.42435 | DS7: 541315 | DT7: 16496767 | DU7: =DT7/DS7 -> 30.475355 | DV7: =DU7*3.30578512 -> 100.74498 | DW7: 515771 | DX7: 15552540 | DY7: =DX7/DW7 -> 30.153964 | DZ7: =DY7*3.30578512 -> 99.682524 | EA7: 664134 | EB7: 28924634 | EC7: =EB7/EA7 -> 43.552407 | ED7: =EC7*3.30578512 -> 143.9749 | EE7: 588359 | EF7: 19307098 | EG7: =EF7/EE7 -> 32.815166 | EH7: =EG7*3.30578512 -> 108.47989 | EI7: 584507 | EJ7: 24734102 | EK7: =EJ7/EI7 -> 42.316178 | EL7: =EK7*3.30578512 -> 139.88819 | EM7: 458530 | EN7: 13199930 | EO7: =EN7/EM7 -> 28.787495 | EP7: =EO7*3.30578512 -> 95.165272 | EQ7: 498123 | ER7: 16397926 | ES7: =ER7/EQ7 -> 32.919432 | ET7: =ES7*3.30578512 -> 108.82457 | EU7: 361898 | EV7: 14097829 | EW7: =EV7/EU7 -> 38.955254 | EX7: =EW7*3.30578512 -> 128.7777 | EY7: 448540 | EZ7: 20530172 | FA7: =EZ7/EY7 -> 45.771107 | FB7: =FA7*3.30578512 -> 151.30944 | FC7: 407575 | FD7: 14030443 | FE7: =FD7/FC7 -> 34.424199 | FF7: =FE7*3.30578512 -> 113.79901 | FG7: 619321 | FH7: 21840277 | FI7: =FH7/FG7 -> 35.264875 | FJ7: =FI7*3.30578512 -> 116.5781 | FK7: 595452 | FL7: 26572301 | FM7: =FL7/FK7 -> 44.625429 | FN7: =FM7*3.30578512 -> 147.52208 | FQ7: =FP7/FO7 -> #DIV/0! | FR7: =FQ7*3.30578512 -> #DIV/0! | FU7: =FT7/FS7 -> #DIV/0! | FV7: =FU7*3.30578512 -> #DIV/0! | FY7: =FX7/FW7 -> #DIV/0! | FZ7: =FY7*3.30578512 -> #DIV/0!
B8: 倉庫 | C8: 6068912 | D8: 71338916 | E8: =D8/C8 -> 11.754811 | F8: =E8*3.30578512 -> 38.858881 | G8: 835125 | H8: 10518520 | I8: =H8/G8 -> 12.595144 | J8: =I8*3.30578512 -> 41.636841 | K8: 775039 | L8: 10489793 | M8: =L8/K8 -> 13.534536 | N8: =M8*3.30578512 -> 44.742267 | O8: 912194 | P8: 11744726 | Q8: =P8/O8 -> 12.87525 | R8: =Q8*3.30578512 -> 42.562811 | S8: 881069 | T8: 11962789 | U8: =T8/S8 -> 13.577585 | V8: =U8*3.30578512 -> 44.884578 | W8: 852317 | X8: 11001456 | Y8: =X8/W8 -> 12.907705 | Z8: =Y8*3.30578512 -> 42.670098 | AA8: 963165 | AB8: 13762764 | AC8: =AB8/AA8 -> 14.289103 | AD8: =AC8*3.30578512 -> 47.236704 | AE8: 931010 | AF8: 14396013 | AG8: =AF8/AE8 -> 15.462791 | AH8: =AG8*3.30578512 -> 51.116664 | AI8: 660707 | AJ8: 9569279 | AK8: =AJ8/AI8 -> 14.483393 | AL8: =AK8*3.30578512 -> 47.878984 | AM8: 572632 | AN8: 8144155 | AO8: =AN8/AM8 -> 14.222319 | AP8: =AO8*3.30578512 -> 47.015931 | AQ8: 462154 | AR8: 7709515 | AS8: =AR8/AQ8 -> 16.681701 | AT8: =AS8*3.30578512 -> 55.14612 | AU8: 600119 | AV8: 8565731 | AW8: =AV8/AU8 -> 14.273387 | AX8: =AW8*3.30578512 -> 47.184752 | AY8: 672464 | AZ8: 9951811 | BA8: =AZ8/AY8 -> 14.799024 | BB8: =BA8*3.30578512 -> 48.922394 | BC8: 674938 | BD8: 10530530 | BE8: =BD8/BC8 -> 15.602218 | BF8: =BE8*3.30578512 -> 51.577581 | BG8: 900471 | BH8: 12993465 | BI8: =BH8/BG8 -> 14.429632 | BJ8: =BI8*3.30578512 -> 47.701262 | BK8: 346787 | BL8: 5546101 | BM8: =BL8/BK8 -> 15.992817 | BN8: =BM8*3.30578512 -> 52.868816 | BO8: 1025089 | BP8: 14773342 | BQ8: =BP8/BO8 -> 14.411765 | BR8: =BQ8*3.30578512 -> 47.642199 | BS8: 564527 | BT8: 8541089 | BU8: =BT8/BS8 -> 15.129638 | BV8: =BU8*3.30578512 -> 50.015331 | BW8: 498046 | BX8: 8652166 | BY8: =BX8/BW8 -> 17.372223 | BZ8: =BY8*3.30578512 -> 57.428835 | CA8: 489596 | CB8: 7565679 | CC8: =CB8/CA8 -> 15.452902 | CD8: =CC8*3.30578512 -> 51.083973 | CE8: 674749 | CF8: 11295329 | CG8: =CF8/CE8 -> 16.740046 | CH8: =CG8*3.30578512 -> 55.338994 | CI8: 566910 | CJ8: 10583923 | CK8: =CJ8/CI8 -> 18.669494 | CL8: =CK8*3.30578512 -> 61.717336 | CM8: 813132 | CN8: 17541418 | CO8: =CN8/CM8 -> 21.572657 | CP8: =CO8*3.30578512 -> 71.31457 | CQ8: 431285 | CR8: 7939075 | CS8: =CR8/CQ8 -> 18.407955 | CT8: =CS8*3.30578512 -> 60.852745 | CU8: 547167 | CV8: 8335203 | CW8: =CV8/CU8 -> 15.23338 | CX8: =CW8*3.30578512 -> 50.358282 | CY8: 471248 | CZ8: 7460266 | DA8: =CZ8/CY8 -> 15.83087 | DB8: =DA8*3.30578512 -> 52.333456 | DC8: 769671 | DD8: 12584915 | DE8: =DD8/DC8 -> 16.351032 | DF8: =DE8*3.30578512 -> 54.052998 | DG8: 535000 | DH8: 9907385 | DI8: =DH8/DG8 -> 18.518477 | DJ8: =DI8*3.30578512 -> 61.218105 | DK8: 633476 | DL8: 11687494 | DM8: =DL8/DK8 -> 18.449782 | DN8: =DM8*3.30578512 -> 60.991014 | DO8: 534316 | DP8: 8145786 | DQ8: =DP8/DO8 -> 15.245259 | DR8: =DQ8*3.30578512 -> 50.397552 | DS8: 824075 | DT8: 13859993 | DU8: =DT8/DS8 -> 16.818849 | DV8: =DU8*3.30578512 -> 55.599501 | DW8: 533993 | DX8: 9059516 | DY8: =DX8/DW8 -> 16.965608 | DZ8: =DY8*3.30578512 -> 56.084655 | EA8: 422016 | EB8: 10597770 | EC8: =EB8/EA8 -> 25.112247 | ED8: =EC8*3.30578512 -> 83.015692 | EE8: 918818 | EF8: 16429638 | EG8: =EF8/EE8 -> 17.881276 | EH8: =EG8*3.30578512 -> 59.111655 | EI8: 672820 | EJ8: 10715865 | EK8: =EJ8/EI8 -> 15.926793 | EL8: =EK8*3.30578512 -> 52.650556 | EM8: 859998 | EN8: 17432970 | EO8: =EN8/EM8 -> 20.270942 | EP8: =EO8*3.30578512 -> 67.01138 | EQ8: 685091 | ER8: 12932026 | ES8: =ER8/EQ8 -> 18.876362 | ET8: =ES8*3.30578512 -> 62.401198 | EU8: 637391 | EV8: 14475455 | EW8: =EV8/EU8 -> 22.710479 | EX8: =EW8*3.30578512 -> 75.075963 | EY8: 846196 | EZ8: 17147341 | FA8: =EZ8/EY8 -> 20.26403 | FB8: =FA8*3.30578512 -> 66.988528 | FC8: 450890 | FD8: 8036493.1 | FE8: =FD8/FC8 -> 17.823622 | FF8: =FE8*3.30578512 -> 58.921066 | FG8: 462406 | FH8: 9510154.6 | FI8: =FH8/FG8 -> 20.566676 | FJ8: =FI8*3.30578512 -> 67.989013 | FK8: 655850 | FL8: 14292666 | FM8: =FL8/FK8 -> 21.792583 | FN8: =FM8*3.30578512 -> 72.041597 | FQ8: =FP8/FO8 -> #DIV/0! | FR8: =FQ8*3.30578512 -> #DIV/0! | FU8: =FT8/FS8 -> #DIV/0! | FV8: =FU8*3.30578512 -> #DIV/0! | FY8: =FX8/FW8 -> #DIV/0! | FZ8: =FY8*3.30578512 -> #DIV/0!
B9: 学校の校舎 | C9: 1386294 | D9: 32660664 | E9: =D9/C9 -> 23.559695 | F9: =E9*3.30578512 -> 77.88329 | G9: 41707 | H9: 1257098 | I9: =H9/G9 -> 30.141175 | J9: =I9*3.30578512 -> 99.640249 | K9: 46099 | L9: 817146 | M9: =L9/K9 -> 17.725894 | N9: =M9*3.30578512 -> 58.597998 | O9: 28892 | P9: 615910 | Q9: =P9/O9 -> 21.317666 | R9: =Q9*3.30578512 -> 70.471622 | S9: 55420 | T9: 1672270 | U9: =T9/S9 -> 30.174486 | V9: =U9*3.30578512 -> 99.750366 | W9: 101064 | X9: 3428795 | Y9: =X9/W9 -> 33.926967 | Z9: =Y9*3.30578512 -> 112.15526 | AA9: 159002 | AB9: 4075445 | AC9: =AB9/AA9 -> 25.631407 | AD9: =AC9*3.30578512 -> 84.731924 | AE9: 104728 | AF9: 2873377 | AG9: =AF9/AE9 -> 27.436569 | AH9: =AG9*3.30578512 -> 90.699402 | AI9: 144121 | AJ9: 5453098 | AK9: =AJ9/AI9 -> 37.836943 | AL9: =AK9*3.30578512 -> 125.0808 | AM9: 72391 | AN9: 1663524 | AO9: =AN9/AM9 -> 22.979707 | AP9: =AO9*3.30578512 -> 75.965975 | AQ9: 109123 | AR9: 2766055 | AS9: =AR9/AQ9 -> 25.348048 | AT9: =AS9*3.30578512 -> 83.795199 | AU9: 202225 | AV9: 6923977 | AW9: =AV9/AU9 -> 34.238976 | AX9: =AW9*3.30578512 -> 113.1867 | AY9: 43313 | AZ9: 1096098 | BA9: =AZ9/AY9 -> 25.306444 | BB9: =BA9*3.30578512 -> 83.657665 | BC9: 39246 | BD9: 944029 | BE9: =BD9/BC9 -> 24.054146 | BF9: =BE9*3.30578512 -> 79.517837 | BG9: 59265 | BH9: 1946253 | BI9: =BH9/BG9 -> 32.839838 | BJ9: =BI9*3.30578512 -> 108.56145 | BK9: 63893 | BL9: 1200093 | BM9: =BL9/BK9 -> 18.782856 | BN9: =BM9*3.30578512 -> 62.092085 | BO9: 113460 | BP9: 2994431 | BQ9: =BP9/BO9 -> 26.391953 | BR9: =BQ9*3.30578512 -> 87.246126 | BS9: 59127 | BT9: 1557736 | BU9: =BT9/BS9 -> 26.345595 | BV9: =BU9*3.30578512 -> 87.092876 | BW9: 74781 | BX9: 2690113 | BY9: =BX9/BW9 -> 35.973215 | BZ9: =BY9*3.30578512 -> 118.91972 | CA9: 95736 | CB9: 5035463 | CC9: =CB9/CA9 -> 52.597382 | CD9: =CC9*3.30578512 -> 173.87564 | CE9: 42496 | CF9: 1340424 | CG9: =CF9/CE9 -> 31.542357 | CH9: =CG9*3.30578512 -> 104.27225 | CI9: 66248 | CJ9: 1746260 | CK9: =CJ9/CI9 -> 26.359437 | CL9: =CK9*3.30578512 -> 87.138635 | CM9: 93038 | CN9: 2863704 | CO9: =CN9/CM9 -> 30.779939 | CP9: =CO9*3.30578512 -> 101.75187 | CQ9: 84806 | CR9: 3555254 | CS9: =CR9/CQ9 -> 41.922199 | CT9: =CS9*3.30578512 -> 138.58578 | CU9: 27220 | CV9: 791133 | CW9: =CV9/CU9 -> 29.064401 | CX9: =CW9*3.30578512 -> 96.080665 | CY9: 67724 | CZ9: 2787558 | DA9: =CZ9/CY9 -> 41.160563 | DB9: =DA9*3.30578512 -> 136.06798 | DC9: 79088 | DD9: 2635389 | DE9: =DD9/DC9 -> 33.322236 | DF9: =DE9*3.30578512 -> 110.15615 | DG9: 59923 | DH9: 1746024 | DI9: =DH9/DG9 -> 29.137794 | DJ9: =DI9*3.30578512 -> 96.323284 | DK9: 96462 | DL9: 3082989 | DM9: =DL9/DK9 -> 31.960658 | DN9: =DM9*3.30578512 -> 105.65507 | DO9: 41794 | DP9: 1429051 | DQ9: =DP9/DO9 -> 34.192731 | DR9: =DQ9*3.30578512 -> 113.03382 | DS9: 60645 | DT9: 1714198 | DU9: =DT9/DS9 -> 28.266106 | DV9: =DU9*3.30578512 -> 93.441673 | DW9: 76047 | DX9: 3006457 | DY9: =DX9/DW9 -> 39.534196 | DZ9: =DY9*3.30578512 -> 130.69156 | EA9: 38811 | EB9: 1172992 | EC9: =EB9/EA9 -> 30.223184 | ED9: =EC9*3.30578512 -> 99.911352 | EE9: 97907 | EF9: 3537671 | EG9: =EF9/EE9 -> 36.132973 | EH9: =EG9*3.30578512 -> 119.44784 | EI9: 127139 | EJ9: 6918704 | EK9: =EJ9/EI9 -> 54.418424 | EL9: =EK9*3.30578512 -> 179.89562 | EM9: 64270 | EN9: 1724033 | EO9: =EN9/EM9 -> 26.824848 | EP9: =EO9*3.30578512 -> 88.677184 | EQ9: 97785 | ER9: 2305605 | ES9: =ER9/EQ9 -> 23.57831 | ET9: =ES9*3.30578512 -> 77.944825 | EU9: 54215 | EV9: 2414176.8 | EW9: =EV9/EU9 -> 44.529684 | EX9: =EW9*3.30578512 -> 147.20557 | EY9: 59521 | EZ9: 2046943.4 | FA9: =EZ9/EY9 -> 34.390273 | FB9: =FA9*3.30578512 -> 113.68685 | FC9: 90752 | FD9: 3601431.8 | FE9: =FD9/FC9 -> 39.684324 | FF9: =FE9*3.30578512 -> 131.18785 | FG9: 85456 | FH9: 2622310.3 | FI9: =FH9/FG9 -> 30.686087 | FJ9: =FI9*3.30578512 -> 101.44161 | FK9: 58555 | FL9: 1998331.5 | FM9: =FL9/FK9 -> 34.127427 | FN9: =FM9*3.30578512 -> 112.81794 | FQ9: =FP9/FO9 -> #DIV/0! | FR9: =FQ9*3.30578512 -> #DIV/0! | FU9: =FT9/FS9 -> #DIV/0! | FV9: =FU9*3.30578512 -> #DIV/0! | FY9: =FX9/FW9 -> #DIV/0! | FZ9: =FY9*3.30578512 -> #DIV/0!
B10: 病院・診療所 | C10: 1106860 | D10: 32198273 | E10: =D10/C10 -> 29.089743 | F10: =E10*3.30578512 -> 96.16444 | G10: 57385 | H10: 1755028 | I10: =H10/G10 -> 30.583393 | J10: =I10*3.30578512 -> 101.10213 | K10: 43562 | L10: 1402723 | M10: =L10/K10 -> 32.200611 | N10: =M10*3.30578512 -> 106.4483 | O10: 82304 | P10: 2924934 | Q10: =P10/O10 -> 35.538176 | R10: =Q10*3.30578512 -> 117.48157 | S10: 96019 | T10: 3707881 | U10: =T10/S10 -> 38.616118 | V10: =U10*3.30578512 -> 127.65659 | W10: 43189 | X10: 1435762 | Y10: =X10/W10 -> 33.243696 | Z10: =Y10*3.30578512 -> 109.89652 | AA10: 28557 | AB10: 1059931 | AC10: =AB10/AA10 -> 37.116329 | AD10: =AC10*3.30578512 -> 122.69861 | AE10: 56783 | AF10: 2046138 | AG10: =AF10/AE10 -> 36.034341 | AH10: =AG10*3.30578512 -> 119.12179 | AI10: 72247 | AJ10: 3036285 | AK10: =AJ10/AI10 -> 42.026451 | AL10: =AK10*3.30578512 -> 138.93042 | AM10: 50968 | AN10: 1703512 | AO10: =AN10/AM10 -> 33.423167 | AP10: =AO10*3.30578512 -> 110.48981 | AQ10: 132415 | AR10: 4726199 | AS10: =AR10/AQ10 -> 35.692323 | AT10: =AS10*3.30578512 -> 117.99115 | AU10: 58545 | AV10: 2537034 | AW10: =AV10/AU10 -> 43.334768 | AX10: =AW10*3.30578512 -> 143.25543 | AY10: 58359 | AZ10: 1995069 | BA10: =AZ10/AY10 -> 34.186141 | BB10: =BA10*3.30578512 -> 113.01204 | BC10: 72190 | BD10: 2761493 | BE10: =BD10/BC10 -> 38.253124 | BF10: =BE10*3.30578512 -> 126.45661 | BG10: 163710 | BH10: 7492181 | BI10: =BH10/BG10 -> 45.764956 | BJ10: =BI10*3.30578512 -> 151.28911 | BK10: 29840 | BL10: 1086113 | BM10: =BL10/BK10 -> 36.397889 | BN10: =BM10*3.30578512 -> 120.3236 | BO10: 35438 | BP10: 1486760 | BQ10: =BP10/BO10 -> 41.953835 | BR10: =BQ10*3.30578512 -> 138.69036 | BS10: 77116 | BT10: 3958952 | BU10: =BT10/BS10 -> 51.337621 | BV10: =BU10*3.30578512 -> 169.71114 | BW10: 46232 | BX10: 1816366 | BY10: =BX10/BW10 -> 39.288069 | BZ10: =BY10*3.30578512 -> 129.87791 | CA10: 28963 | CB10: 1084974 | CC10: =CB10/CA10 -> 37.460691 | CD10: =CC10*3.30578512 -> 123.837 | CE10: 60497 | CF10: 3091654 | CG10: =CF10/CE10 -> 51.104253 | CH10: =CG10*3.30578512 -> 168.93968 | CI10: 26281 | CJ10: 1308569 | CK10: =CJ10/CI10 -> 49.791446 | CL10: =CK10*3.30578512 -> 164.59982 | CM10: 45229 | CN10: 2018809 | CO10: =CN10/CM10 -> 44.635278 | CP10: =CO10*3.30578512 -> 147.55464 | CQ10: 31937 | CR10: 1354894 | CS10: =CR10/CQ10 -> 42.42396 | CT10: =CS10*3.30578512 -> 140.24449 | CU10: 21575 | CV10: 771966 | CW10: =CV10/CU10 -> 35.780579 | CX10: =CW10*3.30578512 -> 118.28291 | CY10: 18213 | CZ10: 718820 | DA10: =CZ10/CY10 -> 39.467413 | DB10: =DA10*3.30578512 -> 130.47079 | DC10: 61783 | DD10: 2591161 | DE10: =DD10/DC10 -> 41.939708 | DF10: =DE10*3.30578512 -> 138.64366 | DG10: 75208 | DH10: 3674094 | DI10: =DH10/DG10 -> 48.852436 | DJ10: =DI10*3.30578512 -> 161.49566 | DK10: 39809 | DL10: 1533622 | DM10: =DL10/DK10 -> 38.524505 | DN10: =DM10*3.30578512 -> 127.35373 | DO10: 56450 | DP10: 3493040 | DQ10: =DP10/DO10 -> 61.878477 | DR10: =DQ10*3.30578512 -> 204.55695 | DS10: 30018 | DT10: 1239589 | DU10: =DT10/DS10 -> 41.294856 | DV10: =DU10*3.30578512 -> 136.51192 | DW10: 21802 | DX10: 739533 | DY10: =DX10/DW10 -> 33.92042 | DZ10: =DY10*3.30578512 -> 112.13362 | EA10: 17463 | EB10: 662700 | EC10: =EB10/EA10 -> 37.948806 | ED10: =EC10*3.30578512 -> 125.4506 | EE10: 50757 | EF10: 2939783 | EG10: =EF10/EE10 -> 57.91877 | EH10: =EG10*3.30578512 -> 191.46701 | EI10: 15878 | EJ10: 569335 | EK10: =EJ10/EI10 -> 35.856846 | EL10: =EK10*3.30578512 -> 118.53503 | EM10: 85131 | EN10: 5736312 | EO10: =EN10/EM10 -> 67.382176 | EP10: =EO10*3.30578512 -> 222.75099 | EQ10: 18176 | ER10: 663243 | ES10: =ER10/EQ10 -> 36.490042 | ET10: =ES10*3.30578512 -> 120.62824 | EU10: 17345 | EV10: 624753.38 | EW10: =EV10/EU10 -> 36.01922 | EX10: =EW10*3.30578512 -> 119.0718 | EY10: 59787 | EZ10: 3657944 | FA10: =EZ10/EY10 -> 61.182934 | FB10: =FA10*3.30578512 -> 202.25763 | FC10: 81632 | FD10: 5121355.7 | FE10: =FD10/FC10 -> 62.737109 | FF10: =FE10*3.30578512 -> 207.3954 | FG10: 89374 | FH10: 4527145.6 | FI10: =FH10/FG10 -> 50.653944 | FJ10: =FI10*3.30578512 -> 167.45106 | FK10: 39756 | FL10: 2022945.2 | FM10: =FL10/FK10 -> 50.884023 | FN10: =FM10*3.30578512 -> 168.21165 | FQ10: =FP10/FO10 -> #DIV/0! | FR10: =FQ10*3.30578512 -> #DIV/0! | FU10: =FT10/FS10 -> #DIV/0! | FV10: =FU10*3.30578512 -> #DIV/0! | FY10: =FX10/FW10 -> #DIV/0! | FZ10: =FY10*3.30578512 -> #DIV/0!
B11: その他 | C11: 8608567 | D11: 167466039 | E11: =D11/C11 -> 19.453416 | F11: =E11*3.30578512 -> 64.308815 | G11: 468787 | H11: 11628801 | I11: =H11/G11 -> 24.806151 | J11: =I11*3.30578512 -> 82.003804 | K11: 554269 | L11: 13303890 | M11: =L11/K11 -> 24.002587 | N11: =M11*3.30578512 -> 79.347396 | O11: 475415 | P11: 11484248 | Q11: =P11/O11 -> 24.156259 | R11: =Q11*3.30578512 -> 79.855402 | S11: 543839 | T11: 13801597 | U11: =T11/S11 -> 25.378094 | V11: =U11*3.30578512 -> 83.894524 | W11: 444209 | X11: 14214159 | Y11: =X11/W11 -> 31.998809 | Z11: =Y11*3.30578512 -> 105.78119 | AA11: 525185 | AB11: 12856987 | AC11: =AB11/AA11 -> 24.480872 | AD11: =AC11*3.30578512 -> 80.928504 | AE11: 784656 | AF11: 23232064 | AG11: =AF11/AE11 -> 29.607961 | AH11: =AG11*3.30578512 -> 97.877556 | AI11: 516754 | AJ11: 14356047 | AK11: =AJ11/AI11 -> 27.781202 | AL11: =AK11*3.30578512 -> 91.838683 | AM11: 483962 | AN11: 13861034 | AO11: =AN11/AM11 -> 28.640749 | AP11: =AO11*3.30578512 -> 94.680161 | AQ11: 517179 | AR11: 13067907 | AS11: =AR11/AQ11 -> 25.267667 | AT11: =AS11*3.30578512 -> 83.529479 | AU11: 493168 | AV11: 12400631 | AW11: =AV11/AU11 -> 25.144841 | AX11: =AW11*3.30578512 -> 83.123442 | AY11: 452254 | AZ11: 10896023 | BA11: =AZ11/AY11 -> 24.092707 | BB11: =BA11*3.30578512 -> 79.645311 | BC11: 426713 | BD11: 12037838 | BE11: =BD11/BC11 -> 28.210619 | BF11: =BE11*3.30578512 -> 93.258246 | BG11: 426628 | BH11: 10028344 | BI11: =BH11/BG11 -> 23.506061 | BJ11: =BI11*3.30578512 -> 77.705988 | BK11: 429740 | BL11: 10476952 | BM11: =BL11/BK11 -> 24.379746 | BN11: =BM11*3.30578512 -> 80.594201 | BO11: 477653 | BP11: 14518674 | BQ11: =BP11/BO11 -> 30.395861 | BR11: =BQ11*3.30578512 -> 100.48218 | BS11: 436991 | BT11: 13656448 | BU11: =BT11/BS11 -> 31.251097 | BV11: =BU11*3.30578512 -> 103.30941 | BW11: 441980 | BX11: 13211462 | BY11: =BX11/BW11 -> 29.891538 | BZ11: =BY11*3.30578512 -> 98.815002 | CA11: 587762 | CB11: 18266439 | CC11: =CB11/CA11 -> 31.077952 | CD11: =CC11*3.30578512 -> 102.73703 | CE11: 507410 | CF11: 15077442 | CG11: =CF11/CE11 -> 29.714515 | CH11: =CG11*3.30578512 -> 98.229801 | CI11: 431504 | CJ11: 13681572 | CK11: =CJ11/CI11 -> 31.70671 | CL11: =CK11*3.30578512 -> 104.81557 | CM11: 569025 | CN11: 16385060 | CO11: =CN11/CM11 -> 28.794974 | CP11: =CO11*3.30578512 -> 95.189996 | CQ11: 384777 | CR11: 12314279 | CS11: =CR11/CQ11 -> 32.003677 | CT11: =CS11*3.30578512 -> 105.79728 | CU11: 396343 | CV11: 13183424 | CW11: =CV11/CU11 -> 33.262664 | CX11: =CW11*3.30578512 -> 109.95922 | CY11: 382059 | CZ11: 13252033 | DA11: =CZ11/CY11 -> 34.685829 | DB11: =DA11*3.30578512 -> 114.6639 | DC11: 423007 | DD11: 22456401 | DE11: =DD11/DC11 -> 53.08754 | DF11: =DE11*3.30578512 -> 175.496 | DG11: 467942 | DH11: 19166153 | DI11: =DH11/DG11 -> 40.958394 | DJ11: =DI11*3.30578512 -> 135.39965 | DK11: 690848 | DL11: 28299445 | DM11: =DL11/DK11 -> 40.963345 | DN11: =DM11*3.30578512 -> 135.41602 | DO11: 369532 | DP11: 12152064 | DQ11: =DP11/DO11 -> 32.885011 | DR11: =DQ11*3.30578512 -> 108.71078 | DS11: 413077 | DT11: 14026501 | DU11: =DT11/DS11 -> 33.956141 | DV11: =DU11*3.30578512 -> 112.25171 | DW11: 369620 | DX11: 11544272 | DY11: =DX11/DW11 -> 31.232812 | DZ11: =DY11*3.30578512 -> 103.24897 | EA11: 427197 | EB11: 21559705 | EC11: =EB11/EA11 -> 50.467829 | ED11: =EC11*3.30578512 -> 166.8358 | EE11: 473210 | EF11: 17192389 | EG11: =EF11/EE11 -> 36.331415 | EH11: =EG11*3.30578512 -> 120.10385 | EI11: 432596 | EJ11: 15735547 | EK11: =EJ11/EI11 -> 36.374694 | EL11: =EK11*3.30578512 -> 120.24692 | EM11: 344658 | EN11: 10792773 | EO11: =EN11/EM11 -> 31.314442 | EP11: =EO11*3.30578512 -> 103.51882 | EQ11: 335412 | ER11: 12330928 | ES11: =ER11/EQ11 -> 36.763527 | ET11: =ES11*3.30578512 -> 121.53232 | EU11: 353303 | EV11: 10780340 | EW11: =EV11/EU11 -> 30.513016 | EX11: =EW11*3.30578512 -> 100.86947 | EY11: 270559 | EZ11: 12760862 | FA11: =EZ11/EY11 -> 47.164803 | FB11: =FA11*3.30578512 -> 155.9167 | FC11: 469145 | FD11: 25382588 | FE11: =FD11/FC11 -> 54.10393 | FF11: =FE11*3.30578512 -> 178.85597 | FG11: 1234635 | FH11: 88701906 | FI11: =FH11/FG11 -> 71.844639 | FJ11: =FI11*3.30578512 -> 237.50294 | FK11: 358272 | FL11: 22722116 | FM11: =FL11/FK11 -> 63.421412 | FN11: =FM11*3.30578512 -> 209.65756 | FQ11: =FP11/FO11 -> #DIV/0! | FR11: =FQ11*3.30578512 -> #DIV/0! | FU11: =FT11/FS11 -> #DIV/0! | FV11: =FU11*3.30578512 -> #DIV/0! | FY11: =FX11/FW11 -> #DIV/0! | FZ11: =FY11*3.30578512 -> #DIV/0!
B15: 着工多用途建築物
C16: 2015（基準） | G16: 令和4年1月分 | K16: 令和4年2月分 | O16: 令和4年3月分 | S16: 令和4年4月分 | W16: 令和4年5月分 | AA16: 令和4年6月分 | AE16: 令和4年7月分 | AI16: 令和4年8月分 | AM16: 令和4年9月分 | AQ16: 令和4年10月分 | AU16: 令和4年11月分 | AY16: 令和4年12月分 | BC16: 令和5年1月分 | BG16: 令和5年2月分 | BK16: 令和5年3月分 | BO16: 令和5年4月分 | BS16: 令和5年5月分 | BW16: 令和5年6月分 | CA16: 令和5年7月分 | CE16: 令和5年8月分 | CI16: 令和5年9月分 | CM16: 令和5年10月分 | CQ16: 令和5年11月分 | CU16: 令和5年12月分 | CY16: 令和6年1月分 | DC16: 令和6年2月分 | DG16: 令和6年3月分 | DK16: 令和6年4月分 | DO16: 令和6年5月分 | DS16: 令和6年6月分 | DW16: 令和6年7月分 | EA16: 令和6年8月分 | EE16: 令和6年9月分 | EI16: 令和6年10月分 | EM16: 令和6年11月分 | EQ16: 令和6年12月分 | EU16: 令和7年1月分 | EY16: 令和7年2月分 | FC16: 令和7年3月分 | FG16: 令和7年4月分 | FK16: 令和7年5月分 | FO16: 令和7年6月分 | FS16: 令和7年7月分 | FW16: 令和7年8月分 | GA16: 令和7年9月分 | GE16: 令和7年10月分 | GI16: 令和7年11月分
C17: 床面積の合計 （㎡） | D17: 工事費予定額（万円） | E17: 面積単価 （万円/㎡） | F17: 面積単価 （万円/坪） | G17: 床面積の合計 （㎡） | H17: 工事費予定額（万円） | I17: 面積単価 （万円/㎡） | J17: 面積単価 （万円/坪） | K17: 床面積の合計 （㎡） | L17: 工事費予定額（万円） | M17: 面積単価 （万円/㎡） | N17: 面積単価 （万円/坪） | O17: 床面積の合計 （㎡） | P17: 工事費予定額（万円） | Q17: 面積単価 （万円/㎡） | R17: 面積単価 （万円/坪） | S17: 床面積の合計 （㎡） | T17: 工事費予定額（万円） | U17: 面積単価 （万円/㎡） | V17: 面積単価 （万円/坪） | W17: 床面積の合計 （㎡） | X17: 工事費予定額（万円） | Y17: 面積単価 （万円/㎡） | Z17: 面積単価 （万円/坪） | AA17: 床面積の合計 （㎡） | AB17: 工事費予定額（万円） | AC17: 面積単価 （万円/㎡） | AD17: 面積単価 （万円/坪） | AE17: 床面積の合計 （㎡） | AF17: 工事費予定額（万円） | AG17: 面積単価 （万円/㎡） | AH17: 面積単価 （万円/坪） | AI17: 床面積の合計 （㎡） | AJ17: 工事費予定額（万円） | AK17: 面積単価 （万円/㎡） | AL17: 面積単価 （万円/坪） | AM17: 床面積の合計 （㎡） | AN17: 工事費予定額（万円） | AO17: 面積単価 （万円/㎡） | AP17: 面積単価 （万円/坪） | AQ17: 床面積の合計 （㎡） | AR17: 工事費予定額（万円） | AS17: 面積単価 （万円/㎡） | AT17: 面積単価 （万円/坪） | AU17: 床面積の合計 （㎡） | AV17: 工事費予定額（万円） | AW17: 面積単価 （万円/㎡） | AX17: 面積単価 （万円/坪） | AY17: 床面積の合計 （㎡） | AZ17: 工事費予定額（万円） | BA17: 面積単価 （万円/㎡） | BB17: 面積単価 （万円/坪） | BC17: 床面積の合計 （㎡） | BD17: 工事費予定額（万円） | BE17: 面積単価 （万円/㎡） | BF17: 面積単価 （万円/坪） | BG17: 床面積の合計 （㎡） | BH17: 工事費予定額（万円） | BI17: 面積単価 （万円/㎡） | BJ17: 面積単価 （万円/坪） | BK17: 床面積の合計 （㎡） | BL17: 工事費予定額（万円） | BM17: 面積単価 （万円/㎡） | BN17: 面積単価 （万円/坪） | BO17: 床面積の合計 （㎡） | BP17: 工事費予定額（万円） | BQ17: 面積単価 （万円/㎡） | BR17: 面積単価 （万円/坪） | BS17: 床面積の合計 （㎡） | BT17: 工事費予定額（万円） | BU17: 面積単価 （万円/㎡） | BV17: 面積単価 （万円/坪） | BW17: 床面積の合計 （㎡） | BX17: 工事費予定額（万円） | BY17: 面積単価 （万円/㎡） | BZ17: 面積単価 （万円/坪） | CA17: 床面積の合計 （㎡） | CB17: 工事費予定額（万円） | CC17: 面積単価 （万円/㎡） | CD17: 面積単価 （万円/坪） | CE17: 床面積の合計 （㎡） | CF17: 工事費予定額（万円） | CG17: 面積単価 （万円/㎡） | CH17: 面積単価 （万円/坪） | CI17: 床面積の合計 （㎡） | CJ17: 工事費予定額（万円） | CK17: 面積単価 （万円/㎡） | CL17: 面積単価 （万円/坪） | CM17: 床面積の合計 （㎡） | CN17: 工事費予定額（万円） | CO17: 面積単価 （万円/㎡） | CP17: 面積単価 （万円/坪） | CQ17: 床面積の合計 （㎡） | CR17: 工事費予定額（万円） | CS17: 面積単価 （万円/㎡） | CT17: 面積単価 （万円/坪） | CU17: 床面積の合計 （㎡） | CV17: 工事費予定額（万円） | CW17: 面積単価 （万円/㎡） | CX17: 面積単価 （万円/坪） | CY17: 床面積の合計 （㎡） | CZ17: 工事費予定額（万円） | DA17: 面積単価 （万円/㎡） | DB17: 面積単価 （万円/坪） | DC17: 床面積の合計 （㎡） | DD17: 工事費予定額（万円） | DE17: 面積単価 （万円/㎡） | DF17: 面積単価 （万円/坪） | DG17: 床面積の合計 （㎡） | DH17: 工事費予定額（万円） | DI17: 面積単価 （万円/㎡） | DJ17: 面積単価 （万円/坪） | DK17: 床面積の合計 （㎡） | DL17: 工事費予定額（万円） | DM17: 面積単価 （万円/㎡） | DN17: 面積単価 （万円/坪） | DO17: 床面積の合計 （㎡） | DP17: 工事費予定額（万円） | DQ17: 面積単価 （万円/㎡） | DR17: 面積単価 （万円/坪） | DS17: 床面積の合計 （㎡） | DT17: 工事費予定額（万円） | DU17: 面積単価 （万円/㎡） | DV17: 面積単価 （万円/坪） | DW17: 床面積の合計 （㎡） | DX17: 工事費予定額（万円） | DY17: 面積単価 （万円/㎡） | DZ17: 面積単価 （万円/坪） | EA17: 床面積の合計 （㎡） | EB17: 工事費予定額（万円） | EC17: 面積単価 （万円/㎡） | ED17: 面積単価 （万円/坪） | EE17: 床面積の合計 （㎡） | EF17: 工事費予定額（万円） | EG17: 面積単価 （万円/㎡） | EH17: 面積単価 （万円/坪） | EI17: 床面積の合計 （㎡） | EJ17: 工事費予定額（万円） | EK17: 面積単価 （万円/㎡） | EL17: 面積単価 （万円/坪） | EM17: 床面積の合計 （㎡） | EN17: 工事費予定額（万円） | EO17: 面積単価 （万円/㎡） | EP17: 面積単価 （万円/坪） | EQ17: 床面積の合計 （㎡） | ER17: 工事費予定額（万円） | ES17: 面積単価 （万円/㎡） | ET17: 面積単価 （万円/坪） | EU17: 床面積の合計 （㎡） | EV17: 工事費予定額（万円） | EW17: 面積単価 （万円/㎡） | EX17: 面積単価 （万円/坪） | EY17: 床面積の合計 （㎡） | EZ17: 工事費予定額（万円） | FA17: 面積単価 （万円/㎡） | FB17: 面積単価 （万円/坪） | FC17: 床面積の合計 （㎡） | FD17: 工事費予定額（万円） | FE17: 面積単価 （万円/㎡） | FF17: 面積単価 （万円/坪） | FG17: 床面積の合計 （㎡） | FH17: 工事費予定額（万円） | FI17: 面積単価 （万円/㎡） | FJ17: 面積単価 （万円/坪） | FK17: 床面積の合計 （㎡） | FL17: 工事費予定額（万円） | FM17: 面積単価 （万円/㎡） | FN17: 面積単価 （万円/坪） | FO17: 床面積の合計 （㎡） | FP17: 工事費予定額（万円） | FQ17: 面積単価 （万円/㎡） | FR17: 面積単価 （万円/坪） | FS17: 床面積の合計 （㎡） | FT17: 工事費予定額（万円） | FU17: 面積単価 （万円/㎡） | FV17: 面積単価 （万円/坪） | FW17: 床面積の合計 （㎡） | FX17: 工事費予定額（万円） | FY17: 面積単価 （万円/㎡） | FZ17: 面積単価 （万円/坪） | GA17: 床面積の合計 （㎡） | GB17: 工事費予定額（万円） | GC17: 面積単価 （万円/㎡） | GD17: 面積単価 （万円/坪） | GE17: 床面積の合計 （㎡） | GF17: 工事費予定額（万円） | GG17: 面積単価 （万円/㎡） | GH17: 面積単価 （万円/坪） | GI17: 床面積の合計 （㎡） | GJ17: 工事費予定額（万円） | GK17: 面積単価 （万円/㎡） | GL17: 面積単価 （万円/坪）
